Workbook

Sheet PO
A1: Client Name | B1: Sygnific infra Pvt. Ltd. | D1: Client Name | E1: Hindustan Infrastructure Solution | F1: Machine running 04-May-26
A2: Site | B2: Ahemdabaad | D2: Site | E2: Ahemdabaad
A3: PO# | B3: N/A | D3: PO# | E3: N/A
A4: PO Date | B4: 46016 | D4: PO Date | E4: mail confirmation req. praveen sir mail id par h
A5: PO Validy | B5: 46023 | D5: PO Validy
A6: PO Validy | B6: 46203 | D6: PO Validy
A7: Working hours monthly | B7: 300 HRS | D7: Working hours monthly | E7: 300 HRS
A8: Diesel | B8: Sygnific infra Pvt. Ltd. | D8: Diesel
A9: Hiring charges | B9: Rs 2,40,000/- | D9: Hiring charges | E9: Rs 2,60,000/-
A10: Asset Name | B10: 45 Ton XCMG Crawler CRANE | D10: Asset Name | E10: 45 Ton XCMG Crawler CRANE
A11: Asset Make | B11: XCMG | D11: Asset Make | E11: XCMG
A12: Reg. No. | D12: Reg. No.
A13: Assset Capacity | B13: 45 Ton | D13: Assset Capacity | E13: 45 Ton
A14: Assset QTY | B14: 1 | D14: Assset QTY | E14: 1
A15: Model | B15: 2025 | D15: Model | E15: 2025
A16: Diesel Average | B16: Not Applicable | D16: Diesel Average | E16: Not Applicable
A17: Commissioning | B17: 46011 | D17: Commissioning
A18: Maintaince allowed | B18: 2 Days in a month | C18: 30 Days= 28 Days Billing 31 Days= 29 Days Billing | D18: Maintaince allowed
A19: Breakdwon Allowed | B19: 0 Hours | D19: Breakdwon Allowed
A20: Extra Running Billing | B20: Above 300 Hrs on pro rata basis | D20: Extra Running Billing
A21: Operator Count | D21: Operator Count
A22: Billing cycle | B22: Monthly | D22: Billing cycle | E22: Monthly
A23: HEAD OFFICE PERSON | B23: Sunil Ji | D23: HEAD OFFICE PERSON | E23: Sunil Ji
A24: SITE SUPERVISOR | B24: Sunil Ji | D24: SITE SUPERVISOR | E24: Sunil Ji
A25: Operator Count | B25: 1 | D25: Operator Count | E25: 1
A26: Helper Count | D26: Helper Count
A27: Accomadation Charges (Operator) | B27: Stay, Food and Transport will bear by Signific Infra Mesh Charges will be provided by Ekta | D27: Accomadation Charges (Operator)
A28: Overtime working | B28: Working hours exceeding the stipulated monthly hours will be charged extra on a pro-rata basis. | D28: Overtime working
A29: Required Documents for Billing | B29: Monthly Singned logbook, Tax Invoice | D29: Required Documents for Billing | E29: Monthly Singned logbook, Tax Invoice
A30: Email Id for Billing | B30: mayur.d@sygnificinfra.com info@sygnificinfra.com | D30: Email Id for Billing | E30: mayur.d@sygnificinfra.com info@sygnificinfra.com
A31: Ekta's Email ID used for Billing | B31: ektaenterprises1@gmail.com | D31: Ekta's Email ID used for Billing | E31: ektaenterprises1@gmail.com
A33: Termination or dehire of machine
A35: Payment Term | B35: Payment will be done on 15 to 20 of each month
A72: Termination or dehire of machine
A74: Payment Term

Sheet DEC-25
A1: Vendor Description | E1: EKTA ENTERPRISES
A2: Asset Discription | E2: XCMG Crawler CRANE
A3: Asset Capacity | E3: 45 Ton
A4: Billing Period | E4: 01-12-2025 TO 31-12-2025
A5: COMPANY NAME | E5: Sygnific infra Pvt. Ltd. Ahemdabaad
A6: SR. NO. | B6: Shift | C6: Date | D6: Starting HMR | E6: Closing HMR | F6: HMR | G6: Normal Shift Hours | H6: BD Start | I6: BD End | J6: Total B/D | K6: Diesel issued | L6: Diesel HMR | M6: Hours | N6: Remark
A7: 1 | B7: Day | C7: 45992 | G7: =F7+F8
A8: 2 | B8: Night | C8: =C7
A9: 3 | B9: Day | C9: =C7+1 | G9: =F9+F10
A10: 4 | B10: Night | C10: =C9
A11: 5 | B11: Day | C11: =C9+1 | G11: =F11+F12
A12: 6 | B12: Night | C12: =C11
A13: 7 | B13: Day | C13: =C11+1 | G13: =F13+F14
A14: 8 | B14: Night | C14: =C13
A15: 9 | B15: Day | C15: =C13+1 | G15: =F15+F16
A16: 10 | B16: Night | C16: =C15
A17: 11 | B17: Day | C17: =C15+1 | G17: =F17+F18
A18: 12 | B18: Night | C18: =C17
A19: 13 | B19: Day | C19: =C17+1 | G19: =F19+F20
A20: 14 | B20: Night | C20: =C19
A21: 15 | B21: Day | C21: =C19+1 | G21: =F21+F22
A22: 16 | B22: Night | C22: =C21
A23: 17 | B23: Day | C23: =C21+1 | G23: =F23+F24
A24: 18 | B24: Night | C24: =C23
A25: 19 | B25: Day | C25: =C23+1 | G25: =F25+F26
A26: 20 | B26: Night | C26: =C25
A27: 21 | B27: Day | C27: =C25+1 | G27: =F27+F28
A28: 22 | B28: Night | C28: =C27
A29: 23 | B29: Day | C29: =C27+1 | G29: =F29+F30
A30: 24 | B30: Night | C30: =C29
A31: 25 | B31: Day | C31: =C29+1 | G31: =F31+F32
A32: 26 | B32: Night | C32: =C31
A33: 27 | B33: Day | C33: =C31+1 | G33: =F33+F34
A34: 28 | B34: Night | C34: =C33
A35: 29 | B35: Day | C35: =C33+1 | G35: =F35+F36
A36: 30 | B36: Night | C36: =C35
A37: 31 | B37: Day | C37: =C35+1 | G37: =F37+F38
A38: 32 | B38: Night | C38: =C37
A39: 33 | B39: Day | C39: =C37+1 | G39: =F39+F40
A40: 34 | B40: Night | C40: =C39
...

Sheet JAN-26
A1: Vendor Description | E1: EKTA ENTERPRISES
A2: Asset Discription | E2: XCMG Crawler CRANE
A3: Asset Capacity | E3: 45 Ton
A4: Billing Period | E4: 01-1-2026 TO 31-1-2026
A5: COMPANY NAME | E5: Sygnific infra Pvt. Ltd. Ahemdabaad
A6: SR. NO. | B6: Shift | C6: Date | D6: Starting HMR | E6: Closing HMR | F6: HMR | G6: Normal Shift Hours | H6: BD Start | I6: BD End | J6: Total B/D | K6: Diesel issued | L6: Diesel HMR | M6: Hours | N6: Remark
A7: 1 | B7: Day | C7: 46023 | D7: 1047 | E7: 1049 | F7: =E7-D7 | G7: =F7+F8 | K7: 26 | L7: 1047
A8: 2 | B8: Night | C8: =C7 | D8: =E7 | E8: 1053 | F8: =E8-D8
A9: 3 | B9: Day | C9: =C7+1 | D9: =E8 | E9: 1056 | F9: =E9-D9 | G9: =F9+F10 | K9: 50 | L9: 1053
A10: 4 | B10: Night | C10: =C9 | D10: =E9 | E10: 1060 | F10: =E10-D10
A11: 5 | B11: Day | C11: =C9+1 | D11: =E10 | E11: 1064 | F11: =E11-D11 | G11: =F11+F12 | K11: 50 | L11: 1060
A12: 6 | B12: Night | C12: =C11 | D12: =E11 | E12: 1064 | F12: =E12-D12
A13: 7 | B13: Day | C13: =C11+1 | D13: 1066 | E13: 1069 | F13: =E13-D13 | G13: =F13+F14
A14: 8 | B14: Night | C14: =C13 | D14: =E13 | E14: 1074 | F14: =E14-D14
A15: 9 | B15: Day | C15: =C13+1 | D15: =E14 | E15: 1079 | F15: =E15-D15 | G15: =F15+F16 | K15: 50 | L15: 1074
A16: 10 | B16: Night | C16: =C15 | D16: =E15 | E16: 1083 | F16: =E16-D16
A17: 11 | B17: Day | C17: =C15+1 | D17: =E16 | E17: 1088 | F17: =E17-D17 | G17: =F17+F18 | K17: 50 | L17: 1084
A18: 12 | B18: Night | C18: =C17 | D18: =E17 | E18: 1094 | F18: =E18-D18
A19: 13 | B19: Day | C19: =C17+1 | D19: =E18 | E19: 1098 | F19: =E19-D19 | G19: =F19+F20 | K19: 50 | L19: 1096.1
A20: 14 | B20: Night | C20: =C19 | D20: =E19 | E20: 1100 | F20: =E20-D20
A21: 15 | B21: Day | C21: =C19+1 | D21: =E20 | E21: 1107 | F21: =E21-D21 | G21: =F21+F22
A22: 16 | B22: Night | C22: =C21 | D22: =E21 | E22: 1109 | F22: =E22-D22 | K22: 25 | L22: 1107
A23: 17 | B23: Day | C23: =C21+1 | D23: =E22 | E23: 1113 | F23: =E23-D23 | G23: =F23+F24
A24: 18 | B24: Night | C24: =C23 | D24: =E23 | E24: 1114 | F24: =E24-D24 | K24: 25 | L24: 1114
A25: 19 | B25: Day | C25: =C23+1 | D25: =E24 | E25: 1119 | F25: =E25-D25 | G25: =F25+F26
A26: 20 | B26: Night | C26: =C25 | D26: =E25 | E26: 1123 | F26: =E26-D26
A27: 21 | B27: Day | C27: =C25+1 | D27: =E26 | E27: 1130 | F27: =E27-D27 | G27: =F27+F28 | K27: 50 | L27: 1124
A28: 22 | B28: Night | C28: =C27 | D28: =E27 | E28: 1134 | F28: =E28-D28 | K28: 20 | L28: 1134
A29: 23 | B29: Day | C29: =C27+1 | D29: =E28 | E29: 1140 | F29: =E29-D29 | G29: =F29+F30
A30: 24 | B30: Night | C30: =C29 | D30: =E29 | E30: 1145 | F30: =E30-D30 | K30: 25 | L30: 1142
A31: 25 | B31: Day | C31: =C29+1 | D31: =E30 | E31: 1153 | F31: =E31-D31 | G31: =F31+F32 | K31: 25 | L31: 1148
A32: 26 | B32: Night | C32: =C31 | D32: =E31 | E32: 1158 | F32: =E32-D32 | K32: 60 | L32: 1154
A33: 27 | B33: Day | C33: =C31+1 | D33: =E32 | E33: 1164 | F33: =E33-D33 | G33: =F33+F34
A34: 28 | B34: Night | C34: =C33 | D34: =E33 | E34: 1166 | F34: =E34-D34 | K34: 25 | L34: 1164
A35: 29 | B35: Day | C35: =C33+1 | D35: =E34 | E35: 1168 | F35: =E35-D35 | G35: =F35+F36
A36: 30 | B36: Night | C36: =C35 | D36: =E35 | E36: 1174 | F36: =E36-D36 | K36: 25 | L36: 1169
A37: 31 | B37: Day | C37: =C35+1 | D37: =E36 | E37: 1179 | F37: =E37-D37 | G37: =F37+F38 | K37: 20 | L37: 1176
A38: 32 | B38: Night | C38: =C37 | D38: =E37 | E38: 1185 | F38: =E38-D38 | K38: 25 | L38: 1180
A39: 33 | B39: Day | C39: =C37+1 | D39: =E38 | E39: 1188 | F39: =E39-D39 | G39: =F39+F40 | K39: 50 | L39: 1187
A40: 34 | B40: Night | C40: =C39 | D40: =E39 | E40: 1192 | F40: =E40-D40
...

Sheet FEB-26
A1: Vendor Description | E1: EKTA ENTERPRISES
A2: Asset Discription | E2: XCMG Crawler CRANE
A3: Asset Capacity | E3: 45 Ton
A4: Billing Period | E4: 01-2-2026 TO 28-2-2026
A5: COMPANY NAME | E5: Sygnific infra Pvt. Ltd. Ahemdabaad
A6: SR. NO. | B6: Shift | C6: Date | D6: Starting HMR | E6: Closing HMR | F6: HMR | G6: Normal Shift Hours | H6: BD Start | I6: BD End | J6: Total B/D | K6: Diesel issued | L6: Diesel HMR | M6: Hours | N6: Remark
A7: 1 | B7: Day | C7: 46054 | D7: 1279 | E7: 1282 | F7: =E7-D7 | G7: =F7+F8 | K7: 25 | L7: 1282
A8: 2 | B8: Night | C8: =C7 | D8: =E7 | E8: 1286 | F8: =E8-D8
A9: 3 | B9: Day | C9: =C7+1 | D9: =E8 | E9: 1290 | F9: =E9-D9 | G9: =F9+F10 | K9: 30 | L9: 1287
A10: 4 | B10: Night | C10: =C9 | D10: =E9 | E10: 1297 | F10: =E10-D10 | K10: 25 | L10: 1294
A11: 5 | B11: Day | C11: =C9+1 | D11: =E10 | E11: 1301 | F11: =E11-D11 | G11: =F11+F12
A12: 6 | B12: Night | C12: =C11 | D12: =E11 | E12: 1303 | F12: =E12-D12 | K12: 20 | L12: 1301
A13: 7 | B13: Day | C13: =C11+1 | D13: =E12 | E13: 1309 | F13: =E13-D13 | G13: =F13+F14 | K13: 50 | L13: 1303
A14: 8 | B14: Night | C14: =C13 | D14: =E13 | E14: 1310 | F14: =E14-D14
A15: 9 | B15: Day | C15: =C13+1 | D15: =E14 | E15: 1314 | F15: =E15-D15 | G15: =F15+F16
A16: 10 | B16: Night | C16: =C15 | D16: =E15 | E16: 1318 | F16: =E16-D16 | K16: 25 | L16: 1317
A17: 11 | B17: Day | C17: =C15+1 | D17: =E16 | E17: 1325 | F17: =E17-D17 | G17: =F17+F18 | K17: 25 | L17: 1323
A18: 12 | B18: Night | C18: =C17 | D18: =E17 | E18: 1329 | F18: =E18-D18 | K18: 25 | L18: 1328
A19: 13 | B19: Day | C19: =C17+1 | D19: =E18 | E19: 1333 | F19: =E19-D19 | G19: =F19+F20 | K19: 25 | L19: 1332
A20: 14 | B20: Night | C20: =C19 | D20: =E19 | E20: 1336 | F20: =E20-D20
A21: 15 | B21: Day | C21: =C19+1 | D21: =E20 | E21: 1340 | F21: =E21-D21 | G21: =F21+F22
A22: 16 | B22: Night | C22: =C21 | D22: =E21 | E22: 1350 | F22: =E22-D22 | K22: 25 | L22: 1345
A23: 17 | B23: Day | C23: =C21+1 | D23: =E22 | E23: 1353 | F23: =E23-D23 | G23: =F23+F24 | K23: 25 | L23: 1350
A24: 18 | B24: Night | C24: =C23 | D24: =E23 | E24: 1355 | F24: =E24-D24
A25: 19 | B25: Day | C25: =C23+1 | D25: =E24 | E25: 1359 | F25: =E25-D25 | G25: =F25+F26 | K25: 25 | L25: 1355
A26: 20 | B26: Night | C26: =C25 | D26: =E25 | E26: 1363 | F26: =E26-D26 | K26: 25 | L26: 1359
A27: 21 | B27: Day | C27: =C25+1 | D27: =E26 | E27: 1365 | F27: =E27-D27 | G27: =F27+F28
A28: 22 | B28: Night | C28: =C27 | D28: =E27 | E28: 1366 | F28: =E28-D28
A29: 23 | B29: Day | C29: =C27+1 | D29: =E28 | E29: 1369 | F29: =E29-D29 | G29: =F29+F30 | K29: 25 | L29: 1366
A30: 24 | B30: Night | C30: =C29 | D30: =E29 | E30: 1370 | F30: =E30-D30
A31: 25 | B31: Day | C31: =C29+1 | D31: =E30 | E31: 1372 | F31: =E31-D31 | G31: =F31+F32 | K31: 25 | L31: 1370
A32: 26 | B32: Night | C32: =C31 | D32: =E31 | E32: 1372 | F32: =E32-D32
A33: 27 | B33: Day | C33: =C31+1 | D33: =E32 | E33: 1375 | F33: =E33-D33 | G33: =F33+F34
A34: 28 | B34: Night | C34: =C33 | D34: =E33 | E34: 1376 | F34: =E34-D34 | K34: 25 | L34: 1375
A35: 29 | B35: Day | C35: =C33+1 | D35: =E34 | E35: 1378 | F35: =E35-D35 | G35: =F35+F36
A36: 30 | B36: Night | C36: =C35 | D36: =E35 | E36: 1381 | F36: =E36-D36 | K36: 25 | L36: 1378
A37: 31 | B37: Day | C37: =C35+1 | D37: =E36 | E37: 1382 | F37: =E37-D37 | G37: =F37+F38
A38: 32 | B38: Night | C38: =C37 | D38: =E37 | E38: 1382 | F38: =E38-D38
A39: 33 | B39: Day | C39: =C37+1 | D39: =E38 | E39: 1384 | F39: =E39-D39 | G39: =F39+F40
A40: 34 | B40: Night | C40: =C39 | D40: =E39 | E40: 1385 | F40: =E40-D40
...

Sheet MAY-26
A1: Vendor Description | E1: EKTA ENTERPRISES
A2: Asset Discription | E2: XCMG Crawler CRANE
A3: Asset Capacity | E3: 45 Ton
A4: Billing Period | E4: 04-05-2026 TO 31-05-2026
A5: COMPANY NAME | E5: Hindustan Infrastructure solution Ahemdabaad
A6: SR. NO. | B6: Shift | C6: Date | D6: Starting HMR | E6: Closing HMR | F6: HMR | G6: Normal Shift Hours | H6: BD Start | I6: BD End | J6: Total B/D | K6: Diesel issued | L6: Diesel HMR | M6: Hours | N6: Remark
A7: 1 | B7: Day | C7: 46143 | G7: =F7+F8
A8: 2 | B8: Night | C8: =C7
A9: 3 | B9: Day | C9: =C7+1 | G9: =F9+F10
A10: 4 | B10: Night | C10: =C9
A11: 5 | B11: Day | C11: =C9+1 | G11: =F11+F12 | N11: Sunday
A12: 6 | B12: Night | C12: =C11 | D12: Machine start 04-05-26
A13: 7 | B13: Day | C13: =C11+1 | D13: 1536 | E13: 1538 | F13: =E13-D13 | G13: =F13+F14 | K13: 130
A14: 8 | B14: Night | C14: =C13 | D14: =E13 | E14: 1538 | F14: =E14-D14
A15: 9 | B15: Day | C15: =C13+1 | D15: =E14 | E15: 1541 | F15: =E15-D15 | G15: =F15+F16
A16: 10 | B16: Night | C16: =C15 | D16: =E15 | E16: 1544 | F16: =E16-D16
A17: 11 | B17: Day | C17: =C15+1 | D17: =E16 | E17: 1548 | F17: =E17-D17 | G17: =F17+F18
A18: 12 | B18: Night | C18: =C17 | D18: =E17 | E18: 1548 | F18: =E18-D18
A19: 13 | B19: Day | C19: =C17+1 | D19: =E18 | E19: 1553 | F19: =E19-D19 | G19: =F19+F20
A20: 14 | B20: Night | C20: =C19 | D20: =E19 | E20: 1553 | F20: =E20-D20
A21: 15 | B21: Day | C21: =C19+1 | D21: =E20 | E21: 1554 | F21: =E21-D21 | G21: =F21+F22
A22: 16 | B22: Night | C22: =C21 | D22: =E21 | E22: 1555 | F22: =E22-D22
A23: 17 | B23: Day | C23: =C21+1 | D23: =E22 | E23: 1557 | F23: =E23-D23 | G23: =F23+F24 | K23: 60
A24: 18 | B24: Night | C24: =C23 | D24: =E23 | E24: 1560 | F24: =E24-D24
A25: 19 | B25: Day | C25: =C23+1 | D25: =E24 | E25: 1563 | F25: =E25-D25 | G25: =F25+F26 | N25: Sunday
A26: 20 | B26: Night | C26: =C25 | D26: =E25 | E26: 1566 | F26: =E26-D26
A27: 21 | B27: Day | C27: =C25+1 | D27: =E26 | E27: 1568 | F27: =E27-D27 | G27: =F27+F28 | K27: 73
A28: 22 | B28: Night | C28: =C27 | D28: =E27 | E28: 1568 | F28: =E28-D28
A29: 23 | B29: Day | C29: =C27+1 | D29: =E28 | E29: 1570 | F29: =E29-D29 | G29: =F29+F30
A30: 24 | B30: Night | C30: =C29 | D30: =E29 | E30: 1573 | F30: =E30-D30
A31: 25 | B31: Day | C31: =C29+1 | D31: =E30 | E31: 1575 | F31: =E31-D31 | G31: =F31+F32 | K31: 50
A32: 26 | B32: Night | C32: =C31 | D32: =E31 | E32: 1575 | F32: =E32-D32
A33: 27 | B33: Day | C33: =C31+1 | D33: =E32 | E33: 1577 | F33: =E33-D33 | G33: =F33+F34
A34: 28 | B34: Night | C34: =C33 | D34: =E33 | E34: 1577 | F34: =E34-D34
A35: 29 | B35: Day | C35: =C33+1 | D35: =E34 | E35: 1578 | F35: =E35-D35 | G35: =F35+F36
A36: 30 | B36: Night | C36: =C35 | D36: =E35 | E36: 1578 | F36: =E36-D36
A37: 31 | B37: Day | C37: =C35+1 | D37: =E36 | E37: 1578 | F37: =E37-D37 | G37: =F37+F38
A38: 32 | B38: Night | C38: =C37 | D38: =E37 | E38: 1578 | F38: =E38-D38
A39: 33 | B39: Day | C39: =C37+1 | D39: =E38 | E39: 1578 | F39: =E39-D39 | G39: =F39+F40 | N39: Sunday
A40: 34 | B40: Night | C40: =C39 | D40: =E39 | E40: 1578 | F40: =E40-D40
...

Sheet MAR-26
A1: Vendor Description | E1: EKTA ENTERPRISES
A2: Asset Discription | E2: XCMG Crawler CRANE
A3: Asset Capacity | E3: 45 Ton
A4: Billing Period | E4: 01-3-2026 TO 31-3-2026
A5: COMPANY NAME | E5: Sygnific infra Pvt. Ltd. Ahemdabaad
A6: SR. NO. | B6: Shift | C6: Date | D6: Starting HMR | E6: Closing HMR | F6: HMR | G6: Normal Shift Hours | H6: BD Start | I6: BD End | J6: Total B/D | K6: Diesel issued | L6: Diesel HMR | M6: Hours | N6: Remark
A7: 1 | B7: Day | C7: 46082 | D7: 1413 | E7: 1413 | F7: =E7-D7 | G7: =F7+F8 | N7: Sunday
A8: 2 | B8: Night | C8: =C7 | D8: =E7 | E8: 1413 | F8: =E8-D8
A9: 3 | B9: Day | C9: =C7+1 | D9: =E8 | E9: 1414 | F9: =E9-D9 | G9: =F9+F10
A10: 4 | B10: Night | C10: =C9 | D10: =E9 | E10: 1414 | F10: =E10-D10
A11: 5 | B11: Day | C11: =C9+1 | D11: =E10 | E11: 1414 | F11: =E11-D11 | G11: =F11+F12
A12: 6 | B12: Night | C12: =C11 | D12: =E11 | E12: 1414 | F12: =E12-D12
A13: 7 | B13: Day | C13: =C11+1 | D13: =E12 | E13: 1414 | F13: =E13-D13 | G13: =F13+F14
A14: 8 | B14: Night | C14: =C13 | D14: =E13 | E14: 1414 | F14: =E14-D14
A15: 9 | B15: Day | C15: =C13+1 | D15: =E14 | E15: 1417 | F15: =E15-D15 | G15: =F15+F16
A16: 10 | B16: Night | C16: =C15 | D16: =E15 | E16: 1424 | F16: =E16-D16 | K16: 25 | L16: 1424
A17: 11 | B17: Day | C17: =C15+1 | D17: =E16 | E17: 1425 | F17: =E17-D17 | G17: =F17+F18
A18: 12 | B18: Night | C18: =C17 | D18: =E17 | E18: 1430 | F18: =E18-D18 | K18: 25 | L18: 1430
A19: 13 | B19: Day | C19: =C17+1 | D19: =E18 | E19: 1435 | F19: =E19-D19 | G19: =F19+F20 | K19: 25 | L19: 1434
A20: 14 | B20: Night | C20: =C19 | D20: =E19 | E20: 1439 | F20: =E20-D20
A21: 15 | B21: Day | C21: =C19+1 | D21: =E20 | E21: 1444 | F21: =E21-D21 | G21: =F21+F22 | N21: Sunday
A22: 16 | B22: Night | C22: =C21 | D22: =E21 | E22: 1450 | F22: =E22-D22 | K22: 25 | L22: 1447
A23: 17 | B23: Day | C23: =C21+1 | D23: =E22 | E23: 1452 | F23: =E23-D23 | G23: =F23+F24
A24: 18 | B24: Night | C24: =C23 | D24: =E23 | E24: 1458 | F24: =E24-D24 | K24: 25 | L24: 1456
A25: 19 | B25: Day | C25: =C23+1 | D25: =E24 | E25: 1460 | F25: =E25-D25 | G25: =F25+F26
A26: 20 | B26: Night | C26: =C25 | D26: =E25 | E26: 1467 | F26: =E26-D26 | K26: 20 | L26: 1462
A27: 21 | B27: Day | C27: =C25+1 | D27: =E26 | E27: 1468 | F27: =E27-D27 | G27: =F27+F28
A28: 22 | B28: Night | C28: =C27 | D28: =E27 | E28: 1468 | F28: =E28-D28
A29: 23 | B29: Day | C29: =C27+1 | D29: =E28 | E29: 1469 | F29: =E29-D29 | G29: =F29+F30 | K29: 25 | L29: 1468
A30: 24 | B30: Night | C30: =C29 | D30: =E29 | E30: 1476 | F30: =E30-D30
A31: 25 | B31: Day | C31: =C29+1 | D31: =E30 | E31: 1477 | F31: =E31-D31 | G31: =F31+F32
A32: 26 | B32: Night | C32: =C31 | D32: =E31 | E32: 1484 | F32: =E32-D32 | K32: 25 | L32: 1479
A33: 27 | B33: Day | C33: =C31+1 | D33: =E32 | E33: 1485 | F33: =E33-D33 | G33: =F33+F34 | K33: 13 | L33: 1484
A34: 28 | B34: Night | C34: =C33 | D34: =E33 | E34: 1492 | F34: =E34-D34
A35: 29 | B35: Day | C35: =C33+1 | D35: =E34 | E35: 1496 | F35: =E35-D35 | G35: =F35+F36 | K35: 20 | L35: 1496 | N35: Sunday
A36: 30 | B36: Night | C36: =C35 | D36: =E35 | E36: 1498 | F36: =E36-D36
A37: 31 | B37: Day | C37: =C35+1 | D37: =E36 | E37: 1501 | F37: =E37-D37 | G37: =F37+F38 | K37: 25 | L37: 1498
A38: 32 | B38: Night | C38: =C37 | D38: =E37 | E38: 1503 | F38: =E38-D38 | K38: 25 | L38: 1501
A39: 33 | B39: Day | C39: =C37+1 | D39: =E38 | E39: 1506 | F39: =E39-D39 | G39: =F39+F40
A40: 34 | B40: Night | C40: =C39 | D40: =E39 | E40: 1506 | F40: =E40-D40
...

Sheet JUNE-26
A1: Vendor Description | E1: EKTA ENTERPRISES
A2: Asset Discription | E2: XCMG Crawler CRANE
A3: Asset Capacity | E3: 45 Ton
A4: Billing Period | E4: 01-06-2026 TO 30-06-2026
A5: COMPANY NAME | E5: Hindustan Infrastructure solution Ahemdabaad
A6: SR. NO. | B6: Shift | C6: Date | D6: Starting HMR | E6: Closing HMR | F6: HMR | G6: Normal Shift Hours | H6: BD Start | I6: BD End | J6: Total B/D | K6: Diesel issued | L6: Diesel HMR | M6: Hours | N6: Remark
A7: 1 | B7: Day | C7: 46174 | D7: 1591 | E7: 1591 | F7: =E7-D7 | G7: =F7+F8
A8: 2 | B8: Night | C8: =C7 | D8: =E7 | E8: 1591 | F8: =E8-D8
A9: 3 | B9: Day | C9: =C7+1 | D9: =E8 | E9: 1591 | F9: =E9-D9 | G9: =F9+F10
A10: 4 | B10: Night | C10: =C9 | D10: =E9 | E10: 1591 | F10: =E10-D10
A11: 5 | B11: Day | C11: =C9+1 | D11: =E10 | E11: 1591 | F11: =E11-D11 | G11: =F11+F12
A12: 6 | B12: Night | C12: =C11 | D12: =E11 | E12: 1591 | F12: =E12-D12
A13: 7 | B13: Day | C13: =C11+1 | D13: =E12 | E13: 1591 | F13: =E13-D13 | G13: =F13+F14
A14: 8 | B14: Night | C14: =C13 | D14: =E13 | E14: 1591 | F14: =E14-D14
A15: 9 | B15: Day | C15: =C13+1 | D15: =E14 | E15: 1591 | F15: =E15-D15 | G15: =F15+F16
A16: 10 | B16: Night | C16: =C15 | D16: =E15 | E16: 1591 | F16: =E16-D16
A17: 11 | B17: Day | C17: =C15+1 | D17: =E16 | E17: 1591 | F17: =E17-D17 | G17: =F17+F18
A18: 12 | B18: Night | C18: =C17 | D18: =E17 | E18: 1591 | F18: =E18-D18
A19: 13 | B19: Day | C19: =C17+1 | D19: =E18 | E19: 1596 | F19: =E19-D19 | G19: =F19+F20 | N19: Sunday
A20: 14 | B20: Night | C20: =C19 | D20: =E19 | E20: 1600 | F20: =E20-D20 | K20: 110
A21: 15 | B21: Day | C21: =C19+1 | D21: =E20 | E21: 1603 | F21: =E21-D21 | G21: =F21+F22
A22: 16 | B22: Night | C22: =C21 | D22: =E21 | E22: 1603 | F22: =E22-D22
A23: 17 | B23: Day | C23: =C21+1 | D23: =E22 | E23: 1603 | F23: =E23-D23 | G23: =F23+F24
A24: 18 | B24: Night | C24: =C23 | D24: =E23 | E24: 1605 | F24: =E24-D24
A25: 19 | B25: Day | C25: =C23+1 | D25: =E24 | E25: 1605 | F25: =E25-D25 | G25: =F25+F26
A26: 20 | B26: Night | C26: =C25 | D26: =E25 | E26: 1605 | F26: =E26-D26
A27: 21 | B27: Day | C27: =C25+1 | D27: =E26 | E27: 1610 | F27: =E27-D27 | G27: =F27+F28
A28: 22 | B28: Night | C28: =C27 | D28: =E27 | E28: 1612 | F28: =E28-D28
A29: 23 | B29: Day | C29: =C27+1 | D29: =E28 | E29: 1612 | F29: =E29-D29 | G29: =F29+F30
A30: 24 | B30: Night | C30: =C29 | D30: =E29 | E30: 1612 | F30: =E30-D30
A31: 25 | B31: Day | C31: =C29+1 | D31: =E30 | E31: 1612 | F31: =E31-D31 | G31: =F31+F32 | K31: 135
A32: 26 | B32: Night | C32: =C31 | D32: =E31 | E32: 1612 | F32: =E32-D32
A33: 27 | B33: Day | C33: =C31+1 | D33: =E32 | E33: 1616 | F33: =E33-D33 | G33: =F33+F34 | N33: Sunday
A34: 28 | B34: Night | C34: =C33 | D34: =E33 | E34: 1620 | F34: =E34-D34
A35: 29 | B35: Day | C35: =C33+1 | D35: =E34 | E35: 1620 | F35: =E35-D35 | G35: =F35+F36
A36: 30 | B36: Night | C36: =C35 | D36: =E35 | E36: 1620 | F36: =E36-D36
A37: 31 | B37: Day | C37: =C35+1 | D37: =E36 | E37: 1620 | F37: =E37-D37 | G37: =F37+F38
A38: 32 | B38: Night | C38: =C37 | D38: =E37 | E38: 1620 | F38: =E38-D38
A39: 33 | B39: Day | C39: =C37+1 | D39: =E38 | E39: 1624 | F39: =E39-D39 | G39: =F39+F40
A40: 34 | B40: Night | C40: =C39 | D40: =E39 | E40: 1626 | F40: =E40-D40
...

Sheet July-26
A1: Vendor Description | E1: EKTA ENTERPRISES
A2: Asset Discription | E2: XCMG Crawler CRANE
A3: Asset Capacity | E3: 45 Ton
A4: Billing Period | E4: 01-07-2026 TO 31-07-2026
A5: COMPANY NAME | E5: Hindustan Infrastructure solution Ahemdabaad
A6: SR. NO. | B6: Shift | C6: Date | D6: Starting HMR | E6: Closing HMR | F6: HMR | G6: Normal Shift Hours | H6: BD Start | I6: BD End | J6: Total B/D | K6: Diesel issued | L6: Diesel HMR | M6: Hours | N6: Remark
A7: 1 | B7: Day | C7: 46204 | D7: 1665 | E7: 1667 | F7: =E7-D7 | G7: =F7+F8
A8: 2 | B8: Night | C8: =C7 | D8: =E7 | E8: 1669 | F8: =E8-D8
A9: 3 | B9: Day | C9: =C7+1 | D9: =E8 | E9: 1671 | F9: =E9-D9 | G9: =F9+F10
A10: 4 | B10: Night | C10: =C9 | D10: =E9 | E10: 1672 | F10: =E10-D10
A11: 5 | B11: Day | C11: =C9+1 | D11: =E10 | E11: 1672 | F11: =E11-D11 | G11: =F11+F12
A12: 6 | B12: Night | C12: =C11 | D12: =E11 | E12: 1672 | F12: =E12-D12
A13: 7 | B13: Day | C13: =C11+1 | D13: =E12 | E13: 1672 | F13: =E13-D13 | G13: =F13+F14
A14: 8 | B14: Night | C14: =C13 | D14: =E13 | E14: 1672 | F14: =E14-D14
A15: 9 | B15: Day | C15: =C13+1 | D15: =E14 | E15: 1672 | F15: =E15-D15 | G15: =F15+F16 | N15: SUNDAY
A16: 10 | B16: Night | C16: =C15 | D16: =E15 | E16: 1672 | F16: =E16-D16
A17: 11 | B17: Day | C17: =C15+1 | D17: =E16 | E17: 1674 | F17: =E17-D17 | G17: =F17+F18
A18: 12 | B18: Night | C18: =C17 | D18: =E17 | E18: 1676 | F18: =E18-D18
A19: 13 | B19: Day | C19: =C17+1 | D19: =E18 | E19: 1677 | F19: =E19-D19 | G19: =F19+F20
A20: 14 | B20: Night | C20: =C19 | D20: =E19 | E20: 1678 | F20: =E20-D20
A21: 15 | B21: Day | C21: =C19+1 | D21: =E20 | E21: 1679 | F21: =E21-D21 | G21: =F21+F22
A22: 16 | B22: Night | C22: =C21 | D22: =E21 | E22: 1682 | F22: =E22-D22
A23: 17 | B23: Day | C23: =C21+1 | D23: =E22 | E23: 1683 | F23: =E23-D23 | G23: =F23+F24
A24: 18 | B24: Night | C24: =C23 | D24: =E23 | E24: 1684 | F24: =E24-D24
A25: 19 | B25: Day | C25: =C23+1 | D25: =E24 | E25: 1685 | F25: =E25-D25 | G25: =F25+F26
A26: 20 | B26: Night | C26: =C25 | D26: =E25 | E26: 1686 | F26: =E26-D26
A27: 21 | B27: Day | C27: =C25+1 | D27: =E26 | E27: 1690 | F27: =E27-D27 | G27: =F27+F28
A28: 22 | B28: Night | C28: =C27 | D28: =E27 | E28: 1691 | F28: =E28-D28
A29: 23 | B29: Day | C29: =C27+1 | D29: =E28 | E29: 1691 | F29: =E29-D29 | G29: =F29+F30 | N29: SUNDAY
A30: 24 | B30: Night | C30: =C29 | D30: =E29 | E30: 1691 | F30: =E30-D30
A31: 25 | B31: Day | C31: =C29+1 | D31: =E30 | E31: 1695 | F31: =E31-D31 | G31: =F31+F32
A32: 26 | B32: Night | C32: =C31 | D32: =E31 | E32: 1697 | F32: =E32-D32
A33: 27 | B33: Day | C33: =C31+1 | D33: =E32 | E33: 1700 | F33: =E33-D33 | G33: =F33+F34
A34: 28 | B34: Night | C34: =C33 | D34: =E33 | E34: 1701 | F34: =E34-D34
A35: 29 | B35: Day | C35: =C33+1 | D35: =E34 | E35: 1704 | F35: =E35-D35 | G35: =F35+F36
A36: 30 | B36: Night | C36: =C35 | D36: =E35 | E36: 1706 | F36: =E36-D36
A37: 31 | B37: Day | C37: =C35+1 | D37: =E36 | E37: 1708 | F37: =E37-D37 | G37: =F37+F38 | K37: 175
A38: 32 | B38: Night | C38: =C37 | D38: =E37 | E38: 1712 | F38: =E38-D38
A39: 33 | B39: Day | C39: =C37+1 | D39: =E38 | E39: 1713 | F39: =E39-D39 | G39: =F39+F40
A40: 34 | B40: Night | C40: =C39 | D40: =E39 | E40: 1715 | F40: =E40-D40
...

Sheet Aug-26
A1: Vendor Description | E1: EKTA ENTERPRISES
A2: Asset Discription | E2: XCMG Crawler CRANE
A3: Asset Capacity | E3: 45 Ton
A4: Billing Period | E4: 01-08-2026 TO 31-08-2026
A5: COMPANY NAME | E5: Hindustan Infrastructure solution Ahemdabaad
A6: SR. NO. | B6: Shift | C6: Date | D6: Starting HMR | E6: Closing HMR | F6: HMR | G6: Normal Shift Hours | H6: BD Start | I6: BD End | J6: Total B/D | K6: Diesel issued | L6: Diesel HMR | M6: Hours | N6: Remark
A7: 1 | B7: Day | C7: 46235 | D7: 1745 | E7: 1745 | F7: =E7-D7 | G7: =F7+F8
A8: 2 | B8: Night | C8: =C7 | D8: =E7 | E8: 1745 | F8: =E8-D8
A9: 3 | B9: Day | C9: =C7+1 | D9: =E8 | E9: 1745 | F9: =E9-D9 | G9: =F9+F10 | N9: Sunday
A10: 4 | B10: Night | C10: =C9 | D10: =E9 | E10: 1745 | F10: =E10-D10
A11: 5 | B11: Day | C11: =C9+1 | D11: =E10 | E11: 1745 | F11: =E11-D11 | G11: =F11+F12
A12: 6 | B12: Night | C12: =C11 | D12: =E11 | E12: 1745 | F12: =E12-D12
A13: 7 | B13: Day | C13: =C11+1 | D13: =E12 | E13: 1746 | F13: =E13-D13 | G13: =F13+F14
A14: 8 | B14: Night | C14: =C13 | D14: =E13 | E14: 1746 | F14: =E14-D14
A15: 9 | B15: Day | C15: =C13+1 | D15: =E14 | E15: 1746 | F15: =E15-D15 | G15: =F15+F16
A16: 10 | B16: Night | C16: =C15 | D16: =E15 | E16: 1746 | F16: =E16-D16
A17: 11 | B17: Day | C17: =C15+1 | D17: =E16 | E17: 1746 | F17: =E17-D17 | G17: =F17+F18
A18: 12 | B18: Night | C18: =C17 | D18: =E17 | E18: 1746 | F18: =E18-D18
A19: 13 | B19: Day | C19: =C17+1 | D19: =E18 | E19: 1748 | F19: =E19-D19 | G19: =F19+F20
A20: 14 | B20: Night | C20: =C19 | D20: =E19 | E20: 1748 | F20: =E20-D20
A21: 15 | B21: Day | C21: =C19+1 | D21: =E20 | E21: 1751 | F21: =E21-D21 | G21: =F21+F22
A22: 16 | B22: Night | C22: =C21 | D22: =E21 | E22: 1751 | F22: =E22-D22
A23: 17 | B23: Day | C23: =C21+1 | D23: =E22 | E23: 1751 | F23: =E23-D23 | G23: =F23+F24 | N23: Sunday
A24: 18 | B24: Night | C24: =C23 | D24: =E23 | E24: 1751 | F24: =E24-D24
A25: 19 | B25: Day | C25: =C23+1 | D25: =E24 | E25: 1751 | F25: =E25-D25 | G25: =F25+F26 | K25: 220
A26: 20 | B26: Night | C26: =C25 | D26: =E25 | E26: 1751 | F26: =E26-D26
A27: 21 | B27: Day | C27: =C25+1 | D27: =E26 | E27: 1751 | F27: =E27-D27 | G27: =F27+F28
A28: 22 | B28: Night | C28: =C27 | D28: =E27 | E28: 1751 | F28: =E28-D28
A29: 23 | B29: Day | C29: =C27+1 | D29: =E28 | E29: 1752 | F29: =E29-D29 | G29: =F29+F30
A30: 24 | B30: Night | C30: =C29 | D30: =E29 | E30: 1752 | F30: =E30-D30
A31: 25 | B31: Day | C31: =C29+1 | D31: =E30 | E31: 1752 | F31: =E31-D31 | G31: =F31+F32
A32: 26 | B32: Night | C32: =C31 | D32: =E31 | E32: 1752 | F32: =E32-D32
A33: 27 | B33: Day | C33: =C31+1 | D33: =E32 | E33: 1752 | F33: =E33-D33 | G33: =F33+F34
A34: 28 | B34: Night | C34: =C33 | D34: =E33 | E34: 1752 | F34: =E34-D34
A35: 29 | B35: Day | C35: =C33+1 | D35: =E34 | E35: 1752 | F35: =E35-D35 | G35: =F35+F36
A36: 30 | B36: Night | C36: =C35 | D36: =E35 | E36: 1753 | F36: =E36-D36
A37: 31 | B37: Day | C37: =C35+1 | D37: =E36 | E37: 1758 | F37: =E37-D37 | G37: =F37+F38 | N37: Sunday
A38: 32 | B38: Night | C38: =C37 | D38: =E37 | E38: 1759 | F38: =E38-D38
A39: 33 | B39: Day | C39: =C37+1 | D39: =E38 | E39: 1762 | F39: =E39-D39 | G39: =F39+F40
A40: 34 | B40: Night | C40: =C39 | D40: =E39 | E40: 1762 | F40: =E40-D40
...

Sheet Sep-26
A1: Vendor Description | E1: EKTA ENTERPRISES
A2: Asset Discription | E2: XCMG Crawler CRANE
A3: Asset Capacity | E3: 45 Ton
A4: Billing Period | E4: 01-09-2026 TO 30-09-2026
A5: COMPANY NAME | E5: Hindustan Infrastructure solution Ahemdabaad
A6: SR. NO. | B6: Shift | C6: Date | D6: Starting HMR | E6: Closing HMR | F6: HMR at Diesel Fill | G6: Normal Shift Hours | H6: Breakdown Start Time | I6: Breakdown End Time | J6: Breakdown Hours | K6: Diesel Issued (Ltr) | L6: HMR at Diesel Fill | M6: Hours | N6: Remark
A7: 1 | B7: Day | C7: 46266 | D7: ='Aug-26'!E68 | E7: 1804 | F7: =IF(OR(D7="",E7=""),0,E7-D7) | G7: =F7+F8 | K7: 270 | L7: 1802
A8: 2 | B8: Night | C8: 46266 | D8: =E7 | E8: 1806 | F8: =IF(OR(D8="",E8=""),0,E8-D8)
A9: 3 | B9: Day | C9: 46267 | D9: =E8 | E9: 1807 | F9: =IF(OR(D9="",E9=""),0,E9-D9) | G9: =F9+F10
A10: 4 | B10: Night | C10: 46267 | D10: =E9 | E10: 1807 | F10: =IF(OR(D10="",E10=""),0,E10-D10)
A11: 5 | B11: Day | C11: 46268 | D11: =E10 | E11: 1812 | F11: =IF(OR(D11="",E11=""),0,E11-D11) | G11: =F11+F12
A12: 6 | B12: Night | C12: 46268 | D12: =E11 | E12: 1814 | F12: =IF(OR(D12="",E12=""),0,E12-D12)
A13: 7 | B13: Day | C13: 46269 | D13: =E12 | E13: 1814 | F13: =IF(OR(D13="",E13=""),0,E13-D13) | G13: =F13+F14
A14: 8 | B14: Night | C14: 46269 | D14: =E13 | E14: 1814 | F14: =IF(OR(D14="",E14=""),0,E14-D14)
A15: 9 | B15: Day | C15: 46270 | D15: =E14 | E15: 1814 | F15: =IF(OR(D15="",E15=""),0,E15-D15) | G15: =F15+F16
A16: 10 | B16: Night | C16: 46270 | D16: =E15 | E16: 1814 | F16: =IF(OR(D16="",E16=""),0,E16-D16)
A17: 11 | B17: Day | C17: 46271 | D17: =E16 | E17: 1814 | F17: =IF(OR(D17="",E17=""),0,E17-D17) | G17: =F17+F18
A18: 12 | B18: Night | C18: 46271 | D18: =E17 | E18: 1814 | F18: =IF(OR(D18="",E18=""),0,E18-D18)
A19: 13 | B19: Day | C19: 46272 | D19: =E18 | E19: 1815 | F19: =IF(OR(D19="",E19=""),0,E19-D19) | G19: =F19+F20
A20: 14 | B20: Night | C20: 46272 | D20: =E19 | E20: 1815 | F20: =IF(OR(D20="",E20=""),0,E20-D20)
A21: 15 | B21: Day | C21: 46273 | D21: =E20 | E21: 1822 | F21: =IF(OR(D21="",E21=""),0,E21-D21) | G21: =F21+F22
A22: 16 | B22: Night | C22: 46273 | D22: =E21 | E22: 1822 | F22: =IF(OR(D22="",E22=""),0,E22-D22)
A23: 17 | B23: Day | C23: 46274 | D23: =E22 | E23: 1826 | F23: =IF(OR(D23="",E23=""),0,E23-D23) | G23: =F23+F24
A24: 18 | B24: Night | C24: 46274 | D24: =E23 | E24: 1826 | F24: =IF(OR(D24="",E24=""),0,E24-D24)
A25: 19 | B25: Day | C25: 46275 | D25: =E24 | E25: 1826 | F25: =IF(OR(D25="",E25=""),0,E25-D25) | G25: =F25+F26
A26: 20 | B26: Night | C26: 46275 | D26: =E25 | E26: 1826 | F26: =IF(OR(D26="",E26=""),0,E26-D26)
A27: 21 | B27: Day | C27: 46276 | D27: =E26 | E27: 1830 | F27: =IF(OR(D27="",E27=""),0,E27-D27) | G27: =F27+F28
A28: 22 | B28: Night | C28: 46276 | D28: =E27 | E28: 1830 | F28: =IF(OR(D28="",E28=""),0,E28-D28)
A29: 23 | B29: Day | C29: 46277 | D29: =E28 | E29: 1833 | F29: =IF(OR(D29="",E29=""),0,E29-D29) | G29: =F29+F30
A30: 24 | B30: Night | C30: 46277 | D30: =E29 | E30: 1834 | F30: =IF(OR(D30="",E30=""),0,E30-D30)
A31: 25 | B31: Day | C31: 46278 | D31: =E30 | E31: 1834 | F31: =IF(OR(D31="",E31=""),0,E31-D31) | G31: =F31+F32
A32: 26 | B32: Night | C32: 46278 | D32: =E31 | E32: 1834 | F32: =IF(OR(D32="",E32=""),0,E32-D32)
A33: 27 | B33: Day | C33: 46279 | D33: =E32 | E33: 1836 | F33: =IF(OR(D33="",E33=""),0,E33-D33) | G33: =F33+F34
A34: 28 | B34: Night | C34: 46279 | D34: =E33 | E34: 1836 | F34: =IF(OR(D34="",E34=""),0,E34-D34)
A35: 29 | B35: Day | C35: 46280 | D35: =E34 | E35: 1836 | F35: =IF(OR(D35="",E35=""),0,E35-D35) | G35: =F35+F36
A36: 30 | B36: Night | C36: 46280 | D36: =E35 | E36: 1836 | F36: =IF(OR(D36="",E36=""),0,E36-D36)
A37: 31 | B37: Day | C37: 46281 | D37: =E36 | E37: 1836 | F37: =IF(OR(D37="",E37=""),0,E37-D37) | G37: =F37+F38
A38: 32 | B38: Night | C38: 46281 | D38: =E37 | E38: 1836 | F38: =IF(OR(D38="",E38=""),0,E38-D38)
A39: 33 | B39: Day | C39: 46282 | D39: =E38 | E39: 1836 | F39: =IF(OR(D39="",E39=""),0,E39-D39) | G39: =F39+F40
A40: 34 | B40: Night | C40: 46282 | D40: =E39 | E40: 1836 | F40: =IF(OR(D40="",E40=""),0,E40-D40)
...

Sheet Summary
A1: XCMG Crawler CRANE
A2: MONTH | B2: TOTAL RUNNING HR | C2: TOTAL DIESEL CONSUMPTION | D2: MONTHLY AVG | E2: TOTAL B/D
A3: 46266 | B3: ='Sep-26'!G67 | C3: ='Sep-26'!K67 | D3: =zoomline80ton[[#This Row],[TOTAL DIESEL CONSUMPTION]]/zoomline80ton[[#This Row],[TOTAL RUNNING HR]] | E3: ='Sep-26'!J67
A4: 46235 | B4: ='Aug-26'!G69 | C4: ='Aug-26'!K69 | D4: =zoomline80ton[[#This Row],[TOTAL DIESEL CONSUMPTION]]/zoomline80ton[[#This Row],[TOTAL RUNNING HR]] | E4: ='Aug-26'!J69
