Workbook

Sheet PO
A1: Company Name
A2: Site Location
A3: State
A4: PO Start Date | B4: 45962
A5: PO End Date | B5: 48153
A6: Asset Type
A7: Make | B7: RST
A8: Asset Qty | B8: 1, 2=3
A9: Location | B9: Dhirpur, Dalpatpur
A10: Model
A11: Asset#
A12: Loading Capacity
A13: Work Type
A14: Monthly Hiring Charges | B14: 9,00,000
A15: Diesel | B15: Hind Terminal
A16: Diesel Tank Full | B16: Yes
A17: Maximum Running Hour | B17: 520 Hours
A18: Breakdwon Allowed | B18: 120 Hours
A19: Moves per Hour
A20: Supervisor
A21: Supervisor Contact Number
A22: Operator
A23: Helper
A24: Shift
A25: Machine Billing
A26: Diesel Billing
A27: Billing Cycle
A28: Billing
A29: Billing Medium
A30: Document Required for billing
A31: Email ID Used
A32: Sent to | B32: Sahil.jain@hindterminals.com
A33: CC | B33: -
A34: Subject Line | B34: Hind Terminal-Dhirpur-NOV25-Invoice Submission
A35: Dhirpur Billing Address
A36: Dalpatpur Billing Address 1
A37: Dalpatpur Billing Address 2
A38: Company's Contact Person | B38: Sahil Jain
A39: Company's Contact Number
A40: Document Required for billing | B40: Labour Wellfare fund Attendance ESI PF Reciept ECR PF Challan Daily Logsheet Monthly maintanance Logsheet Invoice
...

Sheet NOV-25
A1: DATE | B1: KAMLAR- | D1: Daily Running Hours | E1: Breakdown start time | F1: Breakdown end time | G1: Total Breakdown Hour | H1: Breakdown Reason | I1: DIESEL Consumed | J1: Diesel HMR | K1: Hours | L1: Average | M1: Container Reading | N1: Container Count
A2: PREV Stock | B2: Start HMR | C2: End HMR
A3: 45962 | D3: =C3-B3
A4: =A3+1 | D4: =C4-B4
A5: =A4+1 | D5: =C5-B5
A6: =A5+1 | D6: =C6-B6
A7: =A6+1 | D7: =C7-B7
A8: =A7+1 | D8: =C8-B8
A9: =A8+1 | B9: 22 | C9: 22 | D9: =C9-B9 | I9: 470 | J9: 22
A10: =A9+1 | B10: =C9 | C10: 22 | D10: =C10-B10
A11: =A10+1 | B11: =C10 | C11: 35 | D11: =C11-B11
A12: =A11+1 | B12: =C11 | C12: 45 | D12: =C12-B12
A13: =A12+1 | B13: =C12 | C13: 48 | D13: =C13-B13 | I13: 260 | J13: 45 | K13: =J13-J9 | L13: =I13/K13
A14: =A13+1 | B14: =C13 | C14: 53 | D14: =C14-B14
A15: =A14+1 | B15: =C14 | C15: 65 | D15: =C15-B15
A16: =A15+1 | B16: =C15 | C16: 68 | D16: =C16-B16
A17: =A16+1 | B17: =C16 | C17: 68 | D17: =C17-B17
A18: =A17+1 | B18: =C17 | C18: 70 | D18: =C18-B18
A19: =A18+1 | B19: =C18 | C19: 83 | D19: =C19-B19 | I19: 320 | J19: 74 | K19: =J19-J13 | L19: =I19/K19
A20: =A19+1 | B20: =C19 | C20: 88 | D20: =C20-B20
A21: =A20+1 | B21: =C20 | C21: 93 | D21: =C21-B21
A22: =A21+1 | B22: =C21 | C22: 105 | D22: =C22-B22
A23: =A22+1 | B23: =C22 | C23: 110 | D23: =C23-B23 | I23: 380 | J23: 105 | K23: =J23-J19 | L23: =I23/K23
A24: =A23+1 | B24: =C23 | C24: 121 | D24: =C24-B24
A25: =A24+1 | B25: =C24 | C25: 129 | D25: =C25-B25
A26: =A25+1 | B26: =C25 | C26: 137 | D26: =C26-B26
A27: =A26+1 | B27: =C26 | C27: 143 | D27: =C27-B27 | I27: 395.01 | J27: 136 | K27: =J27-J23 | L27: =I27/K27
A28: =A27+1 | B28: =C27 | C28: 150 | D28: =C28-B28
A29: =A28+1 | B29: =C28 | C29: 158 | D29: =C29-B29
A30: =A29+1 | B30: =C29 | C30: 170 | D30: =C30-B30
A31: =A30+1 | B31: =C30 | C31: 182 | D31: =C31-B31
A32: =A31+1 | B32: =C31 | C32: 190 | D32: =C32-B32
D33: =SUM(D3:D32) | G33: =SUM(G4:G32) | I33: =SUM(I3:I32) | K33: =SUM(K3:K32) | L33: =I33/K33 | N33: =SUM(N3:N32)
A35: Monthly Hiring Charges | B35: 900000
A36: 1 Day Hiring Charges/31 | B36: =B35/30
A37: 24 Days Hiring Charges | B37: =B36*24
A38: Bill Amount | B38: =B37

Sheet DEC-25
A1: DATE | B1: KAMLAR-2 | D1: Daily Running Hours | E1: Breakdown start time | F1: Breakdown end time | G1: Total Breakdown Hour | H1: Breakdown Reason | I1: DIESEL Consumed | J1: Diesel HMR | K1: Hours | L1: Average | M1: Container Reading | N1: Container Count
A2: PREV Stock | B2: Start HMR | C2: End HMR | J2: 136
A3: 45992 | B3: 190 | C3: 205 | D3: =C3-B3
A4: =A3+1 | B4: =C3 | C4: 218 | D4: =C4-B4
A5: =A4+1 | B5: =C4 | C5: 219 | D5: =C5-B5
A6: =A5+1 | B6: =C5 | C6: 226 | D6: =C6-B6 | I6: 218 | J6: 219 | K6: =J6-J2
A7: =A6+1 | B7: =C6 | C7: 241 | D7: =C7-B7
A8: =A7+1 | B8: =C7 | C8: 250 | D8: =C8-B8
A9: =A8+1 | B9: =C8 | C9: 266 | D9: =C9-B9 | I9: 400 | J9: 250 | K9: =J9-J6 | L9: =I9/K9
A10: =A9+1 | B10: =C9 | C10: 278 | D10: =C10-B10
A11: =A10+1 | B11: =C10 | C11: 293 | D11: =C11-B11 | I11: 385 | J11: 282 | K11: =J11-J9 | L11: =I11/K11
A12: =A11+1 | B12: =C11 | C12: 302 | D12: =C12-B12 | I12: 360 | J12: 307 | K12: =J12-J11 | L12: =I12/K12
A13: =A12+1 | B13: =C12 | C13: 319 | D13: =C13-B13
A14: =A13+1 | B14: =C13 | C14: 331 | D14: =C14-B14 | I14: 428 | J14: 337 | K14: =J14-J12 | L14: =I14/K14
A15: =A14+1 | B15: =C14 | C15: 348 | D15: =C15-B15
A16: =A15+1 | B16: =C15 | C16: 355 | D16: =C16-B16
A17: =A16+1 | B17: =C16 | C17: 369 | D17: =C17-B17 | I17: 310 | J17: 362 | K17: =J17-J14 | L17: =I17/K17
A18: =A17+1 | B18: =C17 | C18: 376 | D18: =C18-B18
A19: =A18+1 | B19: =C18 | C19: 380 | D19: =C19-B19
A20: =A19+1 | B20: =C19 | C20: 393 | D20: =C20-B20
A21: =A20+1 | B21: =C20 | C21: 403 | D21: =C21-B21 | I21: 367.01 | J21: 395 | K21: =J21-J17 | L21: =I21/K21
A22: =A21+1 | B22: =C21 | C22: 416 | D22: =C22-B22
A23: =A22+1 | B23: =C22 | C23: 419 | D23: =C23-B23
A24: =A23+1 | B24: =C23 | C24: 423 | D24: =C24-B24
A25: =A24+1 | B25: =C24 | C25: 435 | D25: =C25-B25 | I25: 430 | J25: 429 | K25: =J25-J21 | L25: =I25/K25
A26: =A25+1 | B26: =C25 | C26: 441 | D26: =C26-B26
A27: =A26+1 | B27: =C26 | C27: 444 | D27: =C27-B27
A28: =A27+1 | B28: =C27 | C28: 451 | D28: =C28-B28 | I28: 200 | J28: 445 | K28: =J28-J25 | L28: =I28/K28
A29: =A28+1 | B29: =C28 | C29: 461 | D29: =C29-B29
A30: =A29+1 | B30: =C29 | C30: 466 | D30: =C30-B30 | I30: 300 | J30: 463 | K30: =J30-J28 | L30: =I30/K30
A31: =A30+1 | B31: =C30 | C31: 480 | D31: =C31-B31
A32: =A31+1 | B32: =C31 | C32: 489 | D32: =C32-B32 | I32: 225 | J32: 485 | K32: =J32-J30 | L32: =I32/K32
A33: =A32+1 | B33: =C32 | C33: 498 | D33: =C33-B33
D34: =SUM(D3:D33) | G34: =SUM(G3:G33) | I34: =SUM(I3:I33) | K34: =SUM(K3:K33) | L34: =I34/K34 | N34: =SUM(N3:N33)

Sheet JAN-2026
A1: DATE | B1: KAMLAR- Dhirpur | D1: Daily Running Hours | E1: Breakdown start time | F1: Breakdown end time | G1: Total Breakdown Hour | H1: Breakdown Reason | I1: DIESEL Consumed | J1: Diesel HMR | K1: Hours | L1: Average | M1: KAMLAR-1-Dalpatpur | O1: Daily Running Hours | P1: Breakdown start time | Q1: Breakdown end time | R1: Total Breakdown Hour | S1: Breakdown Reason | T1: DIESEL Consumed | U1: Diesel HMR | V1: Hours | W1: Average | X1: KAMLAR-2-Dalpatpur | Z1: Daily Running Hours | AA1: Breakdown start time | AB1: Breakdown end time | AC1: Total Breakdown Hour | AD1: Breakdown Reason | AE1: DIESEL Consumed | AF1: Diesel HMR | AG1: Hours | AH1: Average
A2: PREV Stock | B2: Start HMR | C2: End HMR | J2: 485 | M2: Start HMR | N2: End HMR | X2: Start HMR | Y2: End HMR
A3: 46023 | B3: 498 | C3: 501 | D3: =C3-B3 | I3: 178 | J3: 498 | K3: =J3-J2 | L3: =I3/K3
A4: =A3+1 | B4: =C3 | C4: 506 | D4: =C4-B4
A5: =A4+1 | B5: =C4 | C5: 510 | D5: =C5-B5 | I5: 105 | J5: 506 | K5: =J5-J3 | L5: =I5/K5
A6: =A5+1 | B6: =C5 | C6: 523 | D6: =C6-B6
A7: =A6+1 | B7: =C6 | C7: 531 | D7: =C7-B7 | I7: 225 | J7: 525 | K7: =J7-J5 | L7: =I7/K7
A8: =A7+1 | B8: =C7 | C8: 541 | D8: =C8-B8
A9: =A8+1 | B9: =C8 | C9: 548 | D9: =C9-B9
A10: =A9+1 | B10: =C9 | C10: 559 | D10: =C10-B10
A11: =A10+1 | B11: =C10 | C11: 565 | D11: =C11-B11 | I11: 205 | J11: 559 | K11: =J11-J7 | L11: =I11/K11
A12: =A11+1 | B12: =C11 | C12: 573 | D12: =C12-B12 | I12: 140 | J12: 570 | K12: =J12-J11 | L12: =I12/K12
A13: =A12+1 | B13: =C12 | C13: 575 | D13: =C13-B13
A14: =A13+1 | B14: =C13 | C14: 583 | D14: =C14-B14
A15: =A14+1 | B15: =C14 | C15: 590 | D15: =C15-B15 | I15: 170 | J15: 584 | K15: =J15-J12 | L15: =I15/K15
A16: =A15+1 | B16: =C15 | C16: 602 | D16: =C16-B16
A17: =A16+1 | B17: =C16 | C17: 612 | D17: =C17-B17 | I17: 260 | J17: 604 | K17: =J17-J15 | L17: =I17/K17
A18: =A17+1 | B18: =C17 | C18: 620 | D18: =C18-B18
A19: =A18+1 | B19: =C18 | C19: 624 | D19: =C19-B19 | I19: 157 | J19: 620 | K19: =J19-J17 | L19: =I19/K19
A20: =A19+1 | B20: =C19 | C20: 624 | D20: =C20-B20
A21: =A20+1 | B21: =C20 | C21: 629 | D21: =C21-B21 | M21: Assesmble
A22: =A21+1 | B22: =C21 | C22: 637 | D22: =C22-B22 | I22: 120 | J22: 630 | K22: =J22-J19 | L22: =I22/K22
A23: =A22+1 | B23: =C22 | C23: 644 | D23: =C23-B23
A24: =A23+1 | B24: =C23 | C24: 659 | D24: =C24-B24 | I24: 286 | J24: 652 | K24: =J24-J22 | L24: =I24/K24
A25: =A24+1 | B25: =C24 | C25: 665 | D25: =C25-B25
A26: =A25+1 | B26: =C25 | C26: 674 | D26: =C26-B26 | I26: 240 | J26: 669 | K26: =J26-J24 | L26: =I26/K26
A27: =A26+1 | B27: =C26 | C27: 694 | D27: =C27-B27
A28: =A27+1 | B28: =C27 | C28: 698 | D28: =C28-B28 | I28: 325 | J28: 694 | K28: =J28-J26 | L28: =I28/K28
A29: =A28+1 | B29: =C28 | C29: 705 | D29: =C29-B29
A30: =A29+1 | B30: =C29 | C30: 721 | D30: =C30-B30 | I30: 200 | J30: 708 | K30: =J30-J28 | L30: =I30/K30
A31: =A30+1 | B31: =C30 | C31: 742 | D31: =C31-B31
A32: =A31+1 | B32: =C31 | C32: 755 | D32: =C32-B32 | I32: 482 | J32: 744 | K32: =J32-J30 | L32: =I32/K32
A33: =A32+1 | B33: =C32 | C33: 762 | D33: =C33-B33
D34: =SUM(D3:D33) | G34: =SUM(G3:G33) | I34: =SUM(I3:I33) | K34: =SUM(K3:K33) | L34: =I34/K34 | O34: =SUM(O3:O33) | R34: =SUM(R3:R33) | T34: =SUM(T3:T33) | V34: =SUM(V3:V33) | W34: =T34/V34 | Z34: =SUM(Z3:Z33) | AC34: =SUM(AC3:AC33) | AE34: =SUM(AE3:AE33) | AG34: =SUM(AG3:AG33) | AH34: =AE34/AG34
B36: Ony Dhirpur invoice sent with full amount

Sheet FEB-26
A1: DATE | B1: KAMLAR- Dhirpur FEB-2025 | D1: Daily Running Hours | E1: Breakdown start time | F1: Breakdown end time | G1: Total Breakdown Hour | H1: Breakdown Reason | I1: DIESEL Consumed | J1: Diesel HMR | K1: Hours | L1: Average | M1: KAMLAR-1-Dalpatpur | O1: Daily Running Hours | P1: Breakdown start time | Q1: Breakdown end time | R1: Total Breakdown Hour | S1: Breakdown Reason | T1: DIESEL Consumed | U1: Diesel HMR | V1: Hours | W1: Average | X1: KAMLAR-2-Dalpatpur | Z1: Daily Running Hours | AA1: Breakdown start time | AB1: Breakdown end time | AC1: Total Breakdown Hour | AD1: Breakdown Reason | AE1: DIESEL Consumed | AF1: Diesel HMR | AG1: Hours | AH1: Average
A2: PREV Stock | B2: Start HMR | C2: End HMR | J2: 744 | M2: Start HMR | N2: End HMR | X2: Start HMR | Y2: End HMR
A3: 46054 | B3: 762 | C3: 785 | D3: =C3-B3 | I3: 335 | J3: 768 | K3: =J3-J2 | L3: =I3/K3 | M3: 43 | N3: 43 | O3: =N3-M3
A4: =A3+1 | B4: =C3 | C4: 785 | D4: =C4-B4 | M4: =N3 | N4: 43 | O4: =N4-M4
A5: =A4+1 | B5: =C4 | C5: 789 | D5: =C5-B5 | I5: 180 | J5: 786 | K5: =J5-J3 | L5: =I5/K5 | M5: =N4 | N5: 43 | O5: =N5-M5
A6: =A5+1 | B6: =C5 | C6: 803 | D6: =C6-B6 | M6: =N5 | N6: 43 | O6: =N6-M6
A7: =A6+1 | B7: =C6 | C7: 810 | D7: =C7-B7 | I7: 285 | J7: 804 | K7: =J7-J5 | L7: =I7/K7 | M7: =N6 | N7: 43 | O7: =N7-M7
A8: =A7+1 | B8: =C7 | C8: 814 | D8: =C8-B8 | M8: =N7 | N8: 43 | O8: =N8-M8
A9: =A8+1 | B9: =C8 | C9: 829 | D9: =C9-B9 | I9: 142 | J9: 814 | K9: =J9-J7 | L9: =I9/K9 | M9: =N8 | N9: 43 | O9: =N9-M9
A10: =A9+1 | B10: =C9 | C10: 844 | D10: =C10-B10 | M10: =N9 | N10: 43 | O10: =N10-M10
A11: =A10+1 | B11: =C10 | C11: 848 | D11: =C11-B11 | I11: 460 | J11: 844 | K11: =J11-J9 | L11: =I11/K11 | M11: =N10 | N11: 43 | O11: =N11-M11
A12: =A11+1 | B12: =C11 | C12: 858 | D12: =C12-B12 | M12: =N11 | N12: 43 | O12: =N12-M12
A13: =A12+1 | B13: =C12 | C13: 876 | D13: =C13-B13 | I13: 254 | J13: 862 | K13: =J13-J11 | L13: =I13/K13 | M13: =N12 | N13: 43 | O13: =N13-M13
A14: =A13+1 | B14: =C13 | C14: 891 | D14: =C14-B14 | I14: 245 | J14: 882 | K14: =J14-J13 | L14: =I14/K14 | M14: =N13 | N14: 43 | O14: =N14-M14
A15: =A14+1 | B15: =C14 | C15: 898 | D15: =C15-B15 | M15: =N14 | N15: 43 | O15: =N15-M15
A16: =A15+1 | B16: =C15 | C16: 911 | D16: =C16-B16 | M16: =N15 | N16: 43 | O16: =N16-M16
A17: =A16+1 | B17: =C16 | C17: 915 | D17: =C17-B17 | I17: 365 | J17: 911 | K17: =J17-J14 | L17: =I17/K17 | M17: =N16 | N17: 43 | O17: =N17-M17
A18: =A17+1 | B18: =C17 | C18: 930 | D18: =C18-B18 | M18: =N17 | N18: 43 | O18: =N18-M18
A19: =A18+1 | B19: =C18 | C19: 951 | D19: =C19-B19 | I19: 330 | J19: 936 | K19: =J19-J17 | L19: =I19/K19 | M19: =N18 | N19: 43 | O19: =N19-M19
A20: =A19+1 | B20: =C19 | C20: 965 | D20: =C20-B20 | I20: 205 | J20: 957 | K20: =J20-J19 | L20: =I20/K20 | M20: =N19 | N20: 43 | O20: =N20-M20
A21: =A20+1 | B21: =C20 | C21: 981 | D21: =C21-B21 | M21: =N20 | N21: 43 | O21: =N21-M21
A22: =A21+1 | B22: =C21 | C22: 991 | D22: =C22-B22 | I22: 370 | J22: 982 | K22: =J22-J20 | L22: =I22/K22 | M22: =N21 | N22: 43 | O22: =N22-M22
A23: =A22+1 | B23: =C22 | C23: 1001 | D23: =C23-B23 | M23: =N22 | N23: 43 | O23: =N23-M23
A24: =A23+1 | B24: =C23 | C24: 1012 | D24: =C24-B24 | I24: 325 | J24: 1002 | K24: =J24-J22 | L24: =I24/K24 | M24: =N23 | N24: 43 | O24: =N24-M24
A25: =A24+1 | B25: =C24 | C25: 1028 | D25: =C25-B25 | I25: 155 | J25: 1015 | K25: =J25-J24 | L25: =I25/K25 | M25: =N24 | N25: 43 | O25: =N25-M25
A26: =A25+1 | B26: =C25 | C26: 1045 | D26: =C26-B26 | I26: 268 | J26: 1033 | K26: =J26-J25 | L26: =I26/K26 | M26: =N25 | N26: 43 | O26: =N26-M26
A27: =A26+1 | B27: =C26 | C27: 1064 | D27: =C27-B27 | I27: 275 | J27: 1051 | K27: =J27-J26 | L27: =I27/K27 | M27: =N26 | N27: 43 | O27: =N27-M27
A28: =A27+1 | B28: =C27 | C28: 1078 | D28: =C28-B28 | I28: 196 | J28: 1066 | K28: =J28-J27 | L28: =I28/K28 | M28: =N27 | N28: 43 | O28: =N28-M28
A29: =A28+1 | B29: =C28 | C29: 1099 | D29: =C29-B29 | I29: 232 | J29: 1083 | K29: =J29-J28 | L29: =I29/K29 | M29: =N28 | N29: 43 | O29: =N29-M29
A30: =A29+1 | B30: =C29 | C30: 1113 | D30: =C30-B30 | I30: 330 | J30: 1104 | K30: =J30-J29 | L30: =I30/K30 | M30: =N29 | N30: 43 | O30: =N30-M30
D31: =SUM(D3:D30) | G31: =SUM(G3:G30) | I31: =SUM(I3:I30) | K31: =SUM(K3:K30) | L31: =I31/K31 | O31: =SUM(O3:O30) | R31: =SUM(R3:R30) | T31: =SUM(T3:T30) | V31: =SUM(V3:V30) | W31: =T31/V31 | Z31: =SUM(Z3:Z30) | AC31: =SUM(AC3:AC30) | AE31: =SUM(AE3:AE30) | AG31: =SUM(AG3:AG30) | AH31: =AE31/AG31

Sheet MAR26
A1: DATE | B1: KAMLAR- Dhirpur MAR-2025 | D1: Daily Running Hours | E1: Breakdown start time | F1: Breakdown end time | G1: Total Breakdown Hour | H1: Breakdown Reason | I1: DIESEL Consumed | J1: Diesel HMR | K1: Hours | L1: Average | M1: KAMLAR-1-Dalpatpur | O1: Daily Running Hours | P1: Breakdown start time | Q1: Breakdown end time | R1: Total Breakdown Hour | S1: Breakdown Reason | T1: DIESEL Consumed | U1: Diesel HMR | V1: Hours | W1: Average | X1: KAMLAR-2-Dalpatpur | Z1: Daily Running Hours | AA1: Breakdown start time | AB1: Breakdown end time | AC1: Total Breakdown Hour | AD1: Breakdown Reason | AE1: DIESEL Consumed | AF1: Diesel HMR | AG1: Hours | AH1: Average
A2: PREV Stock | B2: Start HMR | C2: End HMR | J2: 1104 | M2: Start HMR | N2: End HMR | X2: Start HMR | Y2: End HMR
A3: 46082 | B3: 1113 | C3: 1119 | D3: =C3-B3 | M3: 43 | N3: 43 | O3: =N3-M3
A4: =A3+1 | B4: =C3 | C4: 1128 | D4: =C4-B4 | I4: 250 | J4: 1121 | K4: =J4-J2 | L4: =I4/K4 | M4: =N3 | N4: 43 | O4: =N4-M4 | X4: Assesmble
A5: =A4+1 | B5: =C4 | C5: 1137 | D5: =C5-B5 | I5: 196 | J5: 1134 | K5: =J5-J4 | L5: =I5/K5 | M5: =N4 | N5: 43 | O5: =N5-M5
A6: =A5+1 | B6: =C5 | C6: 1138 | D6: =C6-B6 | M6: =N5 | N6: 43 | O6: =N6-M6
A7: =A6+1 | B7: =C6 | C7: 1141 | D7: =C7-B7 | M7: =N6 | N7: 43 | O7: =N7-M7
A8: =A7+1 | B8: =C7 | C8: 1143 | D8: =C8-B8 | M8: =N7 | N8: 43 | O8: =N8-M8
A9: =A8+1 | B9: =C8 | C9: 1149 | D9: =C9-B9 | I9: 193 | J9: 1148 | K9: =J9-J5 | L9: =I9/K9 | M9: =N8 | N9: 43 | O9: =N9-M9
A10: =A9+1 | B10: =C9 | C10: 1150 | D10: =C10-B10 | M10: =N9 | N10: 43 | O10: =N10-M10
A11: =A10+1 | B11: =C10 | C11: 1153 | D11: =C11-B11 | M11: 44 | N11: 44 | O11: =N11-M11 | X11: 22 | Y11: 22 | Z11: =Y11-X11
A12: =A11+1 | B12: =C11 | C12: 1162 | D12: =C12-B12 | I12: 75 | J12: 1153 | K12: =J12-J9 | L12: =I12/K12 | M12: =N11 | N12: 45 | O12: =N12-M12 | X12: =Y11 | Y12: 22 | Z12: =Y12-X12
A13: =A12+1 | B13: =C12 | C13: 1166 | D13: =C13-B13 | M13: =N12 | N13: 45 | O13: =N13-M13 | X13: =Y12 | Y13: 23 | Z13: =Y13-X13
A14: =A13+1 | B14: =C13 | C14: 1170 | D14: =C14-B14 | I14: 186 | J14: N/F | M14: =N13 | N14: 45 | O14: =N14-M14 | X14: =Y13 | Y14: 23 | Z14: =Y14-X14
A15: =A14+1 | B15: =C14 | C15: 1173 | D15: =C15-B15 | M15: =N14 | N15: 45 | O15: =N15-M15 | X15: =Y14 | Y15: 23 | Z15: =Y15-X15
A16: =A15+1 | B16: =C15 | C16: 1182 | D16: =C16-B16 | M16: =N15 | N16: 45 | O16: =N16-M16 | X16: =Y15 | Y16: 23 | Z16: =Y16-X16
A17: =A16+1 | B17: =C16 | C17: 1185 | D17: =C17-B17 | M17: =N16 | N17: 45 | O17: =N17-M17 | X17: =Y16 | Y17: 23 | Z17: =Y17-X17
A18: =A17+1 | B18: =C17 | C18: 1193 | D18: =C18-B18 | I18: 291 | J18: 1185 | K18: =J18-J12 | L18: =(I18+I14)/K18 | M18: =N17 | N18: 45 | O18: =N18-M18 | X18: =Y17 | Y18: 23 | Z18: =Y18-X18
A19: =A18+1 | B19: =C18 | C19: 1208 | D19: =C19-B19 | M19: =N18 | N19: 45 | O19: =N19-M19 | X19: =Y18 | Y19: 23 | Z19: =Y19-X19
A20: =A19+1 | B20: =C19 | C20: 1214 | D20: =C20-B20 | I20: 350 | J20: 1209 | K20: =J20-J18 | L20: =I20/K20 | M20: =N19 | N20: 45 | O20: =N20-M20 | X20: =Y19 | Y20: 23 | Z20: =Y20-X20
A21: =A20+1 | B21: =C20 | C21: 1230 | D21: =C21-B21 | M21: =N20 | N21: 45 | O21: =N21-M21 | X21: =Y20 | Y21: 23 | Z21: =Y21-X21
A22: =A21+1 | B22: =C21 | C22: 1245 | D22: =C22-B22 | I22: 400 | J22: 1233 | K22: =J22-J20 | L22: =I22/K22 | M22: =N21 | N22: 45 | O22: =N22-M22 | X22: =Y21 | Y22: 23 | Z22: =Y22-X22
A23: =A22+1 | B23: =C22 | C23: 1253 | D23: =C23-B23 | M23: =N22 | N23: 45 | O23: =N23-M23 | X23: =Y22 | Y23: 24 | Z23: =Y23-X23
A24: =A23+1 | B24: =C23 | C24: 1256 | D24: =C24-B24 | I24: 250 | J24: 1253 | K24: =J24-J22 | L24: =I24/K24 | M24: =N23 | N24: 46 | O24: =N24-M24 | X24: =Y23 | Y24: 24 | Z24: =Y24-X24
A25: =A24+1 | B25: =C24 | C25: 1265 | D25: =C25-B25 | M25: =N24 | N25: 46 | O25: =N25-M25 | X25: =Y24 | Y25: 24 | Z25: =Y25-X25
A26: =A25+1 | B26: =C25 | C26: 1278 | D26: =C26-B26 | I26: 160 | J26: 1267 | K26: =J26-J24 | L26: =I26/K26 | M26: =N25 | N26: 46 | O26: =N26-M26 | X26: =Y25 | Y26: 24 | Z26: =Y26-X26
A27: =A26+1 | B27: =C26 | C27: 1291 | D27: =C27-B27 | I27: 240 | J27: 1280 | K27: =J27-J26 | L27: =I27/K27 | M27: =N26 | N27: 46 | O27: =N27-M27 | X27: =Y26 | Y27: 24 | Z27: =Y27-X27
A28: =A27+1 | B28: =C27 | C28: 1300 | D28: =C28-B28 | I28: 225 | J28: 1296 | K28: =J28-J27 | L28: =I28/K28 | M28: =N27 | N28: 46 | O28: =N28-M28 | X28: =Y27 | Y28: 24 | Z28: =Y28-X28
A29: =A28+1 | B29: =C28 | C29: 1305 | D29: =C29-B29 | M29: =N28 | N29: 46 | O29: =N29-M29 | X29: =Y28 | Y29: 24 | Z29: =Y29-X29
A30: =A29+1 | B30: =C29 | C30: 1317 | D30: =C30-B30 | I30: 211 | J30: 1310 | K30: =J30-J28 | L30: =I30/K30 | M30: =N29 | N30: 47 | O30: =N30-M30 | X30: =Y29 | Y30: 24 | Z30: =Y30-X30
A31: =A30+1 | B31: =C30 | C31: 1321 | D31: =C31-B31 | M31: =N30 | N31: 48 | O31: =N31-M31 | X31: =Y30 | Y31: 24 | Z31: =Y31-X31
A32: =A31+1 | B32: =C31 | C32: 1332 | D32: =C32-B32 | I32: 170 | J32: 1323 | K32: =J32-J30 | L32: =I32/K32 | M32: =N31 | N32: 50 | O32: =N32-M32 | T32: 287 | U32: 49 | X32: =Y31 | Y32: 24 | Z32: =Y32-X32 | AE32: 450 | AF32: 24
A33: =A32+1 | B33: =C32 | C33: 1342 | D33: =C33-B33 | I33: 175 | J33: 1333 | K33: =J33-J32 | L33: =I33/K33 | M33: =N32 | N33: 52 | O33: =N33-M33 | X33: =Y32 | Y33: 24 | Z33: =Y33-X33
D34: =SUM(D3:D33) | G34: =SUM(G3:G30) | I34: =SUM(I3:I33) | K34: =SUM(K3:K33) | L34: =I34/K34 | O34: =SUBTOTAL(9,O3:O33) | R34: =SUM(R3:R30) | T34: 287 | V34: =SUM(V3:V30) | W34: =T34/V34 | Z34: =SUBTOTAL(9,Z3:Z33) | AC34: =SUM(AC3:AC30) | AE34: 450 | AG34: =SUM(AG3:AG30) | AH34: =AE34/AG34
A36: Full Amount | M36: Full Amount | X36: Monthly Hiring Charges | Y36: 900000
X37: 1 Day Hiring Charges/31 | Y37: =Y36/31
X38: 30 Days Hiring Charges | Y38: =Y37*30
X39: Bill Amount | Y39: =Y38

Sheet APR-26
A1: 46113 | B1: KAMLAR-DHIRPUR | D1: Daily Running Hours | E1: Breakdown start time | F1: Breakdown end time | G1: Total Breakdown Hour | H1: Breakdown Reason | I1: DIESEL Consumed | J1: Diesel HMR | K1: Hours | L1: Average | M1: KAMLAR-1-Dalpatpur | O1: Daily Running Hours | P1: Breakdown start time | Q1: Breakdown end time | R1: Total Breakdown Hour | S1: Breakdown Reason | T1: DIESEL Consumed | U1: Diesel HMR | V1: Hours | W1: Average | X1: KAMLAR-2-Dalpatpur | Z1: Daily Running Hours | AA1: Breakdown start time | AB1: Breakdown end time | AC1: Total Breakdown Hour | AD1: Breakdown Reason | AE1: DIESEL Consumed | AF1: Diesel HMR | AG1: Hours | AH1: Average
A2: PREV Stock | B2: Start HMR | C2: End HMR | J2: 1333 | M2: Start HMR | N2: End HMR | T2: 287 | U2: 49 | X2: Start HMR | Y2: End HMR | AE2: 450 | AF2: 24
A3: 46113 | B3: 1342 | C3: 1348 | D3: =C3-B3 | I3: 200 | J3: 1345 | K3: =J3-J2 | L3: =I3/K3 | M3: 52 | N3: 57 | O3: =N3-M3 | X3: 24 | Y3: 24 | Z3: =Y3-X3
A4: =A3+1 | B4: =C3 | C4: 1354 | D4: =C4-B4 | M4: =N3 | N4: 62 | O4: =N4-M4 | X4: =Y3 | Y4: 25 | Z4: =Y4-X4
A5: =A4+1 | B5: =C4 | C5: 1355 | D5: =C5-B5 | M5: =N4 | N5: 67 | O5: =N5-M5 | X5: =Y4 | Y5: 25 | Z5: =Y5-X5
A6: =A5+1 | B6: =C5 | C6: 1359 | D6: =C6-B6 | I6: 190 | J6: 1356 | K6: =J6-J3 | L6: =I6/K6 | M6: =N5 | N6: 72 | O6: =N6-M6 | X6: =Y5 | Y6: 25 | Z6: =Y6-X6
A7: =A6+1 | B7: =C6 | C7: 1368 | D7: =C7-B7 | M7: =N6 | N7: 78 | O7: =N7-M7 | X7: =Y6 | Y7: 25 | Z7: =Y7-X7
A8: =A7+1 | B8: =C7 | C8: 1369 | D8: =C8-B8 | M8: =N7 | N8: 85 | O8: =N8-M8 | X8: =Y7 | Y8: 25 | Z8: =Y8-X8
A9: =A8+1 | B9: =C8 | C9: 1377 | D9: =C9-B9 | I9: 177 | J9: 1372 | K9: =J9-J6 | L9: =I9/K9 | M9: =N8 | N9: 90 | O9: =N9-M9 | X9: =Y8 | Y9: 25 | Z9: =Y9-X9
A10: =A9+1 | B10: =C9 | C10: 1382 | D10: =C10-B10 | M10: =N9 | N10: 96 | O10: =N10-M10 | T10: 100 | U10: 91 | V10: =U10-U2 | W10: =T10/V10 | X10: =Y9 | Y10: 28 | Z10: =Y10-X10
A11: =A10+1 | B11: =C10 | C11: 1384 | D11: =C11-B11 | M11: =N10 | N11: 99 | O11: =N11-M11 | X11: =Y10 | Y11: 28 | Z11: =Y11-X11
A12: =A11+1 | B12: =C11 | C12: 1386 | D12: =C12-B12 | I12: 167 | J12: N/F | M12: =N11 | N12: 103 | O12: =N12-M12 | T12: 300 | U12: N/F | X12: =Y11 | Y12: 28 | Z12: =Y12-X12
A13: =A12+1 | B13: =C12 | C13: 1403 | D13: =C13-B13 | M13: =N12 | N13: 106 | O13: =N13-M13 | X13: =Y12 | Y13: 28 | Z13: =Y13-X13
A14: =A13+1 | B14: =C13 | C14: 1409 | D14: =C14-B14 | I14: 268 | J14: N/F | M14: =N13 | N14: 106 | O14: =N14-M14 | X14: =Y13 | Y14: 28 | Z14: =Y14-X14
A15: =A14+1 | B15: =C14 | C15: 1411 | D15: =C15-B15 | M15: =N14 | N15: 108 | O15: =N15-M15 | X15: =Y14 | Y15: 28 | Z15: =Y15-X15
A16: =A15+1 | B16: =C15 | C16: 1416 | D16: =C16-B16 | M16: =N15 | N16: 113 | O16: =N16-M16 | X16: =Y15 | Y16: 29 | Z16: =Y16-X16
A17: =A16+1 | B17: =C16 | C17: 1432 | D17: =C17-B17 | I17: 157 | J17: 1418 | K17: =J17-J9 | L17: =(I17+I14+I12)/K17 | M17: =N16 | N17: 117 | O17: =N17-M17 | X17: =Y16 | Y17: 30 | Z17: =Y17-X17
A18: =A17+1 | B18: =C17 | C18: 1443 | D18: =C18-B18 | I18: 240 | J18: 1434 | K18: =J18-J17 | L18: =I18/K18 | M18: =N17 | N18: 122 | O18: =N18-M18 | X18: =Y17 | Y18: 33 | Z18: =Y18-X18
A19: =A18+1 | B19: =C18 | C19: 1448 | D19: =C19-B19 | I19: 155 | J19: N/F | M19: =N18 | N19: 124 | O19: =N19-M19 | X19: =Y18 | Y19: 33 | Z19: =Y19-X19
A20: =A19+1 | B20: =C19 | C20: 1460 | D20: =C20-B20 | M20: =N19 | N20: 128 | O20: =N20-M20 | T20: 300 | U20: 124 | V20: =U20-U10 | W20: =(T20+T12)/V20 | X20: =Y19 | Y20: 33 | Z20: =Y20-X20
A21: =A20+1 | B21: =C20 | C21: 1463 | D21: =C21-B21 | I21: 244 | J21: N/F | M21: =N20 | N21: 130 | O21: =N21-M21 | X21: =Y20 | Y21: 33 | Z21: =Y21-X21
A22: =A21+1 | B22: =C21 | C22: 1466 | D22: =C22-B22 | M22: =N21 | N22: 135 | O22: =N22-M22 | X22: =Y21 | Y22: 33 | Z22: =Y22-X22
A23: =A22+1 | B23: =C22 | C23: 1470 | D23: =C23-B23 | I23: 82 | J23: N/F | M23: =N22 | N23: 141 | O23: =N23-M23 | T23: 100 | U23: 136 | V23: =U23-U20 | W23: =T23/V23 | X23: =Y22 | Y23: 35 | Z23: =Y23-X23 | AE23: 100 | AF23: 34 | AG23: =AF23-AF2 | AH23: =AE23/AG23
A24: =A23+1 | B24: =C23 | C24: 1484 | D24: =C24-B24 | M24: =N23 | N24: 147 | O24: =N24-M24 | X24: =Y23 | Y24: 38 | Z24: =Y24-X24
A25: =A24+1 | B25: =C24 | C25: 1488 | D25: =C25-B25 | I25: 228 | J25: N/F | M25: =N24 | N25: 151 | O25: =N25-M25 | X25: =Y24 | Y25: 38 | Z25: =Y25-X25
A26: =A25+1 | B26: =C25 | C26: 1494 | D26: =C26-B26 | M26: =N25 | N26: 156 | O26: =N26-M26 | X26: =Y25 | Y26: 38 | Z26: =Y26-X26
A27: =A26+1 | B27: =C26 | C27: 1505 | D27: =C27-B27 | I27: 181 | J27: 1495 | K27: =J27-J18 | L27: =(I27+I25+I23+I21+I19)/K27 | M27: =N26 | N27: 164 | O27: =N27-M27 | T27: 400 | U27: 158 | V27: =U27-U23 | W27: =T27/V27 | X27: =Y26 | Y27: 41 | Z27: =Y27-X27 | AE27: 44 | AF27: 38 | AG27: =AF27-AF23 | AH27: =AE27/AG27
A28: =A27+1 | B28: =C27 | C28: 1508 | D28: =C28-B28 | M28: =N27 | N28: 164 | O28: =N28-M28 | X28: =Y27 | Y28: 41 | Z28: =Y28-X28
A29: =A28+1 | B29: =C28 | C29: 1516 | D29: =C29-B29 | M29: =N28 | N29: 171 | O29: =N29-M29 | X29: =Y28 | Y29: 41 | Z29: =Y29-X29 | AE29: 18 | AF29: 41 | AG29: =AF29-AF27 | AH29: =AE29/AG29
A30: =A29+1 | B30: =C29 | C30: 1521 | D30: =C30-B30 | M30: =N29 | N30: 176 | O30: =N30-M30 | X30: =Y29 | Y30: 42 | Z30: =Y30-X30
A31: =A30+1 | B31: =C30 | C31: 1525 | D31: =C31-B31 | I31: 345 | J31: 1522 | K31: =J31-J27 | L31: =I31/K31 | M31: =N30 | N31: 180 | O31: =N31-M31 | X31: =Y30 | Y31: 45 | Z31: =Y31-X31
A32: =A31+1 | B32: =C31 | C32: 1534 | D32: =C32-B32 | M32: =N31 | N32: 184 | O32: =N32-M32 | X32: =Y31 | Y32: 45 | Z32: =Y32-X32
D33: =SUM(D3:D32) | G33: =SUM(G3:G30) | I33: =SUM(I3:I32) | K33: =SUM(K3:K32) | L33: =I33/K33 | O33: =SUBTOTAL(9,O3:O32) | R33: =SUM(R3:R30) | T33: =SUM(T3:T30) | V33: =SUM(V3:V30) | W33: =T33/V33 | Z33: =SUM(Z3:Z30) | AC33: =SUM(AC3:AC30) | AE33: =SUM(AE3:AE30) | AG33: =SUM(AG3:AG30) | AH33: =AE33/AG33
T34: =T33+T2 | V34: =158-49 | W34: =T34/V34
X35: Monthly Hiring Charges | Y35: 900000
X36: 1 Day Hiring Charges/31 | Y36: =Y35/31
X37: 30 Days Hiring Charges | Y37: =Y36*30
X38: Bill Amount | Y38: =Y37

Sheet May-26
A1: 46143 | B1: KAMLAR-DHIRPUR | D1: Daily Running Hours | E1: Breakdown start time | F1: Breakdown end time | G1: Total Breakdown Hour | H1: Breakdown Reason | I1: DIESEL Consumed | J1: Diesel HMR | K1: Hours | L1: Average | M1: KAMLAR-1-Dalpatpur | O1: Daily Running Hours | P1: Breakdown start time | Q1: Breakdown end time | R1: Total Breakdown Hour | S1: Breakdown Reason | T1: DIESEL Filled | U1: Diesel HMR | V1: Hours | W1: Average | X1: KAMLAR-2-Dalpatpur | Z1: Daily Running Hours | AA1: Breakdown start time | AB1: Breakdown end time | AC1: Total Breakdown Hour | AD1: Breakdown Reason | AE1: DIESEL Filled | AF1: Diesel HMR | AG1: Hours | AH1: Average
A2: PREV Stock | B2: Start HMR | C2: End HMR | J2: 1522 | M2: Start HMR | N2: End HMR | U2: 158 | X2: Start HMR | Y2: End HMR | AF2: 41
A3: 46143 | B3: 1534 | C3: 1550 | D3: =C3-B3 | I3: 280 | J3: 1539 | K3: =J3-J2 | L3: =I3/K3 | M3: 184 | N3: 186 | O3: =N3-M3 | X3: 45 | Y3: 45 | Z3: =Y3-X3
A4: =A3+1 | B4: =C3 | C4: 1554 | D4: =C4-B4 | M4: =N3 | N4: 188 | O4: =N4-M4 | X4: =Y3 | Y4: 45 | Z4: =Y4-X4
A5: =A4+1 | B5: =C4 | C5: 1556 | D5: =C5-B5 | M5: =N4 | N5: 191 | O5: =N5-M5 | X5: =Y4 | Y5: 47 | Z5: =Y5-X5
A6: =A5+1 | B6: =C5 | C6: 1564 | D6: =C6-B6 | I6: 230 | J6: 1556 | K6: =J6-J3 | L6: =I6/K6 | M6: =N5 | N6: 195 | O6: =N6-M6 | X6: =Y5 | Y6: 49 | Z6: =Y6-X6
A7: =A6+1 | B7: =C6 | C7: 1567 | D7: =C7-B7 | M7: =N6 | N7: 198 | O7: =N7-M7 | T7: 300 | U7: 195 | V7: =U7-U2 | W7: =T7/V7 | X7: =Y6 | Y7: 49 | Z7: =Y7-X7
A8: =A7+1 | B8: =C7 | C8: 1570 | D8: =C8-B8 | M8: =N7 | N8: 202 | O8: =N8-M8 | X8: =Y7 | Y8: 49 | Z8: =Y8-X8
A9: =A8+1 | B9: =C8 | C9: 1576 | D9: =C9-B9 | I9: 192 | J9: 1572 | K9: =J9-J6 | L9: =I9/K9 | M9: =N8 | N9: 207 | O9: =N9-M9 | X9: =Y8 | Y9: 51 | Z9: =Y9-X9
A10: =A9+1 | B10: =C9 | C10: 1578 | D10: =C10-B10 | M10: =N9 | N10: 212 | O10: =N10-M10 | X10: =Y9 | Y10: 53 | Z10: =Y10-X10
A11: =A10+1 | B11: =C10 | C11: 1593 | D11: =C11-B11 | I11: 120 | J11: 1578 | K11: =J11-J9 | L11: =I11/K11 | M11: =N10 | N11: 214 | O11: =N11-M11 | X11: =Y10 | Y11: 53 | Z11: =Y11-X11
A12: =A11+1 | B12: =C11 | C12: 1594 | D12: =C12-B12 | M12: =N11 | N12: 215 | O12: =N12-M12 | X12: =Y11 | Y12: 53 | Z12: =Y12-X12
A13: =A12+1 | B13: =C12 | C13: 1598 | D13: =C13-B13 | I13: 245 | J13: 1595 | K13: =J13-J11 | L13: =I13/K13 | M13: =N12 | N13: 216 | O13: =N13-M13 | X13: =Y12 | Y13: 53 | Z13: =Y13-X13
A14: =A13+1 | B14: =C13 | C14: 1608 | D14: =C14-B14 | M14: =N13 | N14: 221 | O14: =N14-M14 | T14: 300 | U14: 217 | V14: =U14-U7 | W14: =T14/V14 | X14: =Y13 | Y14: 55 | Z14: =Y14-X14
A15: =A14+1 | B15: =C14 | C15: 1614 | D15: =C15-B15 | I15: 210 | J15: 1611 | K15: =J15-J13 | L15: =I15/K15 | M15: =N14 | N15: 227 | O15: =N15-M15 | X15: =Y14 | Y15: 58 | Z15: =Y15-X15
A16: =A15+1 | B16: =C15 | C16: 1619 | D16: =C16-B16 | M16: =N15 | N16: 229 | O16: =N16-M16 | X16: =Y15 | Y16: 58 | Z16: =Y16-X16
A17: =A16+1 | B17: =C16 | C17: 1630 | D17: =C17-B17 | M17: =N16 | N17: 232 | O17: =N17-M17 | X17: =Y16 | Y17: 58 | Z17: =Y17-X17
A18: =A17+1 | B18: =C17 | C18: 1636 | D18: =C18-B18 | I18: 375 | J18: 1630 | K18: =J18-J15 | L18: =I18/K18 | M18: =N17 | N18: 238 | O18: =N18-M18 | X18: =Y17 | Y18: 62 | Z18: =Y18-X18
A19: =A18+1 | B19: =C18 | C19: 1645 | D19: =C19-B19 | M19: =N18 | N19: 239 | O19: =N19-M19 | X19: =Y18 | Y19: 62 | Z19: =Y19-X19
A20: =A19+1 | B20: =C19 | C20: 1655 | D20: =C20-B20 | M20: =N19 | N20: 245 | O20: =N20-M20 | X20: =Y19 | Y20: 62 | Z20: =Y20-X20
A21: =A20+1 | B21: =C20 | C21: 1672 | D21: =C21-B21 | I21: 465 | J21: 1660 | K21: =J21-J18 | L21: =I21/K21 | M21: =N20 | N21: 252 | O21: =N21-M21 | T21: 300 | U21: 249 | V21: =U21-U14 | W21: =T21/V21 | X21: =Y20 | Y21: 62 | Z21: =Y21-X21 | AE21: 100 | AF21: 62
A22: =A21+1 | B22: =C21 | C22: 1680 | D22: =C22-B22 | M22: =N21 | N22: 261 | O22: =N22-M22 | X22: =Y21 | Y22: 66 | Z22: =Y22-X22
A23: =A22+1 | B23: =C22 | C23: 1685 | D23: =C23-B23 | I23: 283 | J23: 1681 | K23: =J23-J21 | L23: =I23/K23 | M23: =N22 | N23: 270 | O23: =N23-M23 | X23: =Y22 | Y23: 66 | Z23: =Y23-X23
A24: =A23+1 | B24: =C23 | C24: 1694 | D24: =C24-B24 | M24: =N23 | N24: 276 | O24: =N24-M24 | T24: 300 | U24: 271 | V24: =U24-U21 | W24: =T24/V24 | X24: =Y23 | Y24: 66 | Z24: =Y24-X24
A25: =A24+1 | B25: =C24 | C25: 1704 | D25: =C25-B25 | I25: 230 | J25: 1697 | K25: =J25-J23 | L25: =I25/K25 | M25: =N24 | N25: 284 | O25: =N25-M25 | X25: =Y24 | Y25: 69 | Z25: =Y25-X25
A26: =A25+1 | B26: =C25 | C26: 1708 | D26: =C26-B26 | M26: =N25 | N26: 286 | O26: =N26-M26 | X26: =Y25 | Y26: 71 | Z26: =Y26-X26
A27: =A26+1 | B27: =C26 | C27: 1717 | D27: =C27-B27 | M27: =N26 | N27: 290 | O27: =N27-M27 | X27: =Y26 | Y27: 71 | Z27: =Y27-X27
A28: =A27+1 | B28: =C27 | C28: 1733 | D28: =C28-B28 | M28: =N27 | N28: 296 | O28: =N28-M28 | T28: 200 | U28: 290 | V28: =U28-U24 | W28: =T28/V28 | X28: =Y27 | Y28: 73 | Z28: =Y28-X28
A29: =A28+1 | B29: =C28 | C29: 1750 | D29: =C29-B29 | I29: 213 | J29: 1741 | K29: =J29-J25 | L29: =I29/K29 | M29: =N28 | N29: 304 | O29: =N29-M29 | X29: =Y28 | Y29: 76 | Z29: =Y29-X29
A30: =A29+1 | B30: =C29 | C30: 1756 | D30: =C30-B30 | M30: =N29 | N30: 306 | O30: =N30-M30 | X30: =Y29 | Y30: 76 | Z30: =Y30-X30
A31: =A30+1 | B31: =C30 | C31: 1764 | D31: =C31-B31 | M31: =N30 | N31: 311 | O31: =N31-M31 | X31: =Y30 | Y31: 76 | Z31: =Y31-X31
A32: =A31+1 | B32: =C31 | C32: 1774 | D32: =C32-B32 | I32: 341 | J32: 1765 | K32: =J32-J29 | L32: =I32/K32 | M32: =N31 | N32: 317 | O32: =N32-M32 | T32: 200 | U32: 312 | V32: =U32-U28 | W32: =T32/V32 | X32: =Y31 | Y32: 80 | Z32: =Y32-X32 | AE32: 100 | AF32: 76 | AG32: =AF32-AF2
A33: =A32+1 | B33: =C32 | C33: 1790 | D33: =C33-B33 | M33: =N32 | N33: 317 | O33: =N33-M33 | X33: =Y32 | Y33: 80 | Z33: =Y33-X33
D34: =SUM(D3:D33) | G34: =SUBTOTAL(9,G3:G33) | I34: =SUM(I3:I33) | K34: =SUM(K3:K33) | L34: =I34/K34 | O34: =SUM(O3:O33) | R34: =SUBTOTAL(9,R3:R33) | T34: =SUM(T3:T33) | V34: =SUM(V3:V33) | W34: =T34/V34 | Z34: =SUM(Z3:Z33) | AC34: =SUBTOTAL(9,AC3:AC33) | AE34: =SUM(AE3:AE33) | AG34: =SUM(AG3:AG33) | AH34: =AE34/AG34
X36: Monthly Hiring Charges | Y36: 900000 | AC36: 162
X37: 1 Day Hiring Charges/31 | Y37: =Y36/31 | AC37: 155
X38: 30 Days Hiring Charges | Y38: =Y37*30 | AC38: =AC36-AC37
X39: Bill Amount | Y39: =Y38

Sheet JUNE-26
A1: 46174 | B1: KAMLAR-DHIRPUR | D1: Daily Running Hours | E1: Breakdown start time | F1: Breakdown end time | G1: Total Breakdown Hour | H1: Breakdown Reason | I1: DIESEL Consumed | J1: Diesel HMR | K1: Hours | L1: Average | M1: KAMLAR-1-Dalpatpur | O1: Daily Running Hours | P1: Breakdown start time | Q1: Breakdown end time | R1: Total Breakdown Hour | S1: Breakdown Reason | T1: DIESEL Filled | U1: Diesel HMR | V1: Hours | W1: Average | X1: KAMLAR-2-Dalpatpur | Z1: Daily Running Hours | AA1: Breakdown start time | AB1: Breakdown end time | AC1: Total Breakdown Hour | AD1: Breakdown Reason | AE1: DIESEL Filled | AF1: Diesel HMR | AG1: Hours | AH1: Average
A2: PREV Stock | B2: Start HMR | C2: End HMR | J2: 1765 | M2: Start HMR | N2: End HMR | U2: 312 | X2: Start HMR | Y2: End HMR | AF2: 76
A3: 46174 | B3: 1790 | C3: 1796 | D3: =C3-B3 | I3: 430 | J3: 1792 | K3: =J3-J2 | L3: =I3/K3 | M3: 317 | N3: 323 | O3: =N3-M3 | X3: 80 | Y3: 80 | Z3: =Y3-X3
A4: =A3+1 | B4: =C3 | C4: 1804 | D4: =C4-B4 | M4: =N3 | N4: 328 | O4: =N4-M4 | X4: =Y3 | Y4: 81 | Z4: =Y4-X4
A5: =A4+1 | B5: =C4 | C5: 1811 | D5: =C5-B5 | M5: =N4 | N5: 334 | O5: =N5-M5 | T5: 450 | U5: 330 | V5: =U5-U2 | W5: =T5/V5 | X5: =Y4 | Y5: 83 | Z5: =Y5-X5 | AE5: 350 | AF5: N/F | AH5: =AE5/AG5
A6: =A5+1 | B6: =C5 | C6: 1815 | D6: =C6-B6 | M6: =N5 | N6: 338 | O6: =N6-M6 | X6: =Y5 | Y6: 83 | Z6: =Y6-X6
A7: =A6+1 | B7: =C6 | C7: 1819 | D7: =C7-B7 | I7: 315 | J7: 1815 | K7: =J7-J3 | L7: =I7/K7 | M7: =N6 | N7: 344 | O7: =N7-M7 | X7: =Y6 | Y7: 83 | Z7: =Y7-X7
A8: =A7+1 | B8: =C7 | C8: 1831 | D8: =C8-B8 | M8: =N7 | N8: 347 | O8: =N8-M8 | X8: =Y7 | Y8: 83 | Z8: =Y8-X8
A9: =A8+1 | B9: =C8 | C9: 1834 | D9: =C9-B9 | M9: =N8 | N9: 349 | O9: =N9-M9 | X9: =Y8 | Y9: 83 | Z9: =Y9-X9
A10: =A9+1 | B10: =C9 | C10: 1838 | D10: =C10-B10 | I10: 290 | J10: 1834 | K10: =J10-J7 | L10: =I10/K10 | M10: =N9 | N10: 360 | O10: =N10-M10 | X10: =Y9 | Y10: 88 | Z10: =Y10-X10
A11: =A10+1 | B11: =C10 | C11: 1842 | D11: =C11-B11 | M11: =N10 | N11: 368 | O11: =N11-M11 | X11: =Y10 | Y11: 89 | Z11: =Y11-X11
A12: =A11+1 | B12: =C11 | C12: 1847 | D12: =C12-B12 | M12: =N11 | N12: 373 | O12: =N12-M12 | T12: 450 | U12: 368 | V12: =U12-U2 | W12: =T12/V12 | X12: =Y11 | Y12: 90 | Z12: =Y12-X12
A13: =A12+1 | B13: =C12 | C13: 1864 | D13: =C13-B13 | I13: 210 | J13: 1848 | K13: =J13-J10 | L13: =I13/K13 | M13: =N12 | N13: 381 | O13: =N13-M13 | X13: =Y12 | Y13: 90 | Z13: =Y13-X13
A14: =A13+1 | B14: =C13 | C14: 1868 | D14: =C14-B14 | I14: 280 | J14: 1865 | K14: =J14-J13 | L14: =I14/K14 | M14: =N13 | N14: 389 | O14: =N14-M14 | X14: =Y13 | Y14: 93 | Z14: =Y14-X14
A15: =A14+1 | B15: =C14 | C15: 1871 | D15: =C15-B15 | M15: =N14 | N15: 393 | O15: =N15-M15 | X15: =Y14 | Y15: 93 | Z15: =Y15-X15
A16: =A15+1 | B16: =C15 | C16: 1873 | D16: =C16-B16 | M16: =N15 | N16: 393 | O16: =N16-M16 | X16: =Y15 | Y16: 93 | Z16: =Y16-X16
A17: =A16+1 | B17: =C16 | C17: 1887 | D17: =C17-B17 | M17: =N16 | N17: 401 | O17: =N17-M17 | X17: =Y16 | Y17: 93 | Z17: =Y17-X17
A18: =A17+1 | B18: =C17 | C18: 1892 | D18: =C18-B18 | I18: 301 | J18: 1888 | K18: =J18-J14 | L18: =I18/K18 | M18: =N17 | N18: 405 | O18: =N18-M18 | X18: =Y17 | Y18: 93 | Z18: =Y18-X18
A19: =A18+1 | B19: =C18 | C19: 1899 | D19: =C19-B19 | M19: =N18 | N19: 411 | O19: =N19-M19 | T19: 200 | U19: 405 | V19: N/F | X19: =Y18 | Y19: 95 | Z19: =Y19-X19
A20: =A19+1 | B20: =C19 | C20: 1906 | D20: =C20-B20 | M20: =N19 | N20: 419 | O20: =N20-M20 | T20: 380 | U20: 412 | V20: =U20-U12 | W20: =(T20+T19)/V20 | X20: =Y19 | Y20: 100 | Z20: =Y20-X20 | AE20: 170 | AF20: N/F | AH20: =AE20/AG20
A21: =A20+1 | B21: =C20 | C21: 1911 | D21: =C21-B21 | I21: 311 | J21: 1907 | K21: =J21-J18 | L21: =I21/K21 | M21: =N20 | N21: 424 | O21: =N21-M21 | X21: =Y20 | Y21: 100 | Z21: =Y21-X21
A22: =A21+1 | B22: =C21 | C22: 1926 | D22: =C22-B22 | I22: 72.46 | J22: N/F | M22: =N21 | N22: 434 | O22: =N22-M22 | X22: =Y21 | Y22: 104 | Z22: =Y22-X22
A23: =A22+1 | B23: =C22 | C23: 1943 | D23: =C23-B23 | M23: =N22 | N23: 436 | O23: =N23-M23 | X23: =Y22 | Y23: 105 | Z23: =Y23-X23
A24: =A23+1 | B24: =C23 | C24: 1955 | D24: =C24-B24 | I24: 372 | J24: 1945 | K24: =J24-J21 | L24: =(I24+I22)/K24 | M24: =N23 | N24: 441 | O24: =N24-M24 | X24: =Y23 | Y24: 107 | Z24: =Y24-X24
A25: =A24+1 | B25: =C24 | C25: 1966 | D25: =C25-B25 | M25: =N24 | N25: 452 | O25: =N25-M25 | X25: =Y24 | Y25: 111 | Z25: =Y25-X25
A26: =A25+1 | B26: =C25 | C26: 1977 | D26: =C26-B26 | I26: 241 | J26: 1966 | K26: =J26-J24 | L26: =I26/K26 | M26: =N25 | N26: 456 | O26: =N26-M26 | T26: =440+30 | U26: 454 | V26: =U26-U20 | W26: =T26/V26 | X26: =Y25 | Y26: 111 | Z26: =Y26-X26 | AE26: 215 | AF26: 111 | AG26: =AF26-AF2 | AH26: =(AE26+AE20+AE5)/AG26
A27: =A26+1 | B27: =C26 | C27: 1987 | D27: =C27-B27 | E27: 0.40972222 | F27: 0.78472222 | G27: =F27-E27 | H27: Tyre puncher | I27: 145 | J27: 1978 | K27: =J27-J24 | L27: =I27/K27 | M27: =N26 | N27: 462 | O27: =N27-M27 | X27: =Y26 | Y27: 116 | Z27: =Y27-X27
A28: =A27+1 | B28: =C27 | C28: 1992 | D28: =C28-B28 | M28: =N27 | N28: 463 | O28: =N28-M28 | X28: =Y27 | Y28: 116 | Z28: =Y28-X28
A29: =A28+1 | B29: =C28 | C29: 1998 | D29: =C29-B29 | I29: 133.69 | J29: 1993 | K29: =J29-J27 | L29: =I29/K29 | M29: =N28 | N29: 468 | O29: =N29-M29 | X29: =Y28 | Y29: 116 | Z29: =Y29-X29
A30: =A29+1 | B30: =C29 | C30: 2001 | D30: =C30-B30 | M30: =N29 | N30: 469 | O30: =N30-M30 | X30: =Y29 | Y30: 116 | Z30: =Y30-X30
A31: =A30+1 | B31: =C30 | C31: 2014 | D31: =C31-B31 | I31: 180 | J31: 2001 | K31: =J31-J29 | L31: =I31/K31 | M31: =N30 | N31: 479 | O31: =N31-M31 | X31: =Y30 | Y31: 121 | Z31: =Y31-X31
A32: =A31+1 | B32: =C31 | C32: 2025 | D32: =C32-B32 | M32: =N31 | N32: 485 | O32: =N32-M32 | T32: 45 | U32: 480 | X32: =Y31 | Y32: 123 | Z32: =Y32-X32
D33: =SUM(D3:D32) | G33: =SUBTOTAL(9,G3:G32) | I33: =SUM(I3:I32) | K33: =SUM(K3:K32) | L33: =I33/K33 | O33: =SUM(O3:O32) | R33: =SUBTOTAL(9,R3:R32) | S33: NO B/D. | T33: =SUM(T3:T32) | V33: =SUM(V3:V32) | W33: =T33/V33 | Z33: =SUM(Z3:Z32) | AC33: =SUBTOTAL(9,AC3:AC32) | AD33: NO B/D. | AE33: =SUM(AE3:AE32) | AG33: =SUM(AG3:AG32) | AH33: =AE33/AG33
AE34: =AE33/Z33 | AG34: =AF32-AF21 | AH34: =AE33/AG34

Sheet July-26
A1: 46204 | B1: KAMLAR-DHIRPUR | D1: Daily Running Hours | E1: Breakdown start time | F1: Breakdown end time | G1: Total Breakdown Hour | H1: Breakdown Reason | I1: DIESEL Consumed | J1: Diesel HMR | K1: Hours | L1: Average | M1: KAMLAR-1-Dalpatpur | O1: Daily Running Hours | P1: Breakdown start time | Q1: Breakdown end time | R1: Total Breakdown Hour | S1: Breakdown Reason | T1: DIESEL Filled | U1: Diesel HMR | V1: Hours | W1: Average | X1: KAMLAR-2-Dalpatpur | Z1: Daily Running Hours | AA1: Breakdown start time | AB1: Breakdown end time | AC1: Total Breakdown Hour | AD1: Breakdown Reason | AE1: DIESEL Filled | AF1: Diesel HMR | AG1: Hours | AH1: Average
A2: PREV Stock | B2: Start HMR | C2: End HMR | J2: 2001 | M2: Start HMR | N2: End HMR | T2: 45 | U2: 454 | X2: Start HMR | Y2: End HMR | AF2: 111
A3: 46204 | B3: 2025 | C3: 2029 | D3: =C3-B3 | I3: 301 | J3: 2026 | K3: =J3-J2 | L3: =I3/K3 | M3: 485 | N3: 490 | O3: =N3-M3 | T3: 350 | U3: 486 | V3: =U3-U2 | W3: =T3/V3 | X3: 123 | Y3: 124 | Z3: =Y3-X3 | AE3: 100 | AF3: 123 | AG3: =AF3-AF2 | AH3: =AE3/AG3
A4: =A3+1 | B4: =C3 | C4: 2035 | D4: =C4-B4 | M4: =N3 | N4: 498 | O4: =N4-M4 | X4: =Y3 | Y4: 125 | Z4: =Y4-X4
A5: =A4+1 | B5: =C4 | C5: 2050 | D5: =C5-B5 | I5: 172 | J5: 2039 | K5: =J5-J3 | L5: =I5/K5 | M5: =N4 | N5: 504 | O5: =N5-M5 | X5: =Y4 | Y5: 125 | Z5: =Y5-X5
A6: =A5+1 | B6: =C5 | C6: 2056 | D6: =C6-B6 | M6: =N5 | N6: 511 | O6: =N6-M6 | X6: =Y5 | Y6: 125 | Z6: =Y6-X6
A7: =A6+1 | B7: =C6 | C7: 2059 | D7: =C7-B7 | I7: 233 | J7: 2056 | K7: =J7-J5 | L7: =I7/K7 | M7: =N6 | N7: 512 | O7: =N7-M7 | X7: =Y6 | Y7: 125 | Z7: =Y7-X7
A8: =A7+1 | B8: =C7 | C8: 2070 | D8: =C8-B8 | M8: =N7 | N8: 517 | O8: =N8-M8 | X8: =Y7 | Y8: 125 | Z8: =Y8-X8
A9: =A8+1 | B9: =C8 | C9: 2077 | D9: =C9-B9 | I9: 190 | J9: 2070 | K9: =J9-J7 | L9: =I9/K9 | M9: =N8 | N9: 520 | O9: =N9-M9 | T9: 490 | U9: 519 | V9: =U9-U3 | W9: =T9/V9 | X9: =Y8 | Y9: 126 | Z9: =Y9-X9
A10: =A9+1 | B10: =C9 | C10: 2089 | D10: =C10-B10 | I10: 160 | J10: 2081 | K10: =J10-J9 | L10: =I10/K10 | M10: =N9 | N10: 528 | O10: =N10-M10 | X10: =Y9 | Y10: 129 | Z10: =Y10-X10
A11: =A10+1 | B11: =C10 | C11: 2099 | D11: =C11-B11 | M11: =N10 | N11: 533 | O11: =N11-M11 | X11: =Y10 | Y11: 130 | Z11: =Y11-X11
A12: =A11+1 | B12: =C11 | C12: 2107 | D12: =C12-B12 | I12: 246 | J12: 2101 | K12: =J12-J10 | L12: =I12/K12 | M12: =N11 | N12: 539 | O12: =N12-M12 | X12: =Y11 | Y12: 130 | Z12: =Y12-X12
A13: =A12+1 | B13: =C12 | C13: 2118 | D13: =C13-B13 | M13: =N12 | N13: 543 | O13: =N13-M13 | X13: =Y12 | Y13: 130 | Z13: =Y13-X13
A14: =A13+1 | B14: =C13 | C14: 2125 | D14: =C14-B14 | I14: 288 | M14: =N13 | N14: 543 | O14: =N14-M14 | X14: =Y13 | Y14: 130 | Z14: =Y14-X14
A15: =A14+1 | B15: =C14 | C15: 2129 | D15: =C15-B15 | M15: =N14 | N15: 551 | O15: =N15-M15 | X15: =Y14 | Y15: 130 | Z15: =Y15-X15
A16: =A15+1 | B16: =C15 | C16: 2135 | D16: =C16-B16 | I16: 140 | J16: 2130 | K16: =J16-J12 | L16: =(I16+I14)/K16 | M16: =N15 | N16: 560 | O16: =N16-M16 | T16: 400 | U16: 553 | V16: =U16-U2 | W16: =T16/V16 | X16: =Y15 | Y16: 134 | Z16: =Y16-X16
A17: =A16+1 | B17: =C16 | C17: 2150 | D17: =C17-B17 | I17: 75 | M17: =N16 | N17: 567 | O17: =N17-M17 | X17: =Y16 | Y17: 135 | Z17: =Y17-X17
A18: =A17+1 | B18: =C17 | C18: 2155 | D18: =C18-B18 | M18: =N17 | N18: 575 | O18: =N18-M18 | X18: =Y17 | Y18: 135 | Z18: =Y18-X18
A19: =A18+1 | B19: =C18 | C19: 2159 | D19: =C19-B19 | I19: 235 | M19: =N18 | N19: 580 | O19: =N19-M19 | X19: =Y18 | Y19: 135 | Z19: =Y19-X19
A20: =A19+1 | B20: =C19 | C20: 2175 | D20: =C20-B20 | M20: =N19 | N20: 588 | O20: =N20-M20 | T20: 200 | U20: 583 | V20: =U20-U16 | W20: =T20/V20 | X20: =Y19 | Y20: 144 | Z20: =Y20-X20
A21: =A20+1 | B21: =C20 | C21: 2186 | D21: =C21-B21 | I21: 233 | J21: 2178 | K21: =J21-J16 | L21: =(I21+I19+I17)/K21 | M21: =N20 | N21: 594 | O21: =N21-M21 | X21: =Y20 | Y21: 147 | Z21: =Y21-X21
A22: =A21+1 | B22: =C21 | C22: 2192 | D22: =C22-B22 | M22: =N21 | N22: 607 | O22: =N22-M22 | T22: 350 | U22: 598 | V22: =U22-U20 | W22: =T22/V22 | X22: =Y21 | Y22: 148 | Z22: =Y22-X22 | AE22: 150 | AF22: 148 | AG22: =AF22-AF3 | AH22: =AE22/AG22
A23: =A22+1 | B23: =C22 | C23: 2200 | D23: =C23-B23 | I23: 200 | J23: 2192 | K23: =J23-J21 | L23: =I23/K23 | M23: =N22 | N23: 617 | O23: =N23-M23 | X23: =Y22 | Y23: 150 | Z23: =Y23-X23
A24: =A23+1 | B24: =C23 | C24: 2218 | D24: =C24-B24 | M24: =N23 | N24: 626 | O24: =N24-M24 | X24: =Y23 | Y24: 153 | Z24: =Y24-X24
A25: =A24+1 | B25: =C24 | C25: 2233 | D25: =C25-B25 | I25: 380 | J25: 2221 | K25: =J25-J23 | L25: =I25/K25 | M25: =N24 | N25: 632 | O25: =N25-M25 | T25: 200 | U25: N/F | X25: =Y24 | Y25: 153 | Z25: =Y25-X25
A26: =A25+1 | B26: =C25 | C26: 2243 | D26: =C26-B26 | I26: 210 | J26: 2238 | K26: =J26-J25 | L26: =I26/K26 | M26: =N25 | N26: 641 | O26: =N26-M26 | T26: 250 | U26: 636 | V26: =U26-U22 | W26: =(T26+T25)/V26 | X26: =Y25 | Y26: 154 | Z26: =Y26-X26 | AE26: 250 | AF26: 154 | AG26: N/F
A27: =A26+1 | B27: =C26 | C27: 2256 | D27: =C27-B27 | M27: =N26 | N27: 651 | O27: =N27-M27 | X27: =Y26 | Y27: 157 | Z27: =Y27-X27
A28: =A27+1 | B28: =C27 | C28: 2261 | D28: =C28-B28 | M28: =N27 | N28: 653 | O28: =N28-M28 | X28: =Y27 | Y28: 157 | Z28: =Y28-X28
A29: =A28+1 | B29: =C28 | C29: 2265 | D29: =C29-B29 | I29: 275 | M29: =N28 | N29: 660 | O29: =N29-M29 | X29: =Y28 | Y29: 157 | Z29: =Y29-X29
A30: =A29+1 | B30: =C29 | C30: 2267 | D30: =C30-B30 | M30: =N29 | N30: 669 | O30: =N30-M30 | T30: 300 | U30: 665 | V30: =U30-U26 | W30: =T30/V30 | X30: =Y29 | Y30: 157 | Z30: =Y30-X30
A31: =A30+1 | B31: =C30 | C31: 2279 | D31: =C31-B31 | M31: =N30 | N31: 677 | O31: =N31-M31 | T31: 250 | U31: N/F | X31: =Y30 | Y31: 159 | Z31: =Y31-X31 | AE31: 89 | AF31: 157 | AG31: =AF31-AF22 | AH31: =(AE31+AE26)/AG31
A32: =A31+1 | B32: =C31 | C32: 2286 | D32: =C32-B32 | I32: 264 | J32: 2280 | K32: =J32-J26 | L32: =(I32+I29)/K32 | M32: =N31 | N32: 687 | O32: =N32-M32 | X32: =Y31 | Y32: 163 | Z32: =Y32-X32
A33: =A32+1 | B33: =C32 | C33: 2300 | D33: =C33-B33 | M33: =N32 | N33: 693 | O33: =N33-M33 | X33: =Y32 | Y33: 165 | Z33: =Y33-X33
D34: =SUM(D3:D33) | G34: =SUM(G3:G33) | I34: =SUM(I3:I33) | K34: =SUM(K3:K33) | L34: =I34/K34 | O34: =SUM(O3:O33) | R34: =SUM(R3:R33) | T34: =SUM(T2:T30) | V34: =SUM(V3:V33) | W34: =T34/V34 | Z34: =SUM(Z3:Z33) | AC34: =SUM(AC3:AC33) | AE34: =SUM(AE3:AE33) | AG34: =SUM(AG3:AG33) | AH34: =AE34/AG34

Sheet Aug-26
A1: 46235 | B1: KAMLAR-DHIRPUR | D1: Daily Running Hours | E1: Breakdown start time | F1: Breakdown end time | G1: Total Breakdown Hour | H1: Breakdown Reason | I1: DIESEL Consumed | J1: Diesel HMR | K1: Hours | L1: Average | M1: KAMLAR-1-Dalpatpur | O1: Daily Running Hours | P1: Breakdown start time | Q1: Breakdown end time | R1: Total Breakdown Hour | S1: Breakdown Reason | T1: DIESEL Filled | U1: Diesel HMR | V1: Hours | W1: Average | X1: KAMLAR-2-Dalpatpur | Z1: Daily Running Hours | AA1: Breakdown start time | AB1: Breakdown end time | AC1: Total Breakdown Hour | AD1: Breakdown Reason | AE1: DIESEL Filled | AF1: Diesel HMR | AG1: Hours | AH1: Average
A2: PREV Stock | B2: Start HMR | C2: End HMR | J2: 2280 | M2: Start HMR | N2: End HMR | T2: 250 | U2: 665 | X2: Start HMR | Y2: End HMR | AF2: 157
A3: 46235 | B3: 2300 | C3: 2309 | D3: =C3-B3 | I3: 328 | J3: 2305 | K3: =J3-J2 | L3: =I3/K3 | M3: 693 | N3: 699 | O3: =N3-M3 | X3: 165 | Y3: 169 | Z3: =Y3-X3
A4: =A3+1 | B4: =C3 | C4: 2309 | D4: =C4-B4 | M4: =N3 | N4: 700 | O4: =N4-M4 | X4: =Y3 | Y4: 171 | Z4: =Y4-X4
A5: =A4+1 | B5: =C4 | C5: 2312 | D5: =C5-B5 | M5: =N4 | N5: 704 | O5: =N5-M5 | T5: 370 | U5: 701 | V5: =U5-U2 | W5: =(T5+T2)/V5 | X5: =Y4 | Y5: 171 | Z5: =Y5-X5 | AE5: 150 | AF5: 171 | AG5: =AF5-AF2 | AH5: =AE5/AG5
A6: =A5+1 | B6: =C5 | C6: 2314 | D6: =C6-B6 | M6: =N5 | N6: 708 | O6: =N6-M6 | X6: =Y5 | Y6: 171 | Z6: =Y6-X6
A7: =A6+1 | B7: =C6 | C7: 2320 | D7: =C7-B7 | I7: 192 | J7: 2319 | K7: =J7-J3 | L7: =I7/K7 | M7: =N6 | N7: 716 | O7: =N7-M7 | X7: =Y6 | Y7: 174 | Z7: =Y7-X7
A8: =A7+1 | B8: =C7 | C8: 2327 | D8: =C8-B8 | M8: =N7 | N8: 723 | O8: =N8-M8 | X8: =Y7 | Y8: 176 | Z8: =Y8-X8
A9: =A8+1 | B9: =C8 | C9: 2336 | D9: =C9-B9 | I9: 178 | J9: 2332 | K9: =J9-J7 | L9: =I9/K9 | M9: =N8 | N9: 726 | O9: =N9-M9 | X9: =Y8 | Y9: 177 | Z9: =Y9-X9
A10: =A9+1 | B10: =C9 | C10: 2340 | D10: =C10-B10 | M10: =N9 | N10: 726 | O10: =N10-M10 | X10: =Y9 | Y10: 178 | Z10: =Y10-X10
A11: =A10+1 | B11: =C10 | C11: 2343 | D11: =C11-B11 | M11: =N10 | N11: 726 | O11: =N11-M11 | X11: =Y10 | Y11: 178 | Z11: =Y11-X11
A12: =A11+1 | B12: =C11 | C12: 2355 | D12: =C12-B12 | M12: =N11 | N12: 727 | O12: =N12-M12 | T12: 340 | U12: 726 | V12: =U12-U5 | W12: =T12/V12 | X12: =Y11 | Y12: 178 | Z12: =Y12-X12 | AE12: 40 | AF12: N/F
A13: =A12+1 | B13: =C12 | C13: 2363 | D13: =C13-B13 | I13: 320 | J13: 2355 | K13: =J13-J9 | L13: =I13/K13 | M13: =N12 | N13: 730 | O13: =N13-M13 | X13: =Y12 | Y13: 178 | Z13: =Y13-X13
A14: =A13+1 | B14: =C13 | C14: 2374 | D14: =C14-B14 | M14: =N13 | N14: 737 | O14: =N14-M14 | X14: =Y13 | Y14: 179 | Z14: =Y14-X14
A15: =A14+1 | B15: =C14 | C15: 2382 | D15: =C15-B15 | M15: =N14 | N15: 746 | O15: =N15-M15 | X15: =Y14 | Y15: 179 | Z15: =Y15-X15
A16: =A15+1 | B16: =C15 | C16: 2385 | D16: =C16-B16 | I16: 350 | J16: 2382 | K16: =J16-J13 | L16: =I16/K16 | M16: =N15 | N16: 752 | O16: =N16-M16 | X16: =Y15 | Y16: 183 | Z16: =Y16-X16
A17: =A16+1 | B17: =C16 | C17: 2387 | D17: =C17-B17 | M17: =N16 | N17: 752 | O17: =N17-M17 | X17: =Y16 | Y17: 183 | Z17: =Y17-X17
A18: =A17+1 | B18: =C17 | C18: 2399 | D18: =C18-B18 | M18: =N17 | N18: 752 | O18: =N18-M18 | X18: =Y17 | Y18: 183 | Z18: =Y18-X18
A19: =A18+1 | B19: =C18 | C19: 2402 | D19: =C19-B19 | M19: =N18 | N19: 756 | O19: =N19-M19 | T19: 350 | U19: 754 | V19: =U19-U12 | W19: =T19/V19 | X19: =Y18 | Y19: 183 | Z19: =Y19-X19
A20: =A19+1 | B20: =C19 | C20: 2405 | D20: =C20-B20 | I20: 268 | J20: 2402 | K20: =J20-J16 | L20: =I20/K20 | M20: =N19 | N20: 767 | O20: =N20-M20 | X20: =Y19 | Y20: 185 | Z20: =Y20-X20
A21: =A20+1 | B21: =C20 | C21: 2415 | D21: =C21-B21 | M21: =N20 | N21: 779 | O21: =N21-M21 | X21: =Y20 | Y21: 188 | Z21: =Y21-X21
A22: =A21+1 | B22: =C21 | C22: 2418 | D22: =C22-B22 | M22: =N21 | N22: 783 | O22: =N22-M22 | T22: 350 | U22: 782 | V22: =U22-U19 | W22: =T22/V22 | X22: =Y21 | Y22: 188 | Z22: =Y22-X22 | AE22: 100 | AF22: 188 | AG22: =AF22-AF5 | AH22: =AE22/AG22
A23: =A22+1 | B23: =C22 | C23: 2420 | D23: =C23-B23 | I23: 245 | J23: 2419 | K23: =J23-J20 | L23: =I23/K23 | M23: =N22 | N23: 785 | O23: =N23-M23 | X23: =Y22 | Y23: 188 | Z23: =Y23-X23
A24: =A23+1 | B24: =C23 | C24: 2425 | D24: =C24-B24 | M24: =N23 | N24: 787 | O24: =N24-M24 | X24: =Y23 | Y24: 190 | Z24: =Y24-X24
A25: =A24+1 | B25: =C24 | C25: 2434 | D25: =C25-B25 | M25: =N24 | N25: 787 | O25: =N25-M25 | X25: =Y24 | Y25: 190 | Z25: =Y25-X25
A26: =A25+1 | B26: =C25 | C26: 2442 | D26: =C26-B26 | I26: 240 | J26: 2439 | K26: =J26-J23 | L26: =I26/K26 | M26: =N25 | N26: 791 | O26: =N26-M26 | X26: =Y25 | Y26: 191 | Z26: =Y26-X26
A27: =A26+1 | B27: =C26 | C27: 2444 | D27: =C27-B27 | M27: =N26 | N27: 798 | O27: =N27-M27 | X27: =Y26 | Y27: 191 | Z27: =Y27-X27
A28: =A27+1 | B28: =C27 | C28: 2458 | D28: =C28-B28 | M28: =N27 | N28: 802 | O28: =N28-M28 | X28: =Y27 | Y28: 191 | Z28: =Y28-X28
A29: =A28+1 | B29: =C28 | C29: 2462 | D29: =C29-B29 | I29: 260 | J29: 2459 | K29: =J29-J26 | L29: =I29/K29 | M29: =N28 | N29: 808 | O29: =N29-M29 | X29: =Y28 | Y29: 191 | Z29: =Y29-X29
A30: =A29+1 | B30: =C29 | C30: 2465 | D30: =C30-B30 | M30: =N29 | N30: 819 | O30: =N30-M30 | X30: =Y29 | Y30: 198 | Z30: =Y30-X30
A31: =A30+1 | B31: =C30 | C31: 2472 | D31: =C31-B31 | M31: =N30 | N31: 826 | O31: =N31-M31 | X31: =Y30 | Y31: 199 | Z31: =Y31-X31
A32: =A31+1 | B32: =C31 | C32: 2473 | D32: =C32-B32 | M32: =N31 | N32: 833 | O32: =N32-M32 | X32: =Y31 | Y32: 202 | Z32: =Y32-X32
A33: =A32+1 | B33: =C32 | C33: 2481 | D33: =C33-B33 | M33: =N32 | N33: 840 | O33: =N33-M33 | X33: =Y32 | Y33: 204 | Z33: =Y33-X33
D34: =SUM(D3:D33) | G34: =SUM(G3:G33) | H34: No B/D | I34: =SUM(I3:I33) | K34: =SUM(K3:K33) | L34: =I34/K34 | O34: =SUM(O3:O33) | R34: =SUM(R3:R33) | S34: No B/D | T34: =SUM(T2:T33) | V34: =SUM(V3:V33) | W34: =T34/V34 | Z34: =SUM(Z3:Z33) | AC34: =SUM(AC3:AC33) | AD34: No B/D | AE34: =SUM(AE3:AE33) | AG34: =SUM(AG3:AG33) | AH34: =AE34/AG34

Sheet Sep-26
A1: Date | B1: Starting HMR | C1: Closing HMR | D1: Daily Running Hours | E1: Breakdown start time | F1: Breakdown end time | G1: Total Breakdown Hour | H1: Breakdown Reason | I1: Diesel Issued (Ltr) | J1: HMR at Diesel Fill | K1: Hours | L1: Average | M1: Date | N1: Starting HMR | O1: Closing HMR | P1: Daily Running Hours | Q1: Breakdown start time | R1: Breakdown end time | S1: Total Breakdown Hour | T1: Breakdown Reason | U1: Diesel Issued (Ltr) | V1: HMR at Diesel Fill | W1: Hours | X1: Average | Y1: Date | Z1: Starting HMR | AA1: Closing HMR | AB1: Daily Running Hours | AC1: Breakdown start time | AD1: Breakdown end time | AE1: Total Breakdown Hour | AF1: Breakdown Reason | AG1: Diesel Issued (Ltr) | AH1: HMR at Diesel Fill | AI1: Hours | AJ1: Average
A2: PREV Stock | B2: KAMLAR-DHIRPUR | J2: 2459 | M2: PREV Stock | N2: KAMLAR-1-Dalpatpur | V2: 782 | Y2: PREV Stock | Z2: KAMLAR-2-Dalpatpur | AH2: 188
A3: 46266 | B3: 2481 | C3: 2481 | D3: =IF(OR(B3="",C3=""),"",C3-B3) | M3: 46266 | N3: 840 | O3: 854 | P3: =IF(OR(N3="",O3=""),"",O3-N3) | Y3: 46266 | Z3: 204 | AA3: 207 | AB3: =IF(OR(Z3="",AA3=""),"",AA3-Z3)
A4: 46267 | B4: =IF(C3="","",C3) | C4: 2482 | D4: =IF(OR(B4="",C4=""),"",C4-B4) | M4: 46267 | N4: =IF(O3="","",O3) | O4: 859 | P4: =IF(OR(N4="",O4=""),"",O4-N4) | Y4: 46267 | Z4: =IF(AA3="","",AA3) | AA4: 208 | AB4: =IF(OR(Z4="",AA4=""),"",AA4-Z4)
A5: 46268 | B5: =IF(C4="","",C4) | C5: 2486 | D5: =IF(OR(B5="",C5=""),"",C5-B5) | M5: 46268 | N5: =IF(O4="","",O4) | O5: 869 | P5: =IF(OR(N5="",O5=""),"",O5-N5) | Y5: 46268 | Z5: =IF(AA4="","",AA4) | AA5: 211 | AB5: =IF(OR(Z5="",AA5=""),"",AA5-Z5)
A6: 46269 | B6: =IF(C5="","",C5) | C6: 2493 | D6: =IF(OR(B6="",C6=""),"",C6-B6) | M6: 46269 | N6: =IF(O5="","",O5) | O6: 875 | P6: =IF(OR(N6="",O6=""),"",O6-N6) | Y6: 46269 | Z6: =IF(AA5="","",AA5) | AA6: 211 | AB6: =IF(OR(Z6="",AA6=""),"",AA6-Z6)
A7: 46270 | B7: =IF(C6="","",C6) | C7: 2497 | D7: =IF(OR(B7="",C7=""),"",C7-B7) | M7: 46270 | N7: =IF(O6="","",O6) | O7: 885 | P7: =IF(OR(N7="",O7=""),"",O7-N7) | U7: 500 | V7: 875 | W7: =V7-V2 | X7: =U7/W7 | Y7: 46270 | Z7: =IF(AA6="","",AA6) | AA7: 213 | AB7: =IF(OR(Z7="",AA7=""),"",AA7-Z7) | AG7: 60 | AH7: 212 | AI7: =AH7-AH2 | AJ7: =AG7/AI7
A8: 46271 | B8: =IF(C7="","",C7) | C8: 2498 | D8: =IF(OR(B8="",C8=""),"",C8-B8) | M8: 46271 | N8: =IF(O7="","",O7) | O8: 889 | P8: =IF(OR(N8="",O8=""),"",O8-N8) | Y8: 46271 | Z8: =IF(AA7="","",AA7) | AA8: 213 | AB8: =IF(OR(Z8="",AA8=""),"",AA8-Z8)
A9: 46272 | B9: =IF(C8="","",C8) | C9: 2499 | D9: =IF(OR(B9="",C9=""),"",C9-B9) | M9: 46272 | N9: =IF(O8="","",O8) | O9: 899 | P9: =IF(OR(N9="",O9=""),"",O9-N9) | Y9: 46272 | Z9: =IF(AA8="","",AA8) | AA9: 216 | AB9: =IF(OR(Z9="",AA9=""),"",AA9-Z9)
A10: 46273 | B10: =IF(C9="","",C9) | C10: 2505 | D10: =IF(OR(B10="",C10=""),"",C10-B10) | M10: 46273 | N10: =IF(O9="","",O9) | O10: 912 | P10: =IF(OR(N10="",O10=""),"",O10-N10) | Y10: 46273 | Z10: =IF(AA9="","",AA9) | AA10: 226 | AB10: =IF(OR(Z10="",AA10=""),"",AA10-Z10)
A11: 46274 | B11: =IF(C10="","",C10) | C11: 2517 | D11: =IF(OR(B11="",C11=""),"",C11-B11) | M11: 46274 | N11: =IF(O10="","",O10) | O11: 922 | P11: =IF(OR(N11="",O11=""),"",O11-N11) | Y11: 46274 | Z11: =IF(AA10="","",AA10) | AA11: 230 | AB11: =IF(OR(Z11="",AA11=""),"",AA11-Z11)
A12: 46275 | B12: =IF(C11="","",C11) | C12: 2519 | D12: =IF(OR(B12="",C12=""),"",C12-B12) | I12: 227 | J12: 2517 | K12: =J12-J2 | L12: =I12/K12 | M12: 46275 | N12: =IF(O11="","",O11) | O12: 934 | P12: =IF(OR(N12="",O12=""),"",O12-N12) | Y12: 46275 | Z12: =IF(AA11="","",AA11) | AA12: 230 | AB12: =IF(OR(Z12="",AA12=""),"",AA12-Z12)
A13: 46276 | B13: =IF(C12="","",C12) | C13: 2520 | D13: =IF(OR(B13="",C13=""),"",C13-B13) | M13: 46276 | N13: =IF(O12="","",O12) | O13: 946 | P13: =IF(OR(N13="",O13=""),"",O13-N13) | Y13: 46276 | Z13: =IF(AA12="","",AA12) | AA13: 237 | AB13: =IF(OR(Z13="",AA13=""),"",AA13-Z13)
A14: 46277 | B14: =IF(C13="","",C13) | C14: 2522 | D14: =IF(OR(B14="",C14=""),"",C14-B14) | M14: 46277 | N14: =IF(O13="","",O13) | O14: 951 | P14: =IF(OR(N14="",O14=""),"",O14-N14) | Y14: 46277 | Z14: =IF(AA13="","",AA13) | AA14: 237 | AB14: =IF(OR(Z14="",AA14=""),"",AA14-Z14)
A15: 46278 | B15: =IF(C14="","",C14) | C15: 2524 | D15: =IF(OR(B15="",C15=""),"",C15-B15) | M15: 46278 | N15: =IF(O14="","",O14) | O15: 953 | P15: =IF(OR(N15="",O15=""),"",O15-N15) | Y15: 46278 | Z15: =IF(AA14="","",AA14) | AA15: 238 | AB15: =IF(OR(Z15="",AA15=""),"",AA15-Z15)
A16: 46279 | B16: =IF(C15="","",C15) | C16: 2535 | D16: =IF(OR(B16="",C16=""),"",C16-B16) | M16: 46279 | N16: =IF(O15="","",O15) | O16: 960 | P16: =IF(OR(N16="",O16=""),"",O16-N16) | Y16: 46279 | Z16: =IF(AA15="","",AA15) | AA16: 238 | AB16: =IF(OR(Z16="",AA16=""),"",AA16-Z16)
A17: 46280 | B17: =IF(C16="","",C16) | C17: 2550 | D17: =IF(OR(B17="",C17=""),"",C17-B17) | I17: 249 | J17: 2537 | K17: =J17-J12 | L17: =I17/K17 | M17: 46280 | N17: =IF(O16="","",O16) | O17: 970 | P17: =IF(OR(N17="",O17=""),"",O17-N17) | Y17: 46280 | Z17: =IF(AA16="","",AA16) | AA17: 241 | AB17: =IF(OR(Z17="",AA17=""),"",AA17-Z17)
A18: 46281 | B18: =IF(C17="","",C17) | C18: 2552 | D18: =IF(OR(B18="",C18=""),"",C18-B18) | M18: 46281 | N18: =IF(O17="","",O17) | O18: 977 | P18: =IF(OR(N18="",O18=""),"",O18-N18) | Y18: 46281 | Z18: =IF(AA17="","",AA17) | AA18: 241 | AB18: =IF(OR(Z18="",AA18=""),"",AA18-Z18)
A19: 46282 | B19: =IF(C18="","",C18) | C19: 2561 | D19: =IF(OR(B19="",C19=""),"",C19-B19) | M19: 46282 | N19: =IF(O18="","",O18) | O19: 985 | P19: =IF(OR(N19="",O19=""),"",O19-N19) | Y19: 46282 | Z19: =IF(AA18="","",AA18) | AA19: 244 | AB19: =IF(OR(Z19="",AA19=""),"",AA19-Z19)
A20: 46283 | B20: =IF(C19="","",C19) | C20: 2563 | D20: =IF(OR(B20="",C20=""),"",C20-B20) | M20: 46283 | N20: =IF(O19="","",O19) | O20: 992 | P20: =IF(OR(N20="",O20=""),"",O20-N20) | Y20: 46283 | Z20: =IF(AA19="","",AA19) | AA20: 247 | AB20: =IF(OR(Z20="",AA20=""),"",AA20-Z20)
A21: 46284 | B21: =IF(C20="","",C20) | C21: 2570 | D21: =IF(OR(B21="",C21=""),"",C21-B21) | M21: 46284 | N21: =IF(O20="","",O20) | O21: 996 | P21: =IF(OR(N21="",O21=""),"",O21-N21) | Y21: 46284 | Z21: =IF(AA20="","",AA20) | AA21: 247 | AB21: =IF(OR(Z21="",AA21=""),"",AA21-Z21)
A22: 46285 | B22: =IF(C21="","",C21) | D22: =IF(OR(B22="",C22=""),"",C22-B22) | M22: 46285 | N22: =IF(O21="","",O21) | P22: =IF(OR(N22="",O22=""),"",O22-N22) | Y22: 46285 | Z22: =IF(AA21="","",AA21) | AB22: =IF(OR(Z22="",AA22=""),"",AA22-Z22)
A23: 46286 | B23: =IF(C22="","",C22) | C23: 2572 | D23: =IF(OR(B23="",C23=""),"",C23-B23) | M23: 46286 | N23: =IF(O22="","",O22) | O23: 1006 | P23: =IF(OR(N23="",O23=""),"",O23-N23) | Y23: 46286 | Z23: =IF(AA22="","",AA22) | AA23: 247 | AB23: =IF(OR(Z23="",AA23=""),"",AA23-Z23)
A24: 46287 | B24: =IF(C23="","",C23) | C24: 2574 | D24: =IF(OR(B24="",C24=""),"",C24-B24) | E24: 10 | F24: 10 | M24: 46287 | N24: =IF(O23="","",O23) | O24: 1012 | P24: =IF(OR(N24="",O24=""),"",O24-N24) | Q24: 10 | R24: 10 | Y24: 46287 | Z24: =IF(AA23="","",AA23) | AA24: 249 | AB24: =IF(OR(Z24="",AA24=""),"",AA24-Z24) | AC24: 10 | AD24: 10 | AG24: 130.01
A25: 46288 | B25: =IF(C24="","",C24) | D25: =IF(OR(B25="",C25=""),"",C25-B25) | M25: 46288 | N25: =IF(O24="","",O24) | P25: =IF(OR(N25="",O25=""),"",O25-N25) | Y25: 46288 | Z25: =IF(AA24="","",AA24) | AB25: =IF(OR(Z25="",AA25=""),"",AA25-Z25)
A26: 46289 | B26: =IF(C25="","",C25) | C26: 2588 | D26: =IF(OR(B26="",C26=""),"",C26-B26) | M26: 46289 | N26: =IF(O25="","",O25) | P26: =IF(OR(N26="",O26=""),"",O26-N26) | Y26: 46289 | Z26: =IF(AA25="","",AA25) | AB26: =IF(OR(Z26="",AA26=""),"",AA26-Z26)
A27: 46290 | B27: =IF(C26="","",C26) | D27: =IF(OR(B27="",C27=""),"",C27-B27) | M27: 46290 | N27: =IF(O26="","",O26) | P27: =IF(OR(N27="",O27=""),"",O27-N27) | Y27: 46290 | Z27: =IF(AA26="","",AA26) | AB27: =IF(OR(Z27="",AA27=""),"",AA27-Z27)
A28: 46291 | B28: =IF(C27="","",C27) | D28: =IF(OR(B28="",C28=""),"",C28-B28) | M28: 46291 | N28: =IF(O27="","",O27) | P28: =IF(OR(N28="",O28=""),"",O28-N28) | Y28: 46291 | Z28: =IF(AA27="","",AA27) | AB28: =IF(OR(Z28="",AA28=""),"",AA28-Z28)
A29: 46292 | B29: =IF(C28="","",C28) | D29: =IF(OR(B29="",C29=""),"",C29-B29) | M29: 46292 | N29: =IF(O28="","",O28) | P29: =IF(OR(N29="",O29=""),"",O29-N29) | Y29: 46292 | Z29: =IF(AA28="","",AA28) | AB29: =IF(OR(Z29="",AA29=""),"",AA29-Z29)
A30: 46293 | B30: =IF(C29="","",C29) | D30: =IF(OR(B30="",C30=""),"",C30-B30) | M30: 46293 | N30: =IF(O29="","",O29) | P30: =IF(OR(N30="",O30=""),"",O30-N30) | Y30: 46293 | Z30: =IF(AA29="","",AA29) | AB30: =IF(OR(Z30="",AA30=""),"",AA30-Z30)
A31: 46294 | B31: =IF(C30="","",C30) | D31: =IF(OR(B31="",C31=""),"",C31-B31) | M31: 46294 | N31: =IF(O30="","",O30) | P31: =IF(OR(N31="",O31=""),"",O31-N31) | Y31: 46294 | Z31: =IF(AA30="","",AA30) | AB31: =IF(OR(Z31="",AA31=""),"",AA31-Z31)
A32: 46295 | B32: =IF(C31="","",C31) | D32: =IF(OR(B32="",C32=""),"",C32-B32) | M32: 46295 | N32: =IF(O31="","",O31) | P32: =IF(OR(N32="",O32=""),"",O32-N32) | Y32: 46295 | Z32: =IF(AA31="","",AA31) | AB32: =IF(OR(Z32="",AA32=""),"",AA32-Z32)
D34: =SUM(D3:D32) | G34: =SUM(G3:G32) | H34: No B/D | I34: =SUM(I3:I32) | K34: =SUM(K3:K32) | L34: =IF(K34=0,"",I34/K34) | P34: =SUM(P3:P32) | S34: =SUM(S3:S32) | T34: No B/D | U34: =SUM(U2:U32) | W34: =SUM(W3:W32) | X34: =IF(W34=0,"",U34/W34) | AB34: =SUM(AB3:AB32) | AE34: =SUM(AE3:AE32) | AF34: No B/D | AG34: =SUM(AG3:AG32) | AI34: =SUM(AI3:AI32) | AJ34: =IF(AI34=0,"",AG34/AI34)

Sheet SUMMARY
A1: Month | B1: KALMAR MACHINE AVERAGE-DHIRPUR | F1: KALMAR-1 MACHINE AVERAGE-DALPATPUR | J1: KALMAR-2 MACHINE AVERAGE-DALPATPUR
B2: Total Diesel | C2: Actual Running Hours | D2: Diesel Tank Full Hours | E2: Average | F2: Total Diesel | G2: Actual Running Hours | H2: Diesel Tank Full Hours | I2: Average | J2: Total Diesel | K2: Actual Running Hours | L2: Diesel Tank Full Hours | M2: Average | N2: Remark
A3: 45962 | B3: ='NOV-25'!I33 | C3: ='NOV-25'!D33 | D3: ='NOV-25'!K33 | E3: =B3/D3
A4: 45992 | B4: ='DEC-25'!I34 | C4: ='DEC-25'!D34 | D4: ='DEC-25'!K34 | E4: =B4/D4
