Workbook

Sheet PO
A1: Company Name | B1: JSW Infrastracture Ltd. | C1: JSW Infrastracture Ltd. | D1: JSW Infrastracture Ltd. | H1: XCMG-1 Operation started from 01-04-26
A2: Site Location | B2: Arakkonam Railway siding | C2: Arakkonam Railway siding | D2: Arakkonam Railway siding | H2: XCMG-2 & Fork lift Operation started from 15-04-26 and XCMG-2 is MLPM site xcmg because mlpm po have been expired
A3: State | B3: Tamil Nadu | C3: Tamil Nadu | D3: Tamil Nadu
A4: PO Date | B4: 46104 | C4: 46104 | D4: 46104
A5: PO Start Date | B5: 46113 | C5: 46113 | D5: 46113 | E5: Po effective date :- 27-03-26
A6: PO End Date | B6: 46477 | C6: 46477 | D6: 46477
A7: Asset Type | B7: Reach Stacker | C7: Reach Stacker | D7: Forklift
A8: Make | B8: XCMG-1 | C8: XCMG-2 | D8: Loadstar
A9: Asset Qty | B9: 1 | C9: 1 | D9: 1
A10: Model | B10: 2026 | C10: 2026 | D10: 2026
A11: Asset# | B11: XCMG-00253 | C11: NL02Q1679
A12: Loading Capacity | B12: 45 MT | C12: 45 MT
A13: Work Type | B13: Handling containers | C13: Handling containers | D13: Handling containers
A14: XCMG Monthly Hiring Charges | B14: 7,20,000 | C14: 7,20,000 | D14: 5,00,000
A15: Diesel | B15: Ekta | C15: Ekta | D15: Ekta
A16: Diesel Rembursment Cap | B16: 18 Ltrs per hour | C16: 18 Ltrs per hour
A17: Maintance/ Breakdown | B17: 32 Hrs/Month Not 24 Hours regularly | C17: 32 Hrs/Month Not 24 Hours regularly | D17: 32 Hrs/Month Not 24 Hours regularly
A18: Other Breakdown Deduction
A19: Cooling Period | B19: 2 Hours in every 24 Hours | C19: 2 Hours in every 24 Hours
A20: Condition 1
A21: Supervisor | B21: Ramavtar | C21: Ramavtar
A22: Supervisor Contact Number | B22: 7090277999 | C22: 7090277999
A23: Operator | B23: 2 | C23: 2
A24: Helper | B24: 2 | C24: 2
A25: Shift | B25: 9:00 to 21:00 21:00 to 9:00 | C25: 9:00 to 21:00 21:00 to 9:00
A26: Machine Billing
A27: Diesel Billing
A28: Billing Cycle | B28: 1-30 each month | C28: 1-30 each month
A29: Billing | B29: Monthly Billing Diesel Billing | C29: Monthly Billing Diesel Billing
A30: Billing Medium | B30: Email | C30: Email
A31: Document Required for billing | B31: Verified Logsheet with running hours and diesel qty, Diesel purchase slip copy | C31: Verified Logsheet with running hours and diesel qty, Diesel purchase slip copy
A32: Email ID Used
A33: Sent to
A34: CC
A35: Subject Line
A36: Company's Contact Person
A37: Company's Contact Number
A38: Billing Step | B38: Need to send the logsheet without diesel qty for verification on group to Ramavtar and after confirmation need to give the logsheet prinout with one diesel bill to sunil sharma for invoice creation, and then send logsheets and invoices on the above email Id's

Sheet Apr26
A1: Ekta Enterprises | I1: Ekta Enterprises | Q1: Ekta Enterprises
A2: REACH STACKER NO. XCMG-2-Diesel Cap - 18 Liters Per Hour | G2: 46113 | I2: REACH STACKER NO. XCMG-1-Diesel Cap - 18 Liters Per Hour | O2: 46113 | Q2: REACH STACKER NO. Fork Lift 35 Ton-Diesel Cap - 18 Liters Per Hour | W2: 46113
A3: LOCATION : JSW AARKONAM | I3: LOCATION : JSW AARKONAM | Q3: LOCATION : JSW AARKONAM
A4: DATE | B4: ACTIVITY | C4: OPERING HMR | D4: CLOSING HMR | E4: Running Hours | F4: BD HOURS | G4: DIESEL | H4: SIGNATURE | I4: DATE | J4: ACTIVITY | K4: OPERING HMR | L4: CLOSING HMR | M4: Running Hours | N4: BD HOURS | O4: DIESEL | P4: SIGNATURE | Q4: DATE | R4: ACTIVITY | S4: OPERING HMR | T4: CLOSING HMR | U4: Running Hours | V4: BD HOURS | W4: DIESEL | X4: SIGNATURE
A5: 46113 | I5: 46113 | J5: Running | K5: 29 | L5: 30 | M5: =L5-K5 | O5: 590 | Q5: 46113 | R5: Rake Handling | U5: =T5-S5
A6: 46114 | I6: 46114 | J6: Running | K6: =L5 | L6: 36 | M6: =L6-K6 | Q6: 46114 | U6: =T6-S6
A7: 46115 | I7: 46115 | J7: Running | K7: =L6 | L7: 44 | M7: =L7-K7 | Q7: 46115 | U7: =T7-S7
A8: 46116 | I8: 46116 | J8: Idel | K8: =L7 | L8: 44 | M8: =L8-K8 | Q8: 46116 | U8: =T8-S8
A9: 46117 | I9: 46117 | J9: Running | K9: =L8 | L9: 46 | M9: =L9-K9 | Q9: 46117 | U9: =T9-S9
A10: 46118 | I10: 46118 | J10: Running | K10: =L9 | L10: 48 | M10: =L10-K10 | Q10: 46118 | U10: =T10-S10
A11: 46119 | I11: 46119 | J11: Idel | K11: =L10 | L11: 48 | M11: =L11-K11 | Q11: 46119 | U11: =T11-S11
A12: 46120 | I12: 46120 | J12: Idel | K12: =L11 | L12: 48 | M12: =L12-K12 | Q12: 46120 | U12: =T12-S12
A13: 46121 | I13: 46121 | J13: Idel | K13: =L12 | L13: 48 | M13: =L13-K13 | Q13: 46121 | U13: =T13-S13
A14: 46122 | I14: 46122 | J14: Idel | K14: =L13 | L14: 48 | M14: =L14-K14 | Q14: 46122 | U14: =T14-S14
A15: 46123 | I15: 46123 | J15: Idel | K15: =L14 | L15: 48 | M15: =L15-K15 | Q15: 46123 | U15: =T15-S15
A16: 46124 | I16: 46124 | J16: Idel | K16: =L15 | L16: 48 | M16: =L16-K16 | Q16: 46124 | U16: =T16-S16
A17: 46125 | I17: 46125 | J17: Idel | K17: =L16 | L17: 48 | M17: =L17-K17 | Q17: 46125 | U17: =T17-S17
A18: 46126 | I18: 46126 | J18: Idel | K18: =L17 | L18: 48 | M18: =L18-K18 | Q18: 46126 | U18: =T18-S18
A19: 46127 | C19: XCMG-2 Operation started from 15-04-26 | I19: 46127 | J19: Running | K19: =L18 | L19: 49 | M19: =L19-K19 | Q19: 46127 | S19: Fork lift Operation started from 15-04-26
A20: 46128 | B20: Running | C20: 176 | D20: 177 | E20: =D20-C20 | I20: 46128 | J20: Running | K20: =L19 | L20: 52 | M20: =L20-K20 | Q20: 46128 | S20: 9 | T20: 9 | U20: =T20-S20
A21: 46129 | B21: Idel | C21: =D20 | D21: 177 | E21: =D21-C21 | I21: 46129 | J21: Idel | K21: =L20 | L21: 52 | M21: =L21-K21 | Q21: 46129 | S21: =T20 | T21: 9 | U21: =T21-S21
A22: 46130 | B22: Idel | C22: =D21 | D22: 177 | E22: =D22-C22 | I22: 46130 | J22: Idel | K22: =L21 | L22: 52 | M22: =L22-K22 | Q22: 46130 | S22: =T21 | T22: 9 | U22: =T22-S22
A23: 46131 | B23: Running | C23: =D22 | D23: 178 | E23: =D23-C23 | I23: 46131 | J23: Idel | K23: =L22 | L23: 52 | M23: =L23-K23 | Q23: 46131 | S23: =T22 | T23: 9 | U23: =T23-S23
A24: 46132 | B24: Running | C24: =D23 | D24: 188 | E24: =D24-C24 | I24: 46132 | J24: Idel | K24: =L23 | L24: 52 | M24: =L24-K24 | Q24: 46132 | S24: =T23 | T24: 9 | U24: =T24-S24
A25: 46133 | B25: Running | C25: =D24 | D25: 198 | E25: =D25-C25 | I25: 46133 | J25: Idel | K25: =L24 | L25: 52 | M25: =L25-K25 | Q25: 46133 | S25: =T24 | T25: 9 | U25: =T25-S25 | W25: 300
A26: 46134 | B26: Idel | C26: =D25 | D26: 198 | E26: =D26-C26 | I26: 46134 | J26: Idel | K26: =L25 | L26: 52 | M26: =L26-K26 | Q26: 46134 | S26: =T25 | T26: 9 | U26: =T26-S26
A27: 46135 | B27: Running | C27: =D26 | D27: 199 | E27: =D27-C27 | I27: 46135 | J27: Running | K27: =L26 | L27: 53 | M27: =L27-K27 | Q27: 46135 | S27: =T26 | T27: 9 | U27: =T27-S27
A28: 46136 | B28: Idel | C28: =D27 | D28: 199 | E28: =D28-C28 | I28: 46136 | J28: Idel | K28: =L27 | L28: 53 | M28: =L28-K28 | Q28: 46136 | S28: =T27 | T28: 9 | U28: =T28-S28
A29: 46137 | B29: Idel | C29: =D28 | D29: 199 | E29: =D29-C29 | I29: 46137 | J29: Idel | K29: =L28 | L29: 53 | M29: =L29-K29 | Q29: 46137 | S29: =T28 | T29: 9 | U29: =T29-S29
A30: 46138 | B30: Running | C30: =D29 | D30: 200 | E30: =D30-C30 | I30: 46138 | J30: Idel | K30: =L29 | L30: 53 | M30: =L30-K30 | Q30: 46138 | S30: =T29 | T30: 9 | U30: =T30-S30
A31: 46139 | B31: Idel | C31: =D30 | D31: 200 | E31: =D31-C31 | I31: 46139 | J31: Idel | K31: =L30 | L31: 53 | M31: =L31-K31 | Q31: 46139 | S31: =T30 | T31: 9.8 | U31: =T31-S31
A32: 46140 | B32: Idel | C32: =D31 | D32: 200 | E32: =D32-C32 | I32: 46140 | J32: Running | K32: =L31 | L32: 54 | M32: =L32-K32 | Q32: 46140 | S32: =T31 | T32: 10.5 | U32: =T32-S32
A33: 46141 | B33: Running | C33: =D32 | D33: 201 | E33: =D33-C33 | I33: 46141 | J33: Running | K33: =L32 | L33: 59 | M33: =L33-K33 | Q33: 46141 | S33: =T32 | T33: 12 | U33: =T33-S33
A34: 46142 | B34: Running | C34: =D33 | D34: 221 | E34: =D34-C34 | I34: 46142 | J34: Running | K34: =L33 | L34: 61 | M34: =L34-K34 | Q34: 46142 | S34: =T33 | T34: 12 | U34: =T34-S34
B35: Total | E35: =SUM(E5:E34) | J35: Total | M35: =SUM(M5:M34) | O35: =SUM(O5:O34) | R35: Total | U35: =SUM(U5:U34) | W35: 300
A37: Monthly Hiring Charges | C37: 720000 | I37: Monthly Hiring Charges | K37: 720000 | R37: Monthly Hiring Charges | T37: 500000
A38: Per Day Rate/30 | C38: =C37/30 | I38: Per Day Rate/30 | K38: =K37/30 | R38: Per Day Rate/30 | T38: =T37/30
A39: Per Hours Rate | C39: =C38/24 | D39: Diesel Cap | E39: Disel Qty | F39: Diesel Rate | G39: Diesel Amount | I39: Per Hours Rate | K39: =K38/24 | L39: Diesel Cap | M39: Disel Qty | N39: Diesel Rate | O39: Diesel Amount | R39: Per Hours Rate | T39: =T38/24 | U39: Diesel Cap | V39: Disel Qty | W39: Diesel Rate | X39: Diesel Amount
A40: 16-30 Apr Running | C40: 45 | D40: 19 | E40: =C40*D40 | F40: 93.2 | G40: =E40*F40 | I40: Apr Running | K40: 32 | L40: 19 | M40: =K40*L40 | N40: 93.2 | O40: =M40*N40 | R40: 16-30 Apr Running | T40: 3 | U40: 17 | V40: =T40*U40 | W40: 93.2 | X40: =V40*W40
A41: Monthly Hiring Charges 16 Days | C41: =C38*16 | R41: Monthly Hiring Charges 16 Days | T41: =T38*16

Sheet May26-update
A1: Ekta Enterprises | I1: Ekta Enterprises | Q1: Ekta Enterprises
A2: REACH STACKER NO. XCMG-2-Diesel Cap - 19 Liters Per Hour | G2: 46143 | I2: REACH STACKER NO. XCMG-1-Diesel Cap - 19 Liters Per Hour | O2: 46143 | Q2: REACH STACKER NO. Fork Lift 35 Ton-Diesel Cap - 17 Liters Per Hour | W2: 46143
A3: LOCATION : JSW AARKONAM | I3: LOCATION : JSW AARKONAM | Q3: LOCATION : JSW AARKONAM
A4: DATE | B4: ACTIVITY | C4: OPERING HMR | D4: CLOSING HMR | E4: Running Hours | F4: BD HOURS | G4: DIESEL | H4: SIGNATURE | I4: DATE | J4: ACTIVITY | K4: OPERING HMR | L4: CLOSING HMR | M4: Running Hours | N4: BD HOURS | O4: DIESEL | P4: SIGNATURE | Q4: DATE | R4: ACTIVITY | S4: OPERING HMR | T4: CLOSING HMR | U4: Running Hours | V4: BD HOURS | W4: DIESEL | X4: SIGNATURE
A5: 46143 | B5: Running | C5: 221 | D5: 223 | E5: =D5-C5 | I5: 46143 | J5: Running | K5: 61 | L5: 61 | M5: =L5-K5 | Q5: 46143 | R5: Rake Handling | S5: 12 | T5: 12.07 | U5: =T5-S5
A6: 46144 | B6: Running | C6: =D5 | D6: 224 | E6: =D6-C6 | I6: 46144 | J6: Running | K6: =L5 | L6: 62 | M6: =L6-K6 | Q6: 46144 | S6: =T5 | T6: 12.07 | U6: =T6-S6
A7: 46145 | B7: Running | C7: =D6 | D7: 226 | E7: =D7-C7 | I7: 46145 | J7: Running | K7: =L6 | L7: 62 | M7: =L7-K7 | Q7: 46145 | S7: =T6 | T7: 12.07 | U7: =T7-S7
A8: 46146 | B8: Running | C8: =D7 | D8: 227 | E8: =D8-C8 | I8: 46146 | J8: Running | K8: =L7 | L8: 63 | M8: =L8-K8 | Q8: 46146 | S8: =T7 | T8: 12.07 | U8: =T8-S8
A9: 46147 | B9: Running | C9: =D8 | D9: 229 | E9: =D9-C9 | I9: 46147 | J9: Running | K9: =L8 | L9: 63 | M9: =L9-K9 | Q9: 46147 | S9: =T8 | T9: 12.07 | U9: =T9-S9
A10: 46148 | B10: Running | C10: =D9 | D10: 231 | E10: =D10-C10 | I10: 46148 | J10: Running | K10: =L9 | L10: 63 | M10: =L10-K10 | Q10: 46148 | S10: =T9 | T10: 12.07 | U10: =T10-S10
A11: 46149 | B11: Running | C11: =D10 | D11: 232 | E11: =D11-C11 | I11: 46149 | J11: Running | K11: =L10 | L11: 63 | M11: =L11-K11 | Q11: 46149 | S11: =T10 | T11: 12.07 | U11: =T11-S11
A12: 46150 | B12: Running | C12: =D11 | D12: 234 | E12: =D12-C12 | I12: 46150 | J12: Running | K12: =L11 | L12: 64 | M12: =L12-K12 | Q12: 46150 | S12: =T11 | T12: 12.07 | U12: =T12-S12
A13: 46151 | B13: Running | C13: =D12 | D13: 236 | E13: =D13-C13 | I13: 46151 | J13: Running | K13: =L12 | L13: 64 | M13: =L13-K13 | Q13: 46151 | S13: =T12 | T13: 12.07 | U13: =T13-S13
A14: 46152 | B14: Running | C14: =D13 | D14: 237 | E14: =D14-C14 | I14: 46152 | J14: Running | K14: =L13 | L14: 64 | M14: =L14-K14 | Q14: 46152 | S14: =T13 | T14: 12.07 | U14: =T14-S14
A15: 46153 | B15: Running | C15: =D14 | D15: 240 | E15: =D15-C15 | I15: 46153 | J15: Running | K15: =L14 | L15: 65 | M15: =L15-K15 | Q15: 46153 | S15: =T14 | T15: 12.07 | U15: =T15-S15
A16: 46154 | B16: Running | C16: =D15 | D16: 245 | E16: =D16-C16 | I16: 46154 | J16: Running | K16: =L15 | L16: 75 | M16: =L16-K16 | Q16: 46154 | S16: =T15 | T16: 12.07 | U16: =T16-S16
A17: 46155 | B17: Running | C17: =D16 | D17: 247 | E17: =D17-C17 | I17: 46155 | J17: Running | K17: =L16 | L17: 76 | M17: =L17-K17 | Q17: 46155 | S17: =T16 | T17: 12.07 | U17: =T17-S17
... A24: 46162 | B24: Running | C24: =D23 | D24: 262 | E24: =D24-C24 | I24: 46162 | J24: Idel | K24: =L23 | L24: 76 | M24: =L24-K24 | Q24: 46162 | S24: =T23 | T24: 12.07 | U24: =T24-S24
A25: 46163 | B25: Running | C25: =D24 | D25: 265 | E25: =D25-C25 | I25: 46163 | J25: Idel | K25: =L24 | L25: 76 | M25: =L25-K25 | Q25: 46163 | R25: Rake Handling | S25: =T24 | T25: 13.09 | U25: =T25-S25
A26: 46164 | B26: Running | C26: =D25 | D26: 268 | E26: =D26-C26 | I26: 46164 | J26: Idel | K26: =L25 | L26: 76 | M26: =L26-K26 | Q26: 46164 | S26: =T25 | T26: 13.09 | U26: =T26-S26
A27: 46165 | B27: Running | C27: =D26 | D27: 269 | E27: =D27-C27 | I27: 46165 | J27: Idel | K27: =L26 | L27: 76 | M27: =L27-K27 | Q27: 46165 | S27: =T26 | T27: 13.09 | U27: =T27-S27
A28: 46166 | B28: Running | C28: =D27 | D28: 271 | E28: =D28-C28 | I28: 46166 | J28: Idel | K28: =L27 | L28: 76 | M28: =L28-K28 | Q28: 46166 | S28: =T27 | T28: 13.09 | U28: =T28-S28
A29: 46167 | B29: Running | C29: =D28 | D29: 272 | E29: =D29-C29 | I29: 46167 | J29: Idel | K29: =L28 | L29: 76 | M29: =L29-K29 | Q29: 46167 | S29: =T28 | T29: 13.09 | U29: =T29-S29
A30: 46168 | B30: Running | C30: =D29 | D30: 274 | E30: =D30-C30 | I30: 46168 | J30: Idel | K30: =L29 | L30: 76 | M30: =L30-K30 | Q30: 46168 | S30: =T29 | T30: 13.09 | U30: =T30-S30
A31: 46169 | B31: Running | C31: =D30 | D31: 276 | E31: =D31-C31 | I31: 46169 | J31: Idel | K31: =L30 | L31: 76 | M31: =L31-K31 | Q31: 46169 | S31: =T30 | T31: 13.09 | U31: =T31-S31
A32: 46170 | B32: Running | C32: =D31 | D32: 277 | E32: =D32-C32 | I32: 46170 | J32: Idel | K32: =L31 | L32: 76 | M32: =L32-K32 | Q32: 46170 | S32: =T31 | T32: 13.09 | U32: =T32-S32
A33: 46171 | B33: Running | C33: =D32 | D33: 279 | E33: =D33-C33 | I33: 46171 | J33: Idel | K33: =L32 | L33: 76 | M33: =L33-K33 | Q33: 46171 | S33: =T32 | T33: 13.09 | U33: =T33-S33
A34: 46172 | B34: Running | C34: =D33 | D34: 280 | E34: =D34-C34 | I34: 46172 | J34: Idel | K34: =L33 | L34: 76 | M34: =L34-K34 | Q34: 46172 | S34: =T33 | T34: 13.09 | U34: =T34-S34
A35: 46173 | B35: Running | C35: =D34 | D35: 281 | E35: =D35-C35 | I35: 46173 | J35: Idel | K35: =L34 | L35: 76 | M35: =L35-K35 | Q35: 46173 | S35: =T34 | T35: 13.09 | U35: =T35-S35
B36: Total | E36: =SUM(E5:E35) | J36: Total | M36: =SUM(M5:M35) | O36: =SUM(O5:O34) | R36: Total | U36: =SUM(U5:U34)
A38: Monthly Hiring Charges | C38: 720000 | I38: Monthly Hiring Charges | K38: 720000 | R38: Monthly Hiring Charges | T38: 500000
A39: Per Day Rate/31 | C39: =C38/31 | I39: Per Day Rate/31 | K39: =K38/31 | R39: Per Day Rate/31 | T39: =T38/31
A40: Per Hours Rate | C40: =C39/24 | D40: Diesel Cap | E40: Disel Qty | F40: Diesel Rate | G40: Diesel Amount | I40: Per Hours Rate | K40: =K39/24 | L40: Diesel Cap | M40: Disel Qty | N40: Diesel Rate | O40: Diesel Amount | R40: Per Hours Rate | T40: =T39/24 | U40: Diesel Cap | V40: Disel Qty | W40: Diesel Rate | X40: Diesel Amount
A41: 1-15 May Running | C41: 31 | D41: 19 | E41: =C41*D41 | F41: 93.2 | G41: =E41*F41 | I41: 1-15 May Running | K41: 15 | L41: 19 | M41: =K41*L41 | N41: 93.2 | O41: =M41*N41 | R41: 1-15 May Running | T41: 0.07 | U41: 17 | V41: =T41*U41 | W41: 93.2 | X41: =V41*W41
A42: 15-31 May Reading | C42: 29 | D42: 19 | E42: =C42*D42 | F42: 96.06 | G42: =E42*F42 | R42: 16-31 May Running | T42: 1.02 | U42: 17 | V42: =T42*U42 | W42: 96.06 | X42: =V42*W42
C43: =SUM(C41:C42) | E43: =SUM(E41:E42) | G43: =SUM(G41:G42) | T43: =SUM(T41:T42) | V43: =SUM(V41:V42) | X43: =SUM(X41:X42)
A44: Raise tax invoice with full hiring charges for machine | I44: Raise tax invoice with full hiring charges for machine | R44: Raise tax invoice with full hiring charges for machine
A45: Raise Diesel bill as per mentioned calculation | I45: Raise Diesel bill as per mentioned calculation | R45: Raise Diesel bill as per mentioned calculation
A46: Poonam Goswami | I46: Poonam Goswami | R46: Poonam Goswami
A47: 46181 | I47: 46181 | R47: 46181

Sheet May-26
A1: Diesel Cap - 19 Liters Per Hour | M1: Diesel Cap - 19 Liters Per Hour | W1: Fork Lift - 35Ton | AA1: Diesel Cap - 16 Liters Per Hour
A2: S.NO. | B2: DATE | C2: XCMG-1 | E2: Daily Running Hours | F2: Breakdown start time | G2: Breakdown end time | H2: Total B/D | I2: DIESEL Consumed | J2: HMR | K2: HOURS | L2: AVERAGE | M2: XCMG-2 | O2: Daily Running Hours | P2: Breakdown start time | Q2: Breakdown end time | R2: Total B/D | S2: DIESEL Consumed | T2: HMR | U2: HOURS | V2: AVERAGE | W2: OPENING HMR | X2: CLOSING HMR | Y2: TOTAL HMR | Z2: DIESEL | AA2: HMR | AB2: AVERAGE | AC2: BREAK DOWN
A3: PREV Stock | I3: 590 | J3: 30 | M3: PREV Stock | T3: 221 | W3: PREV Stock
A4: 1 | B4: 46143 | C4: 61 | D4: 64 | E4: =D4-C4 | M4: 221 | N4: 223 | O4: =N4-M4 | W4: 12 | X4: 12.07 | Y4: =X4-W4
A5: 2 | B5: =B4+1 | C5: =D4 | D5: 64 | E5: =D5-C5 | M5: =N4 | N5: 224 | O5: =N5-M5 | W5: =X4 | X5: 12.07 | Y5: =X5-W5
A6: 3 | B6: =B5+1 | C6: =D5 | D6: 64 | E6: =D6-C6 | M6: =N5 | N6: 226 | O6: =N6-M6 | W6: =X5 | X6: 12.07 | Y6: =X6-W6
A7: 4 | B7: =B6+1 | C7: =D6 | D7: 64 | E7: =D7-C7 | M7: =N6 | N7: 227 | O7: =N7-M7 | W7: =X6 | X7: 12.07 | Y7: =X7-W7
A8: 5 | B8: =B7+1 | C8: =D7 | D8: 65 | E8: =D8-C8 | M8: =N7 | N8: 229 | O8: =N8-M8 | W8: =X7 | X8: 12.07 | Y8: =X8-W8
A9: 6 | B9: =B8+1 | C9: =D8 | D9: 67 | E9: =D9-C9 | M9: =N8 | N9: 231 | O9: =N9-M9 | W9: =X8 | X9: 12.07 | Y9: =X9-W9
A10: 7 | B10: =B9+1 | C10: =D9 | D10: 67 | E10: =D10-C10 | M10: =N9 | N10: 234 | O10: =N10-M10 | W10: =X9 | X10: 12.07 | Y10: =X10-W10
A11: 8 | B11: =B10+1 | C11: =D10 | D11: 69 | E11: =D11-C11 | M11: =N10 | N11: 236 | O11: =N11-M11 | W11: =X10 | X11: 12.07 | Y11: =X11-W11
A12: 9 | B12: =B11+1 | C12: =D11 | D12: 69 | E12: =D12-C12 | M12: =N11 | N12: 236 | O12: =N12-M12 | W12: =X11 | X12: 12.07 | Y12: =X12-W12
A13: 10 | B13: =B12+1 | C13: =D12 | D13: 69 | E13: =D13-C13 | M13: =N12 | N13: 237 | O13: =N13-M13 | W13: =X12 | X13: 12.07 | Y13: =X13-W13
A14: 11 | B14: =B13+1 | C14: =D13 | D14: 69 | E14: =D14-C14 | M14: =N13 | N14: 251 | O14: =N14-M14 | W14: =X13 | X14: 12.07 | Y14: =X14-W14
A15: 12 | B15: =B14+1 | C15: =D14 | D15: 79 | E15: =D15-C15 | M15: =N14 | N15: 253 | O15: =N15-M15 | W15: =X14 | X15: 12.07 | Y15: =X15-W15
A16: 13 | B16: =B15+1 | C16: =D15 | D16: 79 | E16: =D16-C16 | M16: =N15 | N16: 254 | O16: =N16-M16 | W16: =X15 | X16: 12.07 | Y16: =X16-W16
... A18: 15 | B18: =B17+1 | C18: =D17 | D18: 81 | E18: =D18-C18 | M18: =N17 | N18: 263 | O18: =N18-M18 | W18: =X17 | X18: 12.07 | Y18: =X18-W18
A19: 16 | B19: =B18+1 | C19: =D18 | D19: 81 | E19: =D19-C19 | I19: 560 | J19: 81 | K19: =J19-J3 | L19: =(I19+I3)/K19 | M19: =N18 | N19: 263 | O19: =N19-M19 | W19: =X18 | X19: 12.07 | Y19: =X19-W19
A20: 17 | B20: =B19+1 | C20: =D19 | D20: 81 | E20: =D20-C20 | M20: =N19 | N20: 266 | O20: =N20-M20 | S20: 520 | T20: 263 | U20: =T20-T3 | V20: =S20/U20 | W20: =X19 | X20: 12.07 | Y20: =X20-W20
A21: 18 | B21: =B20+1 | C21: =D20 | D21: 83 | E21: =D21-C21 | M21: =N20 | N21: 267 | O21: =N21-M21 | W21: =X20 | X21: 12.07 | Y21: =X21-W21
A22: 19 | B22: =B21+1 | C22: =D21 | D22: 86 | E22: =D22-C22 | M22: =N21 | N22: 268 | O22: =N22-M22 | W22: =X21 | X22: 12.07 | Y22: =X22-W22
A23: 20 | B23: =B22+1 | C23: =D22 | D23: 87 | E23: =D23-C23 | M23: =N22 | N23: 269 | O23: =N23-M23 | W23: =X22 | X23: 12.07 | Y23: =X23-W23
A24: 21 | B24: =B23+1 | C24: =D23 | D24: 88 | E24: =D24-C24 | M24: =N23 | N24: 271 | O24: =N24-M24 | W24: =X23 | X24: 13.09 | Y24: =X24-W24
A25: 22 | B25: =B24+1 | C25: =D24 | D25: 90 | E25: =D25-C25 | M25: =N24 | N25: 273 | O25: =N25-M25 | W25: =X24 | X25: 13.09 | Y25: =X25-W25
A26: 23 | B26: =B25+1 | C26: =D25 | D26: 90 | E26: =D26-C26 | M26: =N25 | N26: 279 | O26: =N26-M26 | W26: =X25 | X26: 13.09 | Y26: =X26-W26
A27: 24 | B27: =B26+1 | C27: =D26 | D27: 91 | E27: =D27-C27 | M27: =N26 | N27: 280 | O27: =N27-M27 | W27: =X26 | X27: 13.09 | Y27: =X27-W27
A28: 25 | B28: =B27+1 | C28: =D27 | D28: 91 | E28: =D28-C28 | M28: =N27 | N28: 282 | O28: =N28-M28 | W28: =X27 | X28: 13.09 | Y28: =X28-W28
A29: 26 | B29: =B28+1 | C29: =D28 | D29: 93 | E29: =D29-C29 | M29: =N28 | N29: 283 | O29: =N29-M29 | W29: =X28 | X29: 13.09 | Y29: =X29-W29
A30: 27 | B30: =B29+1 | C30: =D29 | D30: 93 | E30: =D30-C30 | M30: =N29 | N30: 283 | O30: =N30-M30 | W30: =X29 | X30: 13.09 | Y30: =X30-W30
A31: 28 | B31: =B30+1 | C31: =D30 | D31: 93 | E31: =D31-C31 | M31: =N30 | N31: 284 | O31: =N31-M31 | W31: =X30 | X31: 13.09 | Y31: =X31-W31
A32: 29 | B32: =B31+1 | C32: =D31 | D32: 93 | E32: =D32-C32 | M32: =N31 | N32: 285 | O32: =N32-M32 | W32: =X31 | X32: 13.09 | Y32: =X32-W32
... A34: 31 | B34: =B33+1 | C34: =D33 | D34: 94 | E34: =D34-C34 | M34: =N33 | N34: 285 | O34: =N34-M34 | W34: =X33 | X34: 13.09 | Y34: =X34-W34
A35: TOTAL | E35: =SUBTOTAL(9,E4:E34) | H35: No break down | I35: =SUBTOTAL(9,I3:I34) | K35: =SUBTOTAL(9,K4:K34) | L35: =I35/K35 | O35: =SUBTOTAL(9,O4:O34) | R35: No break down | S35: =SUBTOTAL(9,S4:S34) | U35: =SUBTOTAL(9,U4:U34) | V35: =S35/U35 | Y35: =SUBTOTAL(9,Y4:Y34) | Z35: =SUBTOTAL(9,Z4:Z34) | AC35: No break down

Sheet June-26
A1: Diesel Cap - 19 Liters Per Hour | N1: Diesel Cap - 19 Liters Per Hour | X1: Fork Lift - 35Ton | AB1: Diesel Cap - 17 Liters Per Hour
A2: S.NO. | B2: DATE | C2: Diesel Purchased | D2: XCMG-1 (2026) | F2: Daily Running Hours | G2: Breakdown start time | H2: Breakdown end time | I2: Total B/D | J2: DIESEL Consumed | K2: HMR | L2: HOURS | M2: AVERAGE | N2: XCMG-2 (2023) | P2: Daily Running Hours | Q2: Breakdown start time | R2: Breakdown end time | S2: Total B/D | T2: DIESEL Consumed | U2: HMR | V2: HOURS | W2: AVERAGE | X2: OPENING HMR | Y2: CLOSING HMR | Z2: TOTAL HMR | AA2: DIESEL | AB2: HMR | AC2: AVERAGE | AD2: BREAK DOWN | AE2: Diesel Balance
K3: 81 | U3: 263 | AE3: 2330
A4: 1 | B4: 46174 | D4: 94 | E4: 94 | F4: =E4-D4 | N4: 285 | O4: 286 | P4: =O4-N4 | X4: 13 | Y4: 13 | Z4: =Y4-X4 | AE4: =AE3+C4-J4-T4-AA4
A5: 2 | B5: =B4+1 | D5: =E4 | E5: 95 | F5: =E5-D5 | N5: =O4 | O5: 286 | P5: =O5-N5 | X5: =Y4 | Y5: 13 | Z5: =Y5-X5 | AE5: =AE4+C5-J5-T5-AA5
A6: 3 | B6: =B5+1 | D6: =E5 | E6: 96 | F6: =E6-D6 | N6: =O5 | O6: 287 | P6: =O6-N6 | X6: =Y5 | Y6: 14 | Z6: =Y6-X6 | AE6: =AE5+C6-J6-T6-AA6
A7: 4 | B7: =B6+1 | D7: =E6 | E7: 97 | F7: =E7-D7 | N7: =O6 | O7: 288 | P7: =O7-N7 | X7: =Y6 | Y7: 14 | Z7: =Y7-X7 | AE7: =AE6+C7-J7-T7-AA7
A8: 5 | B8: =B7+1 | D8: =E7 | E8: 99 | F8: =E8-D8 | N8: =O7 | O8: 288 | P8: =O8-N8 | X8: =Y7 | Y8: 14 | Z8: =Y8-X8 | AE8: =AE7+C8-J8-T8-AA8
A9: 6 | B9: =B8+1 | D9: =E8 | E9: 100 | F9: =E9-D9 | N9: =O8 | O9: 289 | P9: =O9-N9 | X9: =Y8 | Y9: 14 | Z9: =Y9-X9 | AE9: =AE8+C9-J9-T9-AA9
A10: 7 | B10: =B9+1 | D10: =E9 | E10: 100 | F10: =E10-D10 | N10: =O9 | O10: 290 | P10: =O10-N10 | X10: =Y9 | Y10: 14 | Z10: =Y10-X10 | AE10: =AE9+C10-J10-T10-AA10
A11: 8 | B11: =B10+1 | D11: =E10 | E11: 100 | F11: =E11-D11 | N11: =O10 | O11: 292 | P11: =O11-N11 | X11: =Y10 | Y11: 14 | Z11: =Y11-X11 | AE11: =AE10+C11-J11-T11-AA11
A12: 9 | B12: =B11+1 | D12: =E11 | E12: 101 | F12: =E12-D12 | N12: =O11 | O12: 296 | P12: =O12-N12 | X12: =Y11 | Y12: 14 | Z12: =Y12-X12 | AE12: =AE11+C12-J12-T12-AA12
A13: 10 | B13: =B12+1 | D13: =E12 | E13: 102 | F13: =E13-D13 | N13: =O12 | O13: 298 | P13: =O13-N13 | X13: =Y12 | Y13: 14 | Z13: =Y13-X13 | AE13: =AE12+C13-J13-T13-AA13
A14: 11 | B14: =B13+1 | D14: =E13 | E14: 102 | F14: =E14-D14 | N14: =O13 | O14: 300 | P14: =O14-N14 | X14: =Y13 | Y14: 14 | Z14: =Y14-X14 | AE14: =AE13+C14-J14-T14-AA14
A15: 12 | B15: =B14+1 | D15: =E14 | E15: 103 | F15: =E15-D15 | J15: 220 | K15: 103 | L15: =K15-K3 | M15: =J15/L15 | N15: =O14 | O15: 303 | P15: =O15-N15 | T15: 390 | U15: 303 | V15: =U15-U3 | W15: =T15/V15 | X15: =Y14 | Y15: 15 | Z15: =Y15-X15 | AE15: =AE14+C15-J15-T15-AA15
A16: 13 | B16: =B15+1 | D16: =E15 | E16: 104 | F16: =E16-D16 | N16: =O15 | O16: 303 | P16: =O16-N16 | X16: =Y15 | Y16: 15 | Z16: =Y16-X16 | AE16: =AE15+C16-J16-T16-AA16
A17: 14 | B17: =B16+1 | D17: =E16 | E17: 110 | F17: =E17-D17 | N17: =O16 | O17: 310 | P17: =O17-N17 | X17: =Y16 | Y17: 15 | Z17: =Y17-X17 | AE17: =AE16+C17-J17-T17-AA17
A18: 15 | B18: =B17+1 | D18: =E17 | E18: 117 | F18: =E18-D18 | N18: =O17 | O18: 320 | P18: =O18-N18 | X18: =Y17 | Y18: 15 | Z18: =Y18-X18 | AE18: =AE17+C18-J18-T18-AA18
A19: 16 | B19: =B18+1 | D19: =E18 | E19: 121 | F19: =E19-D19 | N19: =O18 | O19: 320 | P19: =O19-N19 | X19: =Y18 | Y19: 15 | Z19: =Y19-X19 | AE19: =AE18+C19-J19-T19-AA19
A20: 17 | B20: =B19+1 | D20: =E19 | E20: 126 | F20: =E20-D20 | N20: =O19 | O20: 321 | P20: =O20-N20 | X20: =Y19 | Y20: 15 | Z20: =Y20-X20 | AE20: =AE19+C20-J20-T20-AA20
A21: 18 | B21: =B20+1 | D21: =E20 | E21: 132 | F21: =E21-D21 | N21: =O20 | O21: 322 | P21: =O21-N21 | X21: =Y20 | Y21: 15 | Z21: =Y21-X21 | AE21: =AE20+C21-J21-T21-AA21
A22: 19 | B22: =B21+1 | D22: =E21 | E22: 132 | F22: =E22-D22 | N22: =O21 | O22: 324 | P22: =O22-N22 | X22: =Y21 | Y22: 15 | Z22: =Y22-X22 | AE22: =AE21+C22-J22-T22-AA22
A23: 20 | B23: =B22+1 | D23: =E22 | E23: 136 | F23: =E23-D23 | N23: =O22 | O23: 326 | P23: =O23-N23 | X23: =Y22 | Y23: 15 | Z23: =Y23-X23 | AE23: =AE22+C23-J23-T23-AA23
A24: 21 | B24: =B23+1 | D24: =E23 | E24: 137 | F24: =E24-D24 | N24: =O23 | O24: 330 | P24: =O24-N24 | X24: =Y23 | Y24: 15 | Z24: =Y24-X24 | AE24: =AE23+C24-J24-T24-AA24
A25: 22 | B25: =B24+1 | D25: =E24 | E25: 140 | F25: =E25-D25 | N25: =O24 | O25: 338 | P25: =O25-N25 | X25: =Y24 | Y25: 15 | Z25: =Y25-X25 | AE25: =AE24+C25-J25-T25-AA25
A26: 23 | B26: =B25+1 | D26: =E25 | E26: 140 | F26: =E26-D26 | N26: =O25 | O26: 342 | P26: =O26-N26 | X26: =Y25 | Y26: 27 | Z26: =Y26-X26 | AE26: =AE25+C26-J26-T26-AA26
A27: 24 | B27: =B26+1 | D27: =E26 | E27: 140 | F27: =E27-D27 | N27: =O26 | O27: 344 | P27: =O27-N27 | X27: =Y26 | Y27: 27 | Z27: =Y27-X27 | AE27: =AE26+C27-J27-T27-AA27
... A30: 27 | B30: =B29+1 | D30: =E29 | E30: 144 | F30: =E30-D30 | N30: =O29 | O30: 349 | P30: =O30-N30 | X30: =Y29 | Y30: 30 | Z30: =Y30-X30 | AE30: =AE29+C30-J30-T30-AA30
A31: 28 | B31: =B30+1 | C31: 1400 | D31: =E30 | E31: 146 | F31: =E31-D31 | J31: 490 | K31: 145 | L31: =K31-K15 | M31: =J31/L31 | N31: =O30 | O31: 352 | P31: =O31-N31 | T31: 530 | U31: 350 | V31: =U31-U15 | W31: =T31/V31 | X31: =Y30 | Y31: 30 | Z31: =Y31-X31 | AE31: =AE30+C31-J31-T31-AA31
A32: 29 | B32: =B31+1 | D32: =E31 | E32: 147 | F32: =E32-D32 | N32: =O31 | O32: 352 | P32: =O32-N32 | X32: =Y31 | Y32: 30 | Z32: =Y32-X32 | AE32: =AE31+C32-J32-T32-AA32
A33: 30 | B33: =B32+1 | D33: =E32 | E33: 147 | F33: =E33-D33 | N33: =O32 | O33: 353 | P33: =O33-N33 | X33: =Y32 | Y33: 30 | Z33: =Y33-X33 | AE33: =AE32+C33-J33-T33-AA33
A34: TOTAL | C34: =SUM(C4:C33) | F34: =SUBTOTAL(9,F4:F33) | I34: No B/D | J34: =SUBTOTAL(9,J4:J33) | L34: =SUBTOTAL(9,L4:L33) | M34: =J34/L34 | P34: =SUBTOTAL(9,P4:P33) | S34: No B/D | T34: =SUBTOTAL(9,T4:T33) | V34: =SUBTOTAL(9,V4:V33) | W34: =T34/V34 | Z34: =SUM(Z4:Z33) | AA34: =SUBTOTAL(9,AA4:AA33) | AD34: No B/D | AE34: =AE33
AE35: 200 | AF35: SANY MACHINE ME 200 LTR DIESEL FILL KIYA 24-06-2026
AD36: DIESEL BALANCE | AE36: =AE34-AE35
W38: =2320+1400
W39: =710+920
W40: =W38-W39

Sheet June26-update
A1: Ekta Enterprises | J1: Ekta Enterprises | S1: Ekta Enterprises
A2: REACH STACKER NO. XCMG-2-Diesel Cap - 19 Liters Per Hour | G2: 46174 | J2: REACH STACKER NO. XCMG-1-Diesel Cap - 19 Liters Per Hour | P2: 46174 | S2: REACH STACKER NO. Fork Lift 35 Ton-Diesel Cap - 17 Liters Per Hour | Y2: 46174
A3: LOCATION : JSW AARKONAM | J3: LOCATION : JSW AARKONAM | S3: LOCATION : JSW AARKONAM
A4: DATE | B4: ACTIVITY | C4: OPERING HMR | D4: CLOSING HMR | E4: Running Hours | F4: BD HOURS | G4: DIESEL | H4: OPERATOR SIGNATURE | I4: JSW SIGNATURE | J4: DATE | K4: ACTIVITY | L4: OPERING HMR | M4: CLOSING HMR | N4: Running Hours | O4: BD HOURS | P4: DIESEL | Q4: OPERATOR SIGNATURE | R4: JSW SIGNATURE | S4: DATE | T4: ACTIVITY | U4: OPERING HMR | V4: CLOSING HMR | W4: Running Hours | X4: BD HOURS | Y4: DIESEL | Z4: OPERATOR SIGNATURE | AA4: JSW SIGNATURE
A5: 46174 | C5: 281 | D5: 286 | E5: =D5-C5 | J5: 46174 | L5: 76 | M5: 82 | N5: =M5-L5 | S5: 46174 | U5: 13 | V5: 13 | W5: =V5-U5
A6: =A5+1 | C6: =D5 | D6: 286 | E6: =D6-C6 | J6: =J5+1 | L6: =M5 | M6: 85 | N6: =M6-L6 | S6: =S5+1 | U6: =V5 | V6: 13 | W6: =V6-U6
A7: =A6+1 | C7: =D6 | D7: 287 | E7: =D7-C7 | J7: =J6+1 | L7: =M6 | M7: 94 | N7: =M7-L7 | S7: =S6+1 | U7: =V6 | V7: 14 | W7: =V7-U7
A8: =A7+1 | C8: =D7 | D8: 288 | E8: =D8-C8 | J8: =J7+1 | L8: =M7 | M8: 97 | N8: =M8-L8 | S8: =S7+1 | U8: =V7 | V8: 14 | W8: =V8-U8
A9: =A8+1 | C9: =D8 | D9: 288 | E9: =D9-C9 | J9: =J8+1 | L9: =M8 | M9: 99 | N9: =M9-L9 | S9: =S8+1 | U9: =V8 | V9: 14 | W9: =V9-U9
A10: =A9+1 | C10: =D9 | D10: 289 | E10: =D10-C10 | J10: =J9+1 | L10: =M9 | M10: 100 | N10: =M10-L10 | S10: =S9+1 | U10: =V9 | V10: 14 | W10: =V10-U10
A11: =A10+1 | C11: =D10 | D11: 290 | E11: =D11-C11 | J11: =J10+1 | L11: =M10 | M11: 100 | N11: =M11-L11 | S11: =S10+1 | U11: =V10 | V11: 14 | W11: =V11-U11
A12: =A11+1 | C12: =D11 | D12: 292 | E12: =D12-C12 | J12: =J11+1 | L12: =M11 | M12: 100 | N12: =M12-L12 | S12: =S11+1 | U12: =V11 | V12: 14 | W12: =V12-U12
A13: =A12+1 | C13: =D12 | D13: 296 | E13: =D13-C13 | J13: =J12+1 | L13: =M12 | M13: 101 | N13: =M13-L13 | S13: =S12+1 | U13: =V12 | V13: 14 | W13: =V13-U13
A14: =A13+1 | C14: =D13 | D14: 298 | E14: =D14-C14 | J14: =J13+1 | L14: =M13 | M14: 102 | N14: =M14-L14 | S14: =S13+1 | U14: =V13 | V14: 14 | W14: =V14-U14
A15: =A14+1 | C15: =D14 | D15: 300 | E15: =D15-C15 | J15: =J14+1 | L15: =M14 | M15: 102 | N15: =M15-L15 | S15: =S14+1 | U15: =V14 | V15: 14 | W15: =V15-U15
A16: =A15+1 | C16: =D15 | D16: 303 | E16: =D16-C16 | J16: =J15+1 | L16: =M15 | M16: 103 | N16: =M16-L16 | S16: =S15+1 | U16: =V15 | V16: 15 | W16: =V16-U16
A17: =A16+1 | C17: =D16 | D17: 303 | E17: =D17-C17 | J17: =J16+1 | L17: =M16 | M17: 104 | N17: =M17-L17 | S17: =S16+1 | U17: =V16 | V17: 15 | W17: =V17-U17
... A34: =A33+1 | C34: =D33 | D34: 353 | E34: =D34-C34 | J34: =J33+1 | L34: =M33 | M34: 147 | N34: =M34-L34 | S34: =S33+1 | U34: =V33 | V34: 30 | W34: =V34-U34
B35: Total | E35: =SUM(E5:E34) | K35: Total | N35: =SUM(N5:N34) | T35: Total | W35: =SUM(W5:W34)
A37: Monthly Hiring Charges | C37: 720000 | J37: Monthly Hiring Charges | L37: 720000 | T37: Monthly Hiring Charges | V37: 500000
A38: Per Day Rate/30 | C38: =C37/30 | J38: Per Day Rate/30 | L38: =L37/30 | T38: Per Day Rate/30 | V38: =V37/30
A39: Per Hours Rate | C39: =C38/24 | J39: Per Hours Rate | L39: =L38/24 | T39: Per Hours Rate | V39: =V38/24
A40: Total KM Running | C40: 72 | J40: Total KM Running | L40: 71 | T40: Total KM Running | V40: 17
A41: Diesel Cap | C41: 19 | J41: Diesel Cap | L41: 19 | T41: Diesel Cap | V41: 17
A42: Disel Qty | C42: =C40*C41 | J42: Disel Qty | L42: =L40*L41 | T42: Disel Qty | V42: =V40*V41
A43: Diesel Rate | C43: 100.37 | J43: Diesel Rate | L43: 100.37 | T43: Diesel Rate | V43: 100.37
A44: Diesel Amount | C44: =C42*C43 | J44: Diesel Amount | L44: =L42*L43 | T44: Diesel Amount | V44: =V42*V43
A46: Raise tax invoice with full hiring charges for machine | J46: Raise tax invoice with full hiring charges for machine | T46: Raise tax invoice with full hiring charges for machine
A47: Raise Diesel bill as per mentioned calculation | J47: Raise Diesel bill as per mentioned calculation | T47: Raise Diesel bill as per mentioned calculation
A48: Poonam Goswami | J48: Poonam Goswami | T48: Poonam Goswami
A49: 46210 | J49: 46210 | T49: 46210

Sheet JULY26-UPDATE
A1: Ekta Enterprises | P1: Ekta Enterprises | AD1: Ekta Enterprises
A2: REACH STACKER NO. XCMG-2-Diesel Cap - 19 Liters Per Hour | K2: 46204 | P2: REACH STACKER NO. XCMG-1-Diesel Cap - 19 Liters Per Hour | X2: 46204 | AD2: REACH STACKER NO. Fork Lift 35 Ton-Diesel Cap - 17 Liters Per Hour | AL2: 46204
A3: LOCATION : JSW AARKONAM | P3: LOCATION : JSW AARKONAM | AD3: LOCATION : JSW AARKONAM
A4: DATE | B4: DIESEL PURCHASED | C4: ACTIVITY | D4: OPERING HMR | E4: CLOSING HMR | F4: Running Hours | G4: BD START TIME | H4: BD END TIME | I4: BD HOURS | J4: DIESEL | K4: HMR | L4: HOUR | M4: AVERAGE | N4: OPERATOR SIGNATURE | O4: JSW SIGNATURE | P4: DATE | Q4: ACTIVITY | R4: OPERING HMR | S4: CLOSING HMR | T4: Running Hours | U4: BD START TIME | V4: BD END TIME | W4: BD HOURS | X4: DIESEL | Y4: HMR | Z4: HOUR | AA4: AVERAGE | AB4: OPERATOR SIGNATURE | AC4: JSW SIGNATURE | AD4: DATE | AE4: ACTIVITY | AF4: OPERING HMR | AG4: CLOSING HMR | AH4: Running Hours | AI4: BD START TIME | AJ4: BD END TIME | AK4: BD HOURS | AL4: DIESEL | AM4: HMR | AN4: HOUR | AO4: AVERAGE | AP4: OPERATOR SIGNATURE | AQ4: JSW SIGNATURE | AR4: Diesel Balance
K5: 350 | Y5: 145 | AR5: 1900
A6: 46204 | D6: 353 | E6: 354 | F6: =E6-D6 | P6: 46204 | R6: 147 | S6: 148 | T6: =S6-R6 | AD6: 46204 | AF6: 30 | AG6: 30 | AH6: =AG6-AF6 | AR6: =AR5+B6-J6-X6-AL6
A7: =A6+1 | D7: =E6 | E7: 355 | F7: =E7-D7 | P7: =P6+1 | R7: =S6 | S7: 149 | T7: =S7-R7 | AD7: =AD6+1 | AF7: =AG6 | AG7: 31 | AH7: =AG7-AF7 | AR7: =AR6+B7-J7-X7-AL7
A8: =A7+1 | D8: =E7 | E8: 355 | F8: =E8-D8 | P8: =P7+1 | R8: =S7 | S8: 149 | T8: =S8-R8 | AD8: =AD7+1 | AF8: =AG7 | AG8: 31 | AH8: =AG8-AF8 | AR8: =AR7+B8-J8-X8-AL8
A9: =A8+1 | D9: =E8 | E9: 355 | F9: =E9-D9 | P9: =P8+1 | R9: =S8 | S9: 149 | T9: =S9-R9 | AD9: =AD8+1 | AF9: =AG8 | AG9: 31 | AH9: =AG9-AF9 | AR9: =AR8+B9-J9-X9-AL9
A10: =A9+1 | D10: =E9 | E10: 355 | F10: =E10-D10 | P10: =P9+1 | R10: =S9 | S10: 150 | T10: =S10-R10 | AD10: =AD9+1 | AF10: =AG9 | AG10: 31 | AH10: =AG10-AF10 | AR10: =AR9+B10-J10-X10-AL10
A11: =A10+1 | D11: =E10 | E11: 356 | F11: =E11-D11 | P11: =P10+1 | R11: =S10 | S11: 150 | T11: =S11-R11 | AD11: =AD10+1 | AF11: =AG10 | AG11: 31 | AH11: =AG11-AF11 | AR11: =AR10+B11-J11-X11-AL11
A12: =A11+1 | D12: =E11 | E12: 356 | F12: =E12-D12 | P12: =P11+1 | R12: =S11 | S12: 150 | T12: =S12-R12 | AD12: =AD11+1 | AF12: =AG11 | AG12: 31 | AH12: =AG12-AF12 | AR12: =AR11+B12-J12-X12-AL12
A13: =A12+1 | D13: =E12 | E13: 356 | F13: =E13-D13 | P13: =P12+1 | R13: =S12 | S13: 150 | T13: =S13-R13 | AD13: =AD12+1 | AF13: =AG12 | AG13: 31 | AH13: =AG13-AF13 | AR13: =AR12+B13-J13-X13-AL13
A14: =A13+1 | D14: =E13 | E14: 356 | F14: =E14-D14 | P14: =P13+1 | R14: =S13 | S14: 153 | T14: =S14-R14 | AD14: =AD13+1 | AF14: =AG13 | AG14: 33 | AH14: =AG14-AF14 | AR14: =AR13+B14-J14-X14-AL14
A15: =A14+1 | D15: =E14 | E15: 357 | F15: =E15-D15 | P15: =P14+1 | R15: =S14 | S15: 154 | T15: =S15-R15 | AD15: =AD14+1 | AF15: =AG14 | AG15: 33 | AH15: =AG15-AF15 | AR15: =AR14+B15-J15-X15-AL15
A16: =A15+1 | D16: =E15 | E16: 359 | F16: =E16-D16 | P16: =P15+1 | R16: =S15 | S16: 155 | T16: =S16-R16 | AD16: =AD15+1 | AF16: =AG15 | AG16: 34 | AH16: =AG16-AF16 | AR16: =AR15+B16-J16-X16-AL16
A17: =A16+1 | D17: =E16 | E17: 364 | F17: =E17-D17 | P17: =P16+1 | R17: =S16 | S17: 159 | T17: =S17-R17 | AD17: =AD16+1 | AF17: =AG16 | AG17: 40 | AH17: =AG17-AF17 | AL17: 200 | AM17: 37 | AR17: =AR16+B17-J17-X17-AL17
A18: =A17+1 | D18: =E17 | E18: 374 | F18: =E18-D18 | P18: =P17+1 | R18: =S17 | S18: 164 | T18: =S18-R18 | AD18: =AD17+1 | AF18: =AG17 | AG18: 42 | AH18: =AG18-AF18 | AR18: =AR17+B18-J18-X18-AL18
A19: =A18+1 | D19: =E18 | E19: 386 | F19: =E19-D19 | P19: =P18+1 | R19: =S18 | S19: 173 | T19: =S19-R19 | AD19: =AD18+1 | AF19: =AG18 | AG19: 46 | AH19: =AG19-AF19 | AR19: =AR18+B19-J19-X19-AL19
A20: =A19+1 | D20: =E19 | E20: 391 | F20: =E20-D20 | P20: =P19+1 | R20: =S19 | S20: 179 | T20: =S20-R20 | AD20: =AD19+1 | AF20: =AG19 | AG20: 46 | AH20: =AG20-AF20 | AR20: =AR19+B20-J20-X20-AL20
A21: =A20+1 | D21: =E20 | E21: 398 | F21: =E21-D21 | J21: 370 | K21: 394 | L21: =K21-K5 | M21: =J21/L21 | P21: =P20+1 | R21: =S20 | S21: 183 | T21: =S21-R21 | X21: 425 | Y21: 181 | Z21: =Y21-Y5 | AA21: =X21/Z21 | AD21: =AD20+1 | AF21: =AG20 | AG21: 50 | AH21: =AG21-AF21 | AR21: =AR20+B21-J21-X21-AL21
A22: =A21+1 | B22: 1400 | D22: =E21 | E22: 404 | F22: =E22-D22 | P22: =P21+1 | R22: =S21 | S22: 187 | T22: =S22-R22 | AD22: =AD21+1 | AF22: =AG21 | AG22: 56 | AH22: =AG22-AF22 | AL22: 315 | AM22: 51 | AR22: =AR21+B22-J22-X22-AL22
A23: =A22+1 | D23: =E22 | E23: 409 | F23: =E23-D23 | P23: =P22+1 | R23: =S22 | S23: 189 | T23: =S23-R23 | AD23: =AD22+1 | AF23: =AG22 | AG23: 56 | AH23: =AG23-AF23 | AR23: =AR22+B23-J23-X23-AL23
A24: =A23+1 | D24: =E23 | E24: 414 | F24: =E24-D24 | P24: =P23+1 | R24: =S23 | S24: 194 | T24: =S24-R24 | AD24: =AD23+1 | AF24: =AG23 | AG24: 62 | AH24: =AG24-AF24 | AR24: =AR23+B24-J24-X24-AL24
A25: =A24+1 | D25: =E24 | E25: 429 | F25: =E25-D25 | P25: =P24+1 | R25: =S24 | S25: 209 | T25: =S25-R25 | AD25: =AD24+1 | AF25: =AG24 | AG25: 66 | AH25: =AG25-AF25 | AR25: =AR24+B25-J25-X25-AL25
A26: =A25+1 | D26: =E25 | E26: 439 | F26: =E26-D26 | P26: =P25+1 | R26: =S25 | S26: 215 | T26: =S26-R26 | AD26: =AD25+1 | AF26: =AG25 | AG26: 68 | AH26: =AG26-AF26 | AR26: =AR25+B26-J26-X26-AL26
A27: =A26+1 | D27: =E26 | E27: 450 | F27: =E27-D27 | J27: 555 | K27: 442 | L27: =K27-K21 | M27: =J27/L27 | P27: =P26+1 | R27: =S26 | S27: 225 | T27: =S27-R27 | AD27: =AD26+1 | AF27: =AG26 | AG27: 70 | AH27: =AG27-AF27 | AR27: =AR26+B27-J27-X27-AL27
A28: =A27+1 | D28: =E27 | E28: 462 | F28: =E28-D28 | P28: =P27+1 | R28: =S27 | S28: 233 | T28: =S28-R28 | AD28: =AD27+1 | AF28: =AG27 | AG28: 73 | AH28: =AG28-AF28 | AR28: =AR27+B28-J28-X28-AL28
A29: =A28+1 | D29: =E28 | E29: 470 | F29: =E29-D29 | P29: =P28+1 | R29: =S28 | S29: 238 | T29: =S29-R29 | AD29: =AD28+1 | AF29: =AG28 | AG29: 73 | AH29: =AG29-AF29 | AR29: =AR28+B29-J29-X29-AL29
A30: =A29+1 | D30: =E29 | E30: 482 | F30: =E30-D30 | P30: =P29+1 | R30: =S29 | S30: 250 | T30: =S30-R30 | X30: 450 | Y30: 240 | Z30: =Y30-Y21 | AA30: =X30/Z30 | AD30: =AD29+1 | AF30: =AG29 | AG30: 75 | AH30: =AG30-AF30 | AR30: =AR29+B30-J30-X30-AL30
A31: =A30+1 | D31: =E30 | E31: 496 | F31: =E31-D31 | J31: 200 | K31: N/F | P31: =P30+1 | R31: =S30 | S31: 265 | T31: =S31-R31 | AD31: =AD30+1 | AF31: =AG30 | AG31: 76 | AH31: =AG31-AF31 | AR31: =AR30+B31-J31-X31-AL31
A32: =A31+1 | D32: =E31 | E32: 507 | F32: =E32-D32 | P32: =P31+1 | R32: =S31 | S32: 275 | T32: =S32-R32 | AD32: =AD31+1 | AF32: =AG31 | AG32: 79 | AH32: =AG32-AF32 | AR32: =AR31+B32-J32-X32-AL32
A33: =A32+1 | D33: =E32 | E33: 520 | F33: =E33-D33 | J33: 550 | K33: 502 | L33: =K33-K27 | M33: =(J33+J31)/L33 | P33: =P32+1 | R33: =S32 | S33: 283 | T33: =S33-R33 | AD33: =AD32+1 | AF33: =AG32 | AG33: 83 | AH33: =AG33-AF33 | AR33: =AR32+B33-J33-X33-AL33
A34: =A33+1 | B34: 1400 | D34: =E33 | E34: 531 | F34: =E34-D34 | P34: =P33+1 | R34: =S33 | S34: 285 | T34: =S34-R34 | AD34: =AD33+1 | AF34: =AG33 | AG34: 87 | AH34: =AG34-AF34 | AR34: =AR33+B34-J34-X34-AL34
A35: =A34+1 | D35: =E34 | E35: 544 | F35: =E35-D35 | J35: 330 | K35: 531 | L35: =K35-K33 | M35: =J35/L35 | P35: =P34+1 | R35: =S34 | S35: 293 | T35: =S35-R35 | X35: 485 | Y35: 286 | Z35: =Y35-Y30 | AA35: =X35/Z35 | AD35: =AD34+1 | AF35: =AG34 | AG35: 90 | AH35: =AG35-AF35 | AR35: =AR34+B35-J35-X35-AL35
A36: =A35+1 | D36: =E35 | E36: 559 | F36: =E36-D36 | P36: =P35+1 | R36: =S35 | S36: 301 | T36: =S36-R36 | AD36: =AD35+1 | AF36: =AG35 | AG36: 95 | AH36: =AG36-AF36 | AL36: 200 | AM36: 91 | AR36: =AR35+B36-J36-X36-AL36
B37: =SUM(B6:B36) | C37: Total | F37: =SUM(F6:F36) | I37: =SUM(I6:I36) | J37: =SUM(J6:J36) | L37: =SUM(L6:L36) | M37: =J37/L37 | Q37: Total | T37: =SUM(T6:T36) | W37: =SUM(W6:W36) | X37: =SUM(X6:X36) | Z37: =SUM(Z6:Z36) | AA37: =X37/Z37 | AE37: Total | AH37: =SUM(AH6:AH36) | AK37: =SUM(AK6:AK36) | AL37: =SUM(AL6:AL36) | AN37: =AM36-AM17 | AO37: =AL37/AN37 | AR37: =AR36
A39: Monthly Hiring Charges | C39: 720000 | P39: Monthly Hiring Charges | R39: 720000 | AD39: Monthly Hiring Charges | AF39: 500000
A40: Per Day Rate/31 | C40: =C39/31 | P40: Per Day Rate/31 | R40: =R39/31 | AD40: Per Day Rate/31 | AF40: =AF39/31
A41: Per Hours Rate | C41: =C40/24 | P41: Per Hours Rate | R41: =R40/24 | AD41: Per Hours Rate | AF41: =AF40/24
...

Sheet Aug26-Update
A1: Ekta Enterprises | P1: Ekta Enterprises | AD1: Ekta Enterprises
A2: REACH STACKER NO. XCMG-2-Diesel Cap - 19 Liters Per Hour | K2: 46235 | P2: REACH STACKER NO. XCMG-1-Diesel Cap - 19 Liters Per Hour | X2: 46235 | AD2: REACH STACKER NO. Fork Lift 35 Ton-Diesel Cap - 17 Liters Per Hour | AL2: 46235
A3: LOCATION : JSW AARKONAM | P3: LOCATION : JSW AARKONAM | AD3: LOCATION : JSW AARKONAM
A4: DATE | B4: DIESEL PURCHASED | C4: ACTIVITY | D4: OPERING HMR | E4: CLOSING HMR | F4: Running Hours | G4: BD START TIME | H4: BD END TIME | I4: BD HOURS | J4: DIESEL | K4: HMR | L4: HOUR | M4: AVERAGE | N4: OPERATOR SIGNATURE | O4: JSW SIGNATURE | P4: DATE | Q4: ACTIVITY | R4: OPERING HMR | S4: CLOSING HMR | T4: Running Hours | U4: BD START TIME | V4: BD END TIME | W4: BD HOURS | X4: DIESEL | Y4: HMR | Z4: HOUR | AA4: AVERAGE | AB4: OPERATOR SIGNATURE | AC4: JSW SIGNATURE | AD4: DATE | AE4: ACTIVITY | AF4: OPERING HMR | AG4: CLOSING HMR | AH4: Running Hours | AI4: BD START TIME | AJ4: BD END TIME | AK4: BD HOURS | AL4: DIESEL | AM4: HMR | AN4: HOUR | AO4: AVERAGE | AP4: OPERATOR SIGNATURE | AQ4: JSW SIGNATURE | AR4: Diesel Balance
K5: 531 | Y5: 286 | AM5: 51 | AR5: 620
A6: 46235 | D6: 559 | E6: 572 | F6: =E6-D6 | P6: 46235 | R6: 301 | S6: 311 | T6: =S6-R6 | AD6: 46235 | AF6: 95 | AG6: 101.9 | AH6: =AG6-AF6 | AR6: =AR5+B6-J6-X6-AL6
A7: =A6+1 | B7: 1800 | D7: =E6 | E7: 588 | F7: =E7-D7 | J7: 275 | K7: 572 | L7: =K7-K5 | M7: =J7/L7 | P7: =P6+1 | R7: =S6 | S7: 323 | T7: =S7-R7 | X7: 500 | Y7: 311 | Z7: =Y7-Y5 | AA7: =X7/Z7 | AD7: =AD6+1 | AF7: =AG6 | AG7: 113.5 | AH7: =AG7-AF7 | AL7: 320 | AM7: 102 | AN7: =AM7-AM5 | AO7: =AL7/AN7 | AR7: =AR6+B7-J7-X7-AL7
A8: =A7+1 | D8: =E7 | E8: 596 | F8: =E8-D8 | P8: =P7+1 | R8: =S7 | S8: 328 | T8: =S8-R8 | AD8: =AD7+1 | AF8: =AG7 | AG8: 119 | AH8: =AG8-AF8 | AR8: =AR7+B8-J8-X8-AL8
A9: =A8+1 | D9: =E8 | E9: 605 | F9: =E9-D9 | P9: =P8+1 | R9: =S8 | S9: 334 | T9: =S9-R9 | AD9: =AD8+1 | AF9: =AG8 | AG9: 124 | AH9: =AG9-AF9 | AR9: =AR8+B9-J9-X9-AL9-AS9 | AS9: 300 | AT9: Diesel filling sany machine in MLPM site
A10: =A9+1 | D10: =E9 | E10: 616 | F10: =E10-D10 | P10: =P9+1 | R10: =S9 | S10: 341 | T10: =S10-R10 | AD10: =AD9+1 | AF10: =AG9 | AG10: 129 | AH10: =AG10-AF10 | AR10: =AR9+B10-J10-X10-AL10-AS10
A11: =A10+1 | D11: =E10 | E11: 624 | F11: =E11-D11 | J11: 400 | P11: =P10+1 | R11: =S10 | S11: 344 | T11: =S11-R11 | X11: 200 | AD11: =AD10+1 | AF11: =AG10 | AG11: 135.5 | AH11: =AG11-AF11 | AL11: 200 | AR11: =AR10+B11-J11-X11-AL11-AS11
A12: =A11+1 | D12: =E11 | E12: 635 | F12: =E12-D12 | P12: =P11+1 | R12: =S11 | S12: 356 | T12: =S12-R12 | AD12: =AD11+1 | AF12: =AG11 | AG12: 145 | AH12: =AG12-AF12 | AR12: =AR11+B12-J12-X12-AL12-AS12
A13: =A12+1 | D13: =E12 | E13: 647 | F13: =E13-D13 | P13: =P12+1 | R13: =S12 | S13: 367 | T13: =S13-R13 | AD13: =AD12+1 | AF13: =AG12 | AG13: 156.9 | AH13: =AG13-AF13 | AR13: =AR12+B13-J13-X13-AL13-AS13
A14: =A13+1 | B14: 1000 | D14: =E13 | E14: 653 | F14: =E14-D14 | P14: =P13+1 | R14: =S13 | S14: 373 | T14: =S14-R14 | AD14: =AD13+1 | AF14: =AG13 | AG14: 158.2 | AH14: =AG14-AF14 | AR14: =AR13+B14-J14-X14-AL14-AS14 | AS14: 200 | AT14: Diesel filling sany machine in MLPM site
A15: =A14+1 | D15: =E14 | E15: 665 | F15: =E15-D15 | J15: 500 | P15: =P14+1 | R15: =S14 | S15: 382 | T15: =S15-R15 | X15: 500 | AD15: =AD14+1 | AF15: =AG14 | AG15: 167.3 | AH15: =AG15-AF15 | AR15: =AR14+B15-J15-X15-AL15-AS15
A16: =A15+1 | B16: 1600 | D16: =E15 | E16: 678 | F16: =E16-D16 | P16: =P15+1 | R16: =S15 | S16: 395 | T16: =S16-R16 | AD16: =AD15+1 | AF16: =AG15 | AG16: 170 | AH16: =AG16-AF16 | AL16: 400 | AR16: =AR15+B16-J16-X16-AL16-AS16
A17: =A16+1 | D17: =E16 | E17: 698 | F17: =E17-D17 | J17: 504 | P17: =P16+1 | R17: =S16 | S17: 411 | T17: =S17-R17 | X17: 462 | AD17: =AD16+1 | AF17: =AG16 | AG17: 178.6 | AH17: =AG17-AF17 | AR17: =AR16+B17-J17-X17-AL17-AS17 | AS17: 250 | AT17: Diesel filling sany machine in MLPM site
A18: =A17+1 | B18: 1200 | D18: =E17 | E18: 705 | F18: =E18-D18 | P18: =P17+1 | R18: =S17 | S18: 420 | T18: =S18-R18 | AD18: =AD17+1 | AF18: =AG17 | AG18: 185.3 | AH18: =AG18-AF18 | AR18: =AR17+B18-J18-X18-AL18-AS18 | AS18: 200 | AT18: Diesel filling sany machine in MLPM site
A19: =A18+1 | D19: =E18 | E19: 705 | F19: =E19-D19 | P19: =P18+1 | R19: =S18 | S19: 420 | T19: =S19-R19 | AD19: =AD18+1 | AF19: =AG18 | AG19: 185.3 | AH19: =AG19-AF19 | AR19: =AR18+B19-J19-X19-AL19-AS19
A20: =A19+1 | D20: =E19 | E20: 720 | F20: =E20-D20 | P20: =P19+1 | R20: =S19 | S20: 436 | T20: =S20-R20 | AD20: =AD19+1 | AF20: =AG19 | AG20: 198.2 | AH20: =AG20-AF20 | AR20: =AR19+B20-J20-X20-AL20-AS20
A21: =A20+1 | D21: =E20 | E21: 736 | F21: =E21-D21 | J21: 462 | K21: 731 | L21: =K21-K7 | M21: =J21/L21 | P21: =P20+1 | R21: =S20 | S21: 448 | T21: =S21-R21 | X21: 414 | Y21: 442 | Z21: =Y21-Y7 | AA21: =X21/Z21 | AD21: =AD20+1 | AF21: =AG20 | AG21: 198.5 | AH21: =AG21-AF21 | AL21: 200 | AM21: 198.4 | AN21: N/F | AR21: =AR20+B21-J21-X21-AL21-AS21
A22: =A21+1 | D22: =E21 | E22: 746 | F22: =E22-D22 | P22: =P21+1 | R22: =S21 | S22: 456 | T22: =S22-R22 | AD22: =AD21+1 | AF22: =AG21 | AG22: 207 | AH22: =AG22-AF22 | AR22: =AR21+B22-J22-X22-AL22-AS22
A23: =A22+1 | D23: =E22 | E23: 755 | F23: =E23-D23 | P23: =P22+1 | R23: =S22 | S23: 467 | T23: =S23-R23 | AD23: =AD22+1 | AF23: =AG22 | AG23: 213 | AH23: =AG23-AF23 | AR23: =AR22+B23-J23-X23-AL23-AS23
A24: =A23+1 | B24: 1400 | D24: =E23 | E24: 770 | F24: =E24-D24 | J24: 462 | K24: 765 | L24: =K24-K21 | M24: =J24/L24 | P24: =P23+1 | R24: =S23 | S24: 480 | T24: =S24-R24 | X24: 462 | Y24: 475 | Z24: =Y24-Y21 | AA24: =X24/Z24 | AD24: =AD23+1 | AF24: =AG23 | AG24: 220.2 | AH24: =AG24-AF24 | AR24: =AR23+B24-J24-X24-AL24-AS24 | AS24: 200 | AT24: Diesel filling sany machine in MLPM site
A25: =A24+1 | D25: =E24 | E25: 781 | F25: =E25-D25 | P25: =P24+1 | R25: =S24 | S25: 491 | T25: =S25-R25 | AD25: =AD24+1 | AF25: =AG24 | AG25: 226.6 | AH25: =AG25-AF25 | AR25: =AR24+B25-J25-X25-AL25-AS25
A26: =A25+1 | B26: 1200 | D26: =E25 | E26: 791 | F26: =E26-D26 | P26: =P25+1 | R26: =S25 | S26: 507 | T26: =S26-R26 | AD26: =AD25+1 | AF26: =AG25 | AG26: 238.5 | AH26: =AG26-AF26 | AL26: 245 | AM26: 226.5 | AN26: N/F | AR26: =AR25+B26-J26-X26-AL26-AS26
A27: =A26+1 | D27: =E26 | E27: 803 | F27: =E27-D27 | P27: =P26+1 | R27: =S26 | S27: 520 | T27: =S27-R27 | X27: 420 | Y27: 514 | Z27: =Y27-Y24 | AA27: =X27/Z27 | AD27: =AD26+1 | AF27: =AG26 | AG27: 249.5 | AH27: =AG27-AF27 | AR27: =AR26+B27-J27-X27-AL27-AS27 | AS27: =250+10+10 | AT27: Diesel filling sany machine in MLPM site and 2 trailar 5200 , 1376
A28: =A27+1 | D28: =E27 | E28: 815 | F28: =E28-D28 | J28: 435 | K28: 805 | L28: =K28-K24 | M28: =J28/L28 | P28: =P27+1 | R28: =S27 | S28: 525 | T28: =S28-R28 | AD28: =AD27+1 | AF28: =AG27 | AG28: 256.3 | AH28: =AG28-AF28 | AL28: 85 | AR28: =AR27+B28-J28-X28-AL28-AS28 | AS28: 50 | AT28: Diesel filling sany machine in MLPM site
A29: =A28+1 | B29: 1500 | D29: =E28 | E29: 824 | F29: =E29-D29 | P29: =P28+1 | R29: =S28 | S29: 535 | T29: =S29-R29 | AD29: =AD28+1 | AF29: =AG28 | AG29: 264.3 | AH29: =AG29-AF29 | AL29: 340 | AM29: 258.2 | AN29: =AM29-AM26 | AO29: =(AL29+AL28)/AN29 | AR29: =AR28+B29-J29-X29-AL29-AS29 | AS29: 300 | AT29: Diesel filling sany machine in MLPM site
A30: =A29+1 | D30: =E29 | E30: 835 | F30: =E30-D30 | P30: =P29+1 | R30: =S29 | S30: 548 | T30: =S30-R30 | AD30: =AD29+1 | AF30: =AG29 | AG30: 275.1 | AH30: =AG30-AF30 | AR30: =AR29+B30-J30-X30-AL30-AS30
A31: =A30+1 | B31: 1600 | D31: =E30 | E31: 844 | F31: =E31-D31 | J31: 365 | K31: 836 | L31: N/F | P31: =P30+1 | R31: =S30 | S31: 555 | T31: =S31-R31 | X31: 495 | Y31: 549 | Z31: =Y31-Y27 | AA31: =X31/Z31 | AD31: =AD30+1 | AF31: =AG30 | AG31: 280 | AH31: =AG31-AF31 | AR31: =AR30+B31-J31-X31-AL31-AS31 | AS31: 400 | AT31: Diesel filling sany machine in MLPM site
A32: =A31+1 | D32: =E31 | E32: 860 | F32: =E32-D32 | P32: =P31+1 | R32: =S31 | S32: 564 | T32: =S32-R32 | AD32: =AD31+1 | AF32: =AG31 | AG32: 288.7 | AH32: =AG32-AF32 | AR32: =AR31+B32-J32-X32-AL32-AS32
A33: =A32+1 | D33: =E32 | E33: 873 | F33: =E33-D33 | P33: =P32+1 | R33: =S32 | S33: 574 | T33: =S33-R33 | AD33: =AD32+1 | AF33: =AG32 | AG33: 298 | AH33: =AG33-AF33 | AR33: =AR32+B33-J33-X33-AL33-AS33
A34: =A33+1 | D34: =E33 | E34: 888 | F34: =E34-D34 | J34: 400 | K34: 873 | L34: =K34-K28 | M34: =(J34+J28)/L34 | P34: =P33+1 | R34: =S33 | S34: 584 | T34: =S34-R34 | AD34: =AD33+1 | AF34: =AG33 | AG34: 304.1 | AH34: =AG34-AF34 | AL34: 200 | AM34: 298.1 | AN34: N/F | AR34: =AR33+B34-J34-X34-AL34-AS34
A35: =A34+1 | B35: 1600 | D35: =E34 | E35: 894 | F35: =E35-D35 | P35: =P34+1 | R35: =S34 | S35: 593 | T35: =S35-R35 | X35: 425 | Y35: 585 | Z35: =Y35-Y31 | AA35: =X35/Z35 | AD35: =AD34+1 | AF35: =AG34 | AG35: 307.9 | AH35: =AG35-AF35 | AR35: =AR34+B35-J35-X35-AL35-AS35
A36: =A35+1 | D36: =E35 | E36: 901 | F36: =E36-D36 | P36: =P35+1 | R36: =S35 | S36: 601 | T36: =S36-R36 | AD36: =AD35+1 | AF36: =AG35 | AG36: 310.1 | AH36: =AG36-AF36 | AR36: =AR35+B36-J36-X36-AL36-AS36 | AS36: 400 | AT36: Diesel filling sany machine in MLPM site
B37: =SUM(B6:B36) | C37: Total | F37: =SUM(F6:F36) | I37: =SUM(I6:I36) | J37: =SUM(J6:J36) | L37: =SUM(L6:L36) | M37: =J37/L37 | Q37: Total | T37: =SUM(T6:T36) | W37: =SUM(W6:W36) | X37: =SUM(X6:X36) | Z37: =SUM(Z6:Z36) | AA37: =X37/Z37 | AE37: Total | AH37: =SUM(AH6:AH36) | AK37: =SUM(AK6:AK36) | AL37: =SUM(AL6:AL36) | AN37: =SUM(AN6:AN36) | AO37: =AL37/AN37 | AR37: =AR36 | AU37: 1285 | AV37: =AR37-AU37
AR38: 1300 | AS38: DIESEL STOCK
D39: Raise Tax invoice with full hiring charges | R39: Raise Tax invoice with full hiring charges | AE39: Raise Tax invoice with full hiring charges | AR39: =AR37-AR38
D40: Raise Diesel reimbursment as per below calculation | R40: Raise Diesel reimbursment as per below calculation | AE40: Raise Diesel reimbursment as per below calculation | AQ40: 1200
...

Sheet Sep26-Update
A1: Ekta Enterprises | P1: Ekta Enterprises | AC1: Ekta Enterprises
A2: REACH STACKER NO. XCMG-2-Diesel Cap - 19 Liters Per Hour | K2: 46266 | P2: REACH STACKER NO. XCMG-1-Diesel Cap - 19 Liters Per Hour | W2: 46266 | AC2: REACH STACKER NO. Fork Lift 35 Ton-Diesel Cap - 17 Liters Per Hour | AJ2: 46266
A3: LOCATION : JSW AARKONAM | P3: LOCATION : JSW AARKONAM | AC3: LOCATION : JSW AARKONAM
A4: Date | B4: Diesel Received (Ltr) | C4: ACTIVITY | D4: OPERING HMR | E4: Closing HMR | F4: Total (Hrs) | G4: Breakdown Start Time | H4: Breakdown End Time | I4: Breakdown Hours | J4: Diesel Issued (Ltr) | K4: HMR at Diesel Fill | L4: HOUR | M4: Avg. Diesel Consumption (Ltr/Hr) | N4: OPERATOR SIGNATURE | O4: JSW SIGNATURE | P4: Date | Q4: ACTIVITY | R4: OPERING HMR | S4: Closing HMR | T4: Total (Hrs) | U4: Breakdown Start Time | V4: Breakdown End Time | W4: Breakdown Hours | X4: Diesel Issued (Ltr) | Y4: HMR at Diesel Fill | Z4: HOUR | AA4: Avg. Diesel Consumption (Ltr/Hr) | AB4: OPERATOR SIGNATURE | AC4: Date | AD4: ACTIVITY | AE4: OPERING HMR | AF4: Closing HMR | AG4: Total (Hrs) | AH4: Breakdown Start Time | AI4: Breakdown End Time | AJ4: Breakdown Hours | AK4: Diesel Issued (Ltr) | AL4: HMR at Diesel Fill | AM4: HOUR | AN4: Avg. Diesel Consumption (Ltr/Hr) | AO4: OPERATOR SIGNATURE | AP4: JSW SIGNATURE
K5: 873 | Y5: 549 | AL5: 298.1 | AP5: 2104
A6: 46266 | D6: 901 | E6: 909 | F6: =IF(OR(D6="",E6=""),"",E6-D6) | P6: 46266 | R6: ='Aug26-Update'!T36 | S6: 613 | T6: =IF(OR(R6="",S6=""),"",S6-R6) | AC6: 46266 | AE6: 310.1 | AF6: 314 | AG6: =IF(OR(AE6="",AF6=""),"",AF6-AE6) | AP6: =AP5+B6-AK6-X6-J6
A7: 46267 | D7: =IF(E6="","",E6) | E7: 923 | F7: =IF(OR(D7="",E7=""),"",E7-D7) | J7: 475 | K7: 909 | L7: =IF(OR(J7="",K7=""),"",IFERROR(K7-K5,"")) | M7: =IF(OR(J7="",K7=""),"",IFERROR(J7/L7,"")) | P7: 46267 | R7: =IF(S6="","",S6) | S7: 630 | T7: =IF(OR(R7="",S7=""),"",S7-R7) | X7: 280 | Y7: 613 | Z7: =Y7-Y5 | AA7: =IF(OR(X7="",Y7=""),"",IFERROR(X7/Z7,"")) | AC7: 46267 | AE7: =IF(AF6="","",AF6) | AF7: 323.1 | AG7: =IF(OR(AE7="",AF7=""),"",AF7-AE7) | AM7: =IF(OR(AK7="",AL7=""),"",IFERROR(AL7-AL5,"")) | AN7: =IF(OR(AK7="",AL7=""),"",IFERROR(AK7/AM7,"")) | AP7: =AP6+B7-AK7-X7-J7
A8: 46268 | B8: 1200 | D8: =IF(E7="","",E7) | E8: 941 | F8: =IF(OR(D8="",E8=""),"",E8-D8) | P8: 46268 | R8: =IF(S7="","",S7) | S8: 647 | T8: =IF(OR(R8="",S8=""),"",S8-R8) | AC8: 46268 | AE8: =IF(AF7="","",AF7) | AF8: 328.2 | AG8: =IF(OR(AE8="",AF8=""),"",AF8-AE8) | AP8: =AP7+B8-AK8-X8-J8
A9: 46269 | D9: =IF(E8="","",E8) | E9: 960 | F9: =IF(OR(D9="",E9=""),"",E9-D9) | J9: 385 | K9: 942 | L9: =K9-K7 | M9: =J9/L9 | P9: 46269 | R9: =IF(S8="","",S8) | S9: 661 | T9: =IF(OR(R9="",S9=""),"",S9-R9) | AC9: 46269 | AE9: =IF(AF8="","",AF8) | AF9: 332.4 | AG9: =IF(OR(AE9="",AF9=""),"",AF9-AE9) | AP9: =AP8+B9-AK9-X9-J9
A10: 46270 | B10: 1200 | D10: =IF(E9="","",E9) | E10: 982 | F10: =IF(OR(D10="",E10=""),"",E10-D10) | J10: 400 | K10: N/F | P10: 46270 | R10: =IF(S9="","",S9) | S10: 681 | T10: =IF(OR(R10="",S10=""),"",S10-R10) | AC10: 46270 | AE10: =IF(AF9="","",AF9) | AF10: 349.4 | AG10: =IF(OR(AE10="",AF10=""),"",AF10-AE10) | AP10: =AP9+B10-AK10-X10-J10
A11: 46271 | D11: =IF(E10="","",E10) | E11: 996 | F11: =IF(OR(D11="",E11=""),"",E11-D11) | P11: 46271 | R11: =IF(S10="","",S10) | S11: 693 | T11: =IF(OR(R11="",S11=""),"",S11-R11) | AC11: 46271 | AE11: =IF(AF10="","",AF10) | AF11: 357.3 | AG11: =IF(OR(AE11="",AF11=""),"",AF11-AE11) | AK11: 400 | AL11: 355.2 | AM11: =AL11-AL5 | AN11: =AK11/AM11 | AP11: =AP10+B11-AK11-X11-J11
A12: 46272 | B12: 600 | D12: =IF(E11="","",E11) | E12: 1005 | F12: =IF(OR(D12="",E12=""),"",E12-D12) | J12: 355 | K12: 997 | L12: =K12-K9 | M12: =(J12+J10)/L12 | P12: 46272 | R12: =IF(S11="","",S11) | S12: 702 | T12: =IF(OR(R12="",S12=""),"",S12-R12) | X12: 510 | Y12: 699 | Z12: =Y12-X7 | AA12: =X12/Z12 | AC12: 46272 | AE12: =IF(AF11="","",AF11) | AF12: 362.6 | AG12: =IF(OR(AE12="",AF12=""),"",AF12-AE12) | AP12: =AP11+B12-AK12-X12-J12
A13: 46273 | D13: =IF(E12="","",E12) | E13: 1015 | F13: =IF(OR(D13="",E13=""),"",E13-D13) | P13: 46273 | R13: =IF(S12="","",S12) | S13: 710 | T13: =IF(OR(R13="",S13=""),"",S13-R13) | AC13: 46273 | AE13: =IF(AF12="","",AF12) | AF13: 369.9 | AG13: =IF(OR(AE13="",AF13=""),"",AF13-AE13) | AP13: =AP12+B13-AK13-X13-J13
A14: 46274 | D14: =IF(E13="","",E13) | E14: 1027 | F14: =IF(OR(D14="",E14=""),"",E14-D14) | P14: 46274 | R14: =IF(S13="","",S13) | S14: 715 | T14: =IF(OR(R14="",S14=""),"",S14-R14) | AC14: 46274 | AE14: =IF(AF13="","",AF13) | AF14: 379.4 | AG14: =IF(OR(AE14="",AF14=""),"",AF14-AE14) | AP14: =AP13+B14-AK14-X14-J14
A15: 46275 | B15: 800 | D15: =IF(E14="","",E14) | E15: 1036 | F15: =IF(OR(D15="",E15=""),"",E15-D15) | J15: 382 | K15: 1031 | L15: =K15-K12 | M15: =J15/L15 | P15: 46275 | R15: =IF(S14="","",S14) | S15: 721 | T15: =IF(OR(R15="",S15=""),"",S15-R15) | AC15: 46275 | AE15: =IF(AF14="","",AF14) | AF15: 386.4 | AG15: =IF(OR(AE15="",AF15=""),"",AF15-AE15) | AP15: =AP14+B15-AK15-X15-J15
A16: 46276 | D16: =IF(E15="","",E15) | E16: 1046 | F16: =IF(OR(D16="",E16=""),"",E16-D16) | P16: 46276 | R16: =IF(S15="","",S15) | S16: 731 | T16: =IF(OR(R16="",S16=""),"",S16-R16) | AC16: 46276 | AE16: =IF(AF15="","",AF15) | AF16: 392.7 | AG16: =IF(OR(AE16="",AF16=""),"",AF16-AE16) | AP16: =AP15+B16-AK16-X16-J16
A17: 46277 | D17: =IF(E16="","",E16) | E17: 1054 | F17: =IF(OR(D17="",E17=""),"",E17-D17) | P17: 46277 | R17: =IF(S16="","",S16) | S17: 739 | T17: =IF(OR(R17="",S17=""),"",S17-R17) | AC17: 46277 | AE17: =IF(AF16="","",AF16) | AF17: 398.6 | AG17: =IF(OR(AE17="",AF17=""),"",AF17-AE17) | AK17: 313 | AL17: ? | AP17: =AP16+B17-AK17-X17-J17
A18: 46278 | D18: =IF(E17="","",E17) | E18: 1057 | F18: =IF(OR(D18="",E18=""),"",E18-D18) | P18: 46278 | R18: =IF(S17="","",S17) | S18: 742 | T18: =IF(OR(R18="",S18=""),"",S18-R18) | AC18: 46278 | AE18: =IF(AF17="","",AF17) | AF18: 401.5 | AG18: =IF(OR(AE18="",AF18=""),"",AF18-AE18) | AP18: =AP17+B18-AK18-X18-J18
A19: 46279 | D19: =IF(E18="","",E18) | E19: 1068 | F19: =IF(OR(D19="",E19=""),"",E19-D19) | J19: 192.01 | K19: 1060 | L19: =K19-K15 | M19: =J19/L19 | P19: 46279 | R19: =IF(S18="","",S18) | S19: 745 | T19: =IF(OR(R19="",S19=""),"",S19-R19) | X19: 120 | Y19: 743 | Z19: =Y19-Y12 | AA19: =X19/Z19 | AC19: 46279 | AE19: =IF(AF18="","",AF18) | AF19: 403 | AG19: =IF(OR(AE19="",AF19=""),"",AF19-AE19) | AP19: =AP18+B19-AK19-X19-J19
A20: 46280 | B20: 902 | D20: =IF(E19="","",E19) | E20: 1075 | F20: =IF(OR(D20="",E20=""),"",E20-D20) | P20: 46280 | R20: =IF(S19="","",S19) | S20: 753 | T20: =IF(OR(R20="",S20=""),"",S20-R20) | AC20: 46280 | AE20: =IF(AF19="","",AF19) | AF20: 407 | AG20: =IF(OR(AE20="",AF20=""),"",AF20-AE20) | AP20: =AP19+B20-AK20-X20-J20
A21: 46281 | D21: =IF(E20="","",E20) | E21: 1084 | F21: =IF(OR(D21="",E21=""),"",E21-D21) | L21: =IF(OR(J21="",K21=""),"",IFERROR(K21-K7,"")) | M21: =IF(OR(J21="",K21=""),"",IFERROR(J21/L21,"")) | P21: 46281 | R21: =IF(S20="","",S20) | S21: 756 | T21: =IF(OR(R21="",S21=""),"",S21-R21) | Z21: =IF(OR(X21="",Y21=""),"",IFERROR(Y21-Y7,"")) | AA21: =IF(OR(X21="",Y21=""),"",IFERROR(X21/Z21,"")) | AC21: 46281 | AE21: =IF(AF20="","",AF20) | AF21: 413.3 | AG21: =IF(OR(AE21="",AF21=""),"",AF21-AE21) | AP21: =AP20+B21-AK21-X21-J21
A22: 46282 | D22: =IF(E21="","",E21) | E22: 1098 | F22: =IF(OR(D22="",E22=""),"",E22-D22) | P22: 46282 | R22: =IF(S21="","",S21) | S22: 764 | T22: =IF(OR(R22="",S22=""),"",S22-R22) | AC22: 46282 | AE22: =IF(AF21="","",AF21) | AF22: 424.1 | AG22: =IF(OR(AE22="",AF22=""),"",AF22-AE22) | AP22: =AP21+B22-AK22-X22-J22
A23: 46283 | D23: =IF(E22="","",E22) | E23: 1111 | F23: =IF(OR(D23="",E23=""),"",E23-D23) | J23: 500 | K23: 1100 | P23: 46283 | R23: =IF(S22="","",S22) | S23: 770 | T23: =IF(OR(R23="",S23=""),"",S23-R23) | Z23: =IF(OR(X23="",Y23=""),"",IFERROR(Y23-Y20,"")) | AA23: =IF(OR(X23="",Y23=""),"",IFERROR(X23/Z23,"")) | AC23: 46283 | AE23: =IF(AF22="","",AF22) | AF23: 427 | AG23: =IF(OR(AE23="",AF23=""),"",AF23-AE23) | AP23: =AP22+B23-AK23-X23-J23
A24: 46284 | D24: =IF(E23="","",E23) | E24: 1118 | F24: =IF(OR(D24="",E24=""),"",E24-D24) | L24: =IF(OR(J24="",K24=""),"",IFERROR(K24-K21,"")) | M24: =IF(OR(J24="",K24=""),"",IFERROR(J24/L24,"")) | P24: 46284 | R24: =IF(S23="","",S23) | S24: 780 | T24: =IF(OR(R24="",S24=""),"",S24-R24) | Z24: =IF(OR(X24="",Y24=""),"",IFERROR(Y24-Y21,"")) | AA24: =IF(OR(X24="",Y24=""),"",IFERROR(X24/Z24,"")) | AC24: 46284 | AE24: =IF(AF23="","",AF23) | AG24: =IF(OR(AE24="",AF24=""),"",AF24-AE24) | AP24: =AP23+B24-AK24-X24-J24
A25: 46285 | D25: =IF(E24="","",E24) | F25: =IF(OR(D25="",E25=""),"",E25-D25) | P25: 46285 | R25: =IF(S24="","",S24) | T25: =IF(OR(R25="",S25=""),"",S25-R25) | AC25: 46285 | AE25: =IF(AF24="","",AF24) | AG25: =IF(OR(AE25="",AF25=""),"",AF25-AE25) | AP25: =AP24+B25-AK25-X25-J25
A26: 46286 | D26: =IF(E25="","",E25) | E26: 1134 | F26: =IF(OR(D26="",E26=""),"",E26-D26) | P26: 46286 | R26: =IF(S25="","",S25) | T26: =IF(OR(R26="",S26=""),"",S26-R26) | AC26: 46286 | AE26: =IF(AF25="","",AF25) | AF26: 439.9 | AG26: =IF(OR(AE26="",AF26=""),"",AF26-AE26) | AP26: =AP25+B26-AK26-X26-J26
A27: 46287 | D27: =IF(E26="","",E26) | E27: 1143 | F27: =IF(OR(D27="",E27=""),"",E27-D27) | G27: 10 | H27: 10 | J27: 222 | K27: 1135 | P27: 46287 | R27: =IF(S26="","",S26) | S27: 793 | T27: =IF(OR(R27="",S27=""),"",S27-R27) | U27: 10 | V27: 10 | X27: 80 | Y27: 789 | Z27: =IF(OR(X27="",Y27=""),"",IFERROR(Y27-Y24,"")) | AA27: =IF(OR(X27="",Y27=""),"",IFERROR(X27/Z27,"")) | AC27: 46287 | AE27: =IF(AF26="","",AF26) | AF27: 444.5 | AG27: =IF(OR(AE27="",AF27=""),"",AF27-AE27) | AH27: 10 | AI27: 10 | AP27: =AP26+B27-AK27-X27-J27
A28: 46288 | D28: =IF(E27="","",E27) | F28: =IF(OR(D28="",E28=""),"",E28-D28) | L28: =IF(OR(J28="",K28=""),"",IFERROR(K28-K24,"")) | M28: =IF(OR(J28="",K28=""),"",IFERROR(J28/L28,"")) | P28: 46288 | R28: =IF(S27="","",S27) | T28: =IF(OR(R28="",S28=""),"",S28-R28) | AC28: 46288 | AE28: =IF(AF27="","",AF27) | AG28: =IF(OR(AE28="",AF28=""),"",AF28-AE28) | AP28: =AP27+B28-AK28-X28-J28
A29: 46289 | D29: =IF(E28="","",E28) | E29: 1155 | F29: =IF(OR(D29="",E29=""),"",E29-D29) | P29: 46289 | R29: =IF(S28="","",S28) | S29: 803 | T29: =IF(OR(R29="",S29=""),"",S29-R29) | AC29: 46289 | AE29: =IF(AF28="","",AF28) | AF29: 453.1 | AG29: =IF(OR(AE29="",AF29=""),"",AF29-AE29) | AN29: =IF(OR(AK29="",AL29=""),"",IFERROR((AK29+AK28)/AM29,"")) | AP29: =AP28+B29-AK29-X29-J29
A30: 46290 | D30: =IF(E29="","",E29) | F30: =IF(OR(D30="",E30=""),"",E30-D30) | P30: 46290 | R30: =IF(S29="","",S29) | T30: =IF(OR(R30="",S30=""),"",S30-R30) | AC30: 46290 | AE30: =IF(AF29="","",AF29) | AG30: =IF(OR(AE30="",AF30=""),"",AF30-AE30) | AP30: =AP29+B30-AK30-X30-J30
