Workbook

Sheet PO
A1: BMCT WO
A3: Work Order Date | B3: 46105
A4: WO No. | B4: PMUMB/2026/OPS/WO-01
A5: Client | B5: Bharat Mumbai Container Terminals Pvt. Ltd. (BMCT) / PSA Mumbai
A6: Service Provider | B6: M/s. Ekta Enterprises
A7: Vendor Address | B7: A-19, Vidyut Nagar, Prince Road, Vaishali Nagar, Jaipur, Rajasthan, Pin 302021
A8: Vendor Mobile | B8: +91 97854 81867
A9: Vendor Email | B9: vikasjain@ektaenterprises.net
A10: Kind Attention | B10: Mr. Vikas Jain
A11: Subject | B11: Provide Two (2) New Reachstacker (RS) services to Bharat Mumbai Container Terminals Private Limited (BMCT)
A12: Reference | B12: BMCT RFQ through email dated 23.03.2026; final quote through email dated 23.03.2026
A13: Scope | B13: Provide 2 new RS on monthly rental basis with trained, experienced operators on 24x7, 365 days basis to BMCT for handling 20'/40' empty/ laden containers in BMCT container yard.
A14: Quantity | B14: 2 nos. new Reachstackers
A15: Make | B15: XCMG / SANY / HYSTER
... A28: Accommodation | B28: L&T will try to provide bachelor accommodation; otherwise reimbursable up to ₹1,500/person/month

Sheet Sheet1
A1: SANY RST-8 DAILY EQUIPMENT REPORT - AUG-26 | K1: OPERATORS DUTY SHIFT RECORD | O1: SANY RST-9 DAILY EQUIPMENT REPORT - AUG-26 | Y1: OPERATORS DUTY SHIFT RECORD
A2: Date | B2: SHIFT | C2: HMR START | D2: HMR END | E2: TOTAL HMR | F2: CC NO START | G2: CC NO END | H2: TOTAL CC NO | I2: FUEL FILL BY BMCT | J2: COOLING PERIOD | K2: DAY | L2: NIGHT | M2: Remarks | O2: Date | P2: SHIFT | Q2: HMR START | R2: HMR END | S2: TOTAL HMR | T2: CC NO START | U2: CC NO END | V2: TOTAL CC NO | W2: FUEL FILL BY BMCT | X2: COOLING PERIOD | Y2: DAY | Z2: NIGHT | AA2: Remarks
A3: 46235 | B3: DAY | C3: ='Aug-26'!C4 | D3: ='Aug-26'!D4 | E3: =D3-C3 | F3: ='Aug-26'!N4 | G3: ='Aug-26'!O4 | H3: =G3-F3 | I3: 270 | J3: 1 Hrs | K3: Pankaj Choudhary | L3: Kanhaiya Lal | O3: 46235 | P3: DAY | Q3: ='Aug-26'!T4 | R3: ='Aug-26'!U4 | S3: =R3-Q3 | T3: ='Aug-26'!AE4 | U3: ='Aug-26'!AF4 | V3: =U3-T3 | W3: 200 | X3: 1 Hrs | Y3: Aman Gupta | Z3: Rajkumar
B4: NIGHT | C4: =D3 | D4: ='Aug-26'!D5 | E4: =D4-C4 | F4: =G3 | G4: ='Aug-26'!O5 | H4: =G4-F4 | P4: NIGHT | Q4: =R3 | R4: ='Aug-26'!U5 | S4: =R4-Q4 | T4: =U3 | U4: ='Aug-26'!AF5 | V4: =U4-T4
A5: =A3+1 | B5: DAY | C5: =D4 | D5: ='Aug-26'!D6 | E5: =D5-C5 | F5: =G4 | G5: ='Aug-26'!O6 | H5: =G5-F5 | I5: 240 | J5: 1 Hrs | K5: Pankaj Choudhary | L5: Kanhaiya Lal | O5: =O3+1 | P5: DAY | Q5: =R4 | R5: ='Aug-26'!U6 | S5: =R5-Q5 | T5: =U4 | U5: ='Aug-26'!AF6 | V5: =U5-T5 | W5: 230 | X5: 1 Hrs | Y5: Aman Gupta | Z5: Nazeer Choudhary
B6: NIGHT | C6: =D5 | D6: ='Aug-26'!D7 | E6: =D6-C6 | F6: =G5 | G6: ='Aug-26'!O7 | H6: =G6-F6 | P6: NIGHT | Q6: =R5 | R6: ='Aug-26'!U7 | S6: =R6-Q6 | T6: =U5 | U6: ='Aug-26'!AF7 | V6: =U6-T6
A7: =A5+1 | B7: DAY | C7: =D6 | D7: ='Aug-26'!D8 | E7: =D7-C7 | F7: =G6 | G7: ='Aug-26'!O8 | H7: =G7-F7 | I7: 230 | J7: 1 Hrs | K7: Pankaj Choudhary | L7: Kanhaiya Lal | O7: =O5+1 | P7: DAY | Q7: =R6 | R7: ='Aug-26'!U8 | S7: =R7-Q7 | T7: =U6 | U7: ='Aug-26'!AF8 | V7: =U7-T7 | W7: 250 | X7: 1 Hrs | Y7: Rajkumar | Z7: Nazeer Choudhary
B8: NIGHT | C8: =D7 | D8: ='Aug-26'!D9 | E8: =D8-C8 | F8: =G7 | G8: ='Aug-26'!O9 | H8: =G8-F8 | P8: NIGHT | Q8: =R7 | R8: ='Aug-26'!U9 | S8: =R8-Q8 | T8: =U7 | U8: ='Aug-26'!AF9 | V8: =U8-T8
A9: =A7+1 | B9: DAY | C9: =D8 | D9: ='Aug-26'!D10 | E9: =D9-C9 | F9: =G8 | G9: ='Aug-26'!O10 | H9: =G9-F9 | I9: 230 | J9: 1 Hrs | K9: Pankaj Choudhary | L9: Kanhaiya Lal | O9: =O7+1 | P9: DAY | Q9: =R8 | R9: ='Aug-26'!U10 | S9: =R9-Q9 | T9: =U8 | U9: ='Aug-26'!AF10 | V9: =U9-T9 | W9: 250 | X9: 1 Hrs | Y9: Rajkumar | Z9: Aman Gupta
B10: NIGHT | C10: =D9 | D10: ='Aug-26'!D11 | E10: =D10-C10 | F10: =G9 | G10: ='Aug-26'!O11 | H10: =G10-F10 | P10: NIGHT | Q10: =R9 | R10: ='Aug-26'!U11 | S10: =R10-Q10 | T10: =U9 | U10: ='Aug-26'!AF11 | V10: =U10-T10
A11: =A9+1 | B11: DAY | C11: =D10 | D11: ='Aug-26'!D12 | E11: =D11-C11 | F11: =G10 | G11: ='Aug-26'!O12 | H11: =G11-F11 | I11: 270 | J11: 1 Hrs | K11: Nazeer Choudhary | L11: Pankaj Choudhary | O11: =O9+1 | P11: DAY | Q11: =R10 | R11: ='Aug-26'!U12 | S11: =R11-Q11 | T11: =U10 | U11: ='Aug-26'!AF12 | V11: =U11-T11 | W11: 250 | X11: 1 Hrs | Y11: Rajkumar | Z11: Aman Gupta
B12: NIGHT | C12: =D11 | D12: ='Aug-26'!D13 | E12: =D12-C12 | F12: =G11 | G12: ='Aug-26'!O13 | H12: =G12-F12 | P12: NIGHT | Q12: =R11 | R12: ='Aug-26'!U13 | S12: =R12-Q12 | T12: =U11 | U12: ='Aug-26'!AF13 | V12: =U12-T12
A13: =A11+1 | B13: DAY | C13: =D12 | D13: ='Aug-26'!D14 | E13: =D13-C13 | F13: =G12 | G13: ='Aug-26'!O14 | H13: =G13-F13 | I13: 150 | J13: 1 Hrs | K13: Kanhaiya Lal | L13: Pankaj Choudhary | O13: =O11+1 | P13: DAY | Q13: =R12 | R13: ='Aug-26'!U14 | S13: =R13-Q13 | T13: =U12 | U13: ='Aug-26'!AF14 | V13: =U13-T13 | W13: 200 | X13: 1 Hrs | Y13: Nazeer Choudhary | Z13: Aman Gupta
B14: NIGHT | C14: =D13 | D14: ='Aug-26'!D15 | E14: =D14-C14 | F14: =G13 | G14: ='Aug-26'!O15 | H14: =G14-F14 | P14: NIGHT | Q14: =R13 | R14: ='Aug-26'!U15 | S14: =R14-Q14 | T14: =U13 | U14: ='Aug-26'!AF15 | V14: =U14-T14
A15: =A13+1 | B15: DAY | C15: =D14 | D15: ='Aug-26'!D16 | E15: =D15-C15 | F15: =G14 | G15: ='Aug-26'!O16 | H15: =G15-F15 | I15: 250 | J15: 1 Hrs | K15: Kanhaiya Lal | L15: Pankaj Choudhary | O15: =O13+1 | P15: DAY | Q15: =R14 | R15: ='Aug-26'!U16 | S15: =R15-Q15 | T15: =U14 | U15: ='Aug-26'!AF16 | V15: =U15-T15 | W15: 200 | X15: 1 Hrs | Y15: Nazeer Choudhary | Z15: Rajkumar
B16: NIGHT | C16: =D15 | D16: ='Aug-26'!D17 | E16: =D16-C16 | F16: =G15 | G16: ='Aug-26'!O17 | H16: =G16-F16 | P16: NIGHT | Q16: =R15 | R16: ='Aug-26'!U17 | S16: =R16-Q16 | T16: =U15 | U16: ='Aug-26'!AF17 | V16: =U16-T16
A17: =A15+1 | B17: DAY | C17: =D16 | D17: ='Aug-26'!D18 | E17: =D17-C17 | F17: =G16 | G17: ='Aug-26'!O18 | H17: =G17-F17 | I17: 230 | J17: 1 Hrs | K17: Kanhaiya Lal | L17: Pankaj Choudhary | O17: =O15+1 | P17: DAY | Q17: =R16 | R17: ='Aug-26'!U18 | S17: =R17-Q17 | T17: =U16 | U17: ='Aug-26'!AF18 | V17: =U17-T17 | W17: 170 | X17: 1 Hrs | Y17: Aman Gupta | Z17: Rajkumar
B18: NIGHT | C18: =D17 | D18: ='Aug-26'!D19 | E18: =D18-C18 | F18: =G17 | G18: ='Aug-26'!O19 | H18: =G18-F18 | P18: NIGHT | Q18: =R17 | R18: ='Aug-26'!U19 | S18: =R18-Q18 | T18: =U17 | U18: ='Aug-26'!AF19 | V18: =U18-T18
A19: =A17+1 | B19: DAY | C19: =D18 | D19: ='Aug-26'!D20 | E19: =D19-C19 | F19: =G18 | G19: ='Aug-26'!O20 | H19: =G19-F19 | I19: 200 | J19: 1 Hrs | K19: Kanhaiya Lal | L19: Nazeer Choudhary | O19: =O17+1 | P19: DAY | Q19: =R18 | R19: ='Aug-26'!U20 | S19: =R19-Q19 | T19: =U18 | U19: ='Aug-26'!AF20 | V19: =U19-T19 | W19: 230 | X19: 1 Hrs | Y19: Aman Gupta | Z19: Rajkumar
B20: NIGHT | C20: =D19 | D20: ='Aug-26'!D21 | E20: =D20-C20 | F20: =G19 | G20: ='Aug-26'!O21 | H20: =G20-F20 | P20: NIGHT | Q20: =R19 | R20: ='Aug-26'!U21 | S20: =R20-Q20 | T20: =U19 | U20: ='Aug-26'!AF21 | V20: =U20-T20
A21: =A19+1 | B21: DAY | C21: =D20 | D21: ='Aug-26'!D22 | E21: =D21-C21 | F21: =G20 | G21: ='Aug-26'!O22 | H21: =G21-F21 | I21: 340 | J21: 1 Hrs | K21: Pankaj Choudhary | L21: Nazeer Choudhary | O21: =O19+1 | P21: DAY | Q21: =R20 | R21: ='Aug-26'!U22 | S21: =R21-Q21 | T21: =U20 | U21: ='Aug-26'!AF22 | V21: =U21-T21 | W21: 350 | X21: 1 Hrs | Y21: Aman Gupta | Z21: Rajkumar
B22: NIGHT | C22: =D21 | D22: ='Aug-26'!D23 | E22: =D22-C22 | F22: =G21 | G22: ='Aug-26'!O23 | H22: =G22-F22 | P22: NIGHT | Q22: =R21 | R22: ='Aug-26'!U23 | S22: =R22-Q22 | T22: =U21 | U22: ='Aug-26'!AF23 | V22: =U22-T22
A23: =A21+1 | B23: DAY | C23: =D22 | D23: ='Aug-26'!D24 | E23: =D23-C23 | F23: =G22 | G23: ='Aug-26'!O24 | H23: =G23-F23 | I23: 240 | J23: 1 Hrs | K23: Pankaj Choudhary | L23: Nazeer Choudhary | O23: =O21+1 | P23: DAY | Q23: =R22 | R23: ='Aug-26'!U24 | S23: =R23-Q23 | T23: =U22 | U23: ='Aug-26'!AF24 | V23: =U23-T23 | W23: 260 | X23: 1 Hrs | Y23: Aman Gupta | Z23: Nazeer Choudhary
B24: NIGHT | C24: =D23 | D24: ='Aug-26'!D25 | E24: =D24-C24 | F24: =G23 | G24: ='Aug-26'!O25 | H24: =G24-F24 | P24: NIGHT | Q24: =R23 | R24: ='Aug-26'!U25 | S24: =R24-Q24 | T24: =U23 | U24: ='Aug-26'!AF25 | V24: =U24-T24
A25: =A23+1 | B25: DAY | C25: =D24 | D25: ='Aug-26'!D26 | E25: =D25-C25 | F25: =G24 | G25: ='Aug-26'!O26 | H25: =G25-F25 | I25: 180 | J25: 1 Hrs | K25: Pankaj Choudhary | L25: Saidullah Choudhary | O25: =O23+1 | P25: DAY | Q25: =R24 | R25: ='Aug-26'!U26 | S25: =R25-Q25 | T25: =U24 | U25: ='Aug-26'!AF26 | V25: =U25-T25 | W25: 150 | X25: 1 Hrs | Y25: Rajkumar | Z25: Kanhaiya Lal
B26: NIGHT | C26: =D25 | D26: ='Aug-26'!D27 | E26: =D26-C26 | F26: =G25 | G26: ='Aug-26'!O27 | H26: =G26-F26 | P26: NIGHT | Q26: =R25 | R26: ='Aug-26'!U27 | S26: =R26-Q26 | T26: =U25 | U26: ='Aug-26'!AF27 | V26: =U26-T26
A27: =A25+1 | B27: DAY | C27: =D26 | D27: ='Aug-26'!D28 | E27: =D27-C27 | F27: =G26 | G27: ='Aug-26'!O28 | H27: =G27-F27 | I27: 150 | J27: 1 Hrs | K27: Pankaj Choudhary | L27: Saidullah Choudhary | O27: =O25+1 | P27: DAY | Q27: =R26 | R27: ='Aug-26'!U28 | S27: =R27-Q27 | T27: =U26 | U27: ='Aug-26'!AF28 | V27: =U27-T27 | W27: 160 | X27: 1 Hrs | Y27: Aman Gupta | Z27: Kanhaiya Lal
B28: NIGHT | C28: =D27 | D28: ='Aug-26'!D29 | E28: =D28-C28 | F28: =G27 | G28: ='Aug-26'!O29 | H28: =G28-F28 | P28: NIGHT | Q28: =R27 | R28: ='Aug-26'!U29 | S28: =R28-Q28 | T28: =U27 | U28: ='Aug-26'!AF29 | V28: =U28-T28
A29: =A27+1 | B29: DAY | C29: =D28 | D29: ='Aug-26'!D30 | E29: =D29-C29 | F29: =G28 | G29: ='Aug-26'!O30 | H29: =G29-F29 | I29: 250 | J29: 1 Hrs | K29: Pankaj Choudhary | L29: Saidullah Choudhary | O29: =O27+1 | P29: DAY | Q29: =R28 | R29: ='Aug-26'!U30 | S29: =R29-Q29 | T29: =U28 | U29: ='Aug-26'!AF30 | V29: =U29-T29 | W29: 250 | X29: 1 Hrs | Y29: Nazeer Choudhary | Z29: Rajkumar
B30: NIGHT | C30: =D29 | D30: ='Aug-26'!D31 | E30: =D30-C30 | F30: =G29 | G30: ='Aug-26'!O31 | H30: =G30-F30 | P30: NIGHT | Q30: =R29 | R30: ='Aug-26'!U31 | S30: =R30-Q30 | T30: =U29 | U30: ='Aug-26'!AF31 | V30: =U30-T30
A31: =A29+1 | B31: DAY | C31: =D30 | D31: ='Aug-26'!D32 | E31: =D31-C31 | F31: =G30 | G31: ='Aug-26'!O32 | H31: =G31-F31 | I31: 230 | J31: 1 Hrs | K31: Kanhaiya Lal | L31: Nazeer Choudhary | O31: =O29+1 | P31: DAY | Q31: =R30 | R31: ='Aug-26'!U32 | S31: =R31-Q31 | T31: =U30 | U31: ='Aug-26'!AF32 | V31: =U31-T31 | W31: 260 | X31: 1 Hrs | Y31: Aman Gupta | Z31: Rajkumar
B32: NIGHT | C32: =D31 | D32: ='Aug-26'!D33 | E32: =D32-C32 | F32: =G31 | G32: ='Aug-26'!O33 | H32: =G32-F32 | P32: NIGHT | Q32: =R31 | R32: ='Aug-26'!U33 | S32: =R32-Q32 | T32: =U31 | U32: ='Aug-26'!AF33 | V32: =U32-T32
A33: =A31+1 | B33: DAY | C33: =D32 | D33: ='Aug-26'!D34 | E33: =D33-C33 | F33: =G32 | G33: ='Aug-26'!O34 | H33: =G33-F33 | I33: 150 | J33: 1 Hrs | K33: Saidullah Choudhary | L33: Nazeer Choudhary | O33: =O31+1 | P33: DAY | Q33: =R32 | R33: ='Aug-26'!U34 | S33: =R33-Q33 | T33: =U32 | U33: ='Aug-26'!AF34 | V33: =U33-T33 | W33: 110 | X33: 1 Hrs | Y33: Kanhaiya Lal | Z33: Aman Gupta
B34: NIGHT | C34: =D33 | D34: ='Aug-26'!D35 | E34: =D34-C34 | F34: =G33 | G34: ='Aug-26'!O35 | H34: =G34-F34 | P34: NIGHT | Q34: =R33 | R34: ='Aug-26'!U35 | S34: =R34-Q34 | T34: =U33 | U34: ='Aug-26'!AF35 | V34: =U34-T34
A35: =A33+1 | B35: DAY | C35: =D34 | D35: ='Aug-26'!D36 | E35: =D35-C35 | F35: =G34 | G35: ='Aug-26'!O36 | H35: =G35-F35 | I35: 320 | J35: 1 Hrs | K35: Pankaj Choudhary | L35: Saidullah Choudhary | O35: =O33+1 | P35: DAY | Q35: =R34 | R35: ='Aug-26'!U36 | S35: =R35-Q35 | T35: =U34 | U35: ='Aug-26'!AF36 | V35: =U35-T35 | W35: 340 | X35: 1 Hrs | Y35: Rajkumar | Z35: Aman Gupta
B36: NIGHT | C36: =D35 | D36: ='Aug-26'!D37 | E36: =D36-C36 | F36: =G35 | G36: ='Aug-26'!O37 | H36: =G36-F36 | P36: NIGHT | Q36: =R35 | R36: ='Aug-26'!U37 | S36: =R36-Q36 | T36: =U35 | U36: ='Aug-26'!AF37 | V36: =U36-T36
A37: =A35+1 | B37: DAY | C37: =D36 | D37: ='Aug-26'!D38 | E37: =D37-C37 | F37: =G36 | G37: ='Aug-26'!O38 | H37: =G37-F37 | J37: 1 Hrs | K37: Pankaj Choudhary | L37: Kanhaiya Lal | O37: =O35+1 | P37: DAY | Q37: =R36 | R37: ='Aug-26'!U38 | S37: =R37-Q37 | T37: =U36 | U37: ='Aug-26'!AF38 | V37: =U37-T37 | W37: 270 | X37: 1 Hrs | Y37: Rajkumar | Z37: Saidullah Choudhary
B38: NIGHT | C38: =D37 | D38: ='Aug-26'!D39 | E38: =D38-C38 | F38: =G37 | G38: ='Aug-26'!O39 | H38: =G38-F38 | P38: NIGHT | Q38: =R37 | R38: ='Aug-26'!U39 | S38: =R38-Q38 | T38: =U37 | U38: ='Aug-26'!AF39 | V38: =U38-T38
A39: =A37+1 | B39: DAY | C39: =D38 | D39: ='Aug-26'!D40 | E39: =D39-C39 | F39: =G38 | G39: ='Aug-26'!O40 | H39: =G39-F39 | I39: 300 | J39: 1 Hrs | K39: Nazeer Choudhary | L39: Saidullah Choudhary | O39: =O37+1 | P39: DAY | Q39: =R38 | R39: ='Aug-26'!U40 | S39: =R39-Q39 | T39: =U38 | U39: ='Aug-26'!AF40 | V39: =U39-T39 | W39: 240 | X39: 1 Hrs | Y39: Aman Gupta | Z39: Kanhaiya Lal
B40: NIGHT | C40: =D39 | D40: ='Aug-26'!D41 | E40: =D40-C40 | F40: =G39 | G40: ='Aug-26'!O41 | H40: =G40-F40 | P40: NIGHT | Q40: =R39 | R40: ='Aug-26'!U41 | S40: =R40-Q40 | T40: =U39 | U40: ='Aug-26'!AF41 | V40: =U40-T40
...

Sheet Apr-26
A1: NEW MACHINE NO - XCMG-8 | J1: BREAKDOWN TIME/Cooling | R1: NEW MACHINE NO - SANY-9 | AA1: BREAKDOWN TIME/Cooling
A2: DATE | B2: SHIFT | C2: SHIFT START - HMR | D2: SHIFT END - HMR | E2: HOURS | F2: DIESEL | G2: HMR | H2: HOURS | I2: AVERAGE | J2: START TIME | K2: END TIME | L2: TOTAL HRS | M2: Remarks | N2: Container Start Count | O2: Container End Count | P2: Total | R2: DATE | S2: SHIFT | T2: SHIFT START - HMR | U2: SHIFT END - HMR | V2: HOURS | W2: DIESEL | X2: HMR | Y2: HOURS | Z2: AVERAGE | AA2: START TIME | AB2: END TIME | AC2: TOTAL HRS | AD2: Remarks | AE2: Container Start Count | AF2: Container End Count | AG2: Total
A3: 46113 | B3: DAY | R3: 46113 | S3: DAY
A4: =A3 | B4: NIGHT | R4: =R3 | S4: NIGHT
A5: =A4+1 | B5: DAY | R5: =R4+1 | S5: DAY
A6: =A5 | B6: NIGHT | R6: =R5 | S6: NIGHT
A7: =A6+1 | B7: DAY | R7: =R6+1 | S7: DAY
A8: =A7 | B8: NIGHT | R8: =R7 | S8: NIGHT
A9: =A8+1 | B9: DAY | R9: =R8+1 | S9: DAY
A10: =A9 | B10: NIGHT | R10: =R9 | S10: NIGHT
A11: =A10+1 | B11: DAY | R11: =R10+1 | S11: DAY
A12: =A11 | B12: NIGHT | R12: =R11 | S12: NIGHT
A13: =A12+1 | B13: DAY | R13: =R12+1 | S13: DAY
A14: =A13 | B14: NIGHT | R14: =R13 | S14: NIGHT
A15: =A14+1 | B15: DAY | R15: =R14+1 | S15: DAY
A16: =A15 | B16: NIGHT | R16: =R15 | S16: NIGHT
A17: =A16+1 | B17: DAY | R17: =R16+1 | S17: DAY
A18: =A17 | B18: NIGHT | R18: =R17 | S18: NIGHT
A19: =A18+1 | B19: DAY | R19: =R18+1 | S19: DAY
A20: =A19 | B20: NIGHT | R20: =R19 | S20: NIGHT
A21: =A20+1 | B21: DAY | R21: =R20+1 | S21: DAY
A22: =A21 | B22: NIGHT | R22: =R21 | S22: NIGHT
A23: =A22+1 | B23: DAY | R23: =R22+1 | S23: DAY
A24: =A23 | B24: NIGHT | R24: =R23 | S24: NIGHT
A25: =A24+1 | B25: DAY | R25: =R24+1 | S25: DAY
A26: =A25 | B26: NIGHT | R26: =R25 | S26: NIGHT
A27: =A26+1 | B27: DAY | R27: =R26+1 | S27: DAY
A28: =A27 | B28: NIGHT | R28: =R27 | S28: NIGHT
A29: =A28+1 | B29: DAY | R29: =R28+1 | S29: DAY
A30: =A29 | B30: NIGHT | R30: =R29 | S30: NIGHT
A31: =A30+1 | B31: DAY | R31: =R30+1 | S31: DAY
A32: =A31 | B32: NIGHT | R32: =R31 | S32: NIGHT
A33: =A32+1 | B33: DAY | R33: =R32+1 | S33: DAY
A34: =A33 | B34: NIGHT | R34: =R33 | S34: NIGHT
A35: =A34+1 | B35: DAY | F35: 500 | G35: 45 | R35: =R34+1 | S35: DAY
A36: =A35 | B36: NIGHT | R36: =R35 | S36: NIGHT
A37: =A36+1 | B37: DAY | R37: =R36+1 | S37: DAY
A38: =A37 | B38: NIGHT | J38: 0.083333333 | K38: 0.5 | L38: =K38-J38 | M38: Electric problem | R38: =R37 | S38: NIGHT
A39: =A38+1 | B39: DAY | J39: =K38 | K39: 0.66666667 | L39: =K39-J39 | M39: Electric problem | R39: =R38+1 | S39: DAY
A40: =A39 | B40: NIGHT | R40: =R39 | S40: NIGHT
...

Sheet May-26
A1: NEW MACHINE NO - XCMG-8 | J1: BREAKDOWN TIME/Cooling | R1: NEW MACHINE NO - SANY-9 | AA1: BREAKDOWN TIME/Cooling
A2: DATE | B2: SHIFT | C2: SHIFT START - HMR | D2: SHIFT END - HMR | E2: HOURS | F2: DIESEL | G2: HMR | H2: HOURS | I2: AVERAGE | J2: START TIME | K2: END TIME | L2: TOTAL HRS | M2: Remarks | N2: Container Start Count | O2: Container End Count | P2: Total | R2: DATE | S2: SHIFT | T2: SHIFT START - HMR | U2: SHIFT END - HMR | V2: HOURS | W2: DIESEL | X2: HMR | Y2: HOURS | Z2: AVERAGE | AA2: START TIME | AB2: END TIME | AC2: TOTAL HRS | AD2: Remarks | AE2: Container Start Count | AF2: Container End Count | AG2: Total
G3: 231 | X3: 27
A4: 46143 | B4: DAY | C4: 246 | D4: 252 | E4: =D4-C4 | F4: 200 | G4: 250 | H4: =G4-G3 | I4: =F4/H4 | J4: 0.29166667 | K4: 0.33333333 | L4: 0.041666667 | M4: Cooling | N4: 2516 | O4: 2634 | P4: =O4-N4 | R4: 46143 | S4: DAY | T4: 37 | U4: 42 | V4: =U4-T4 | W4: 100 | X4: 37 | Y4: =X4-X3 | Z4: =W4/Y4 | AA4: 0.29166667 | AB4: 0.33333333 | AC4: =AB4-AA4 | AD4: Cooling | AE4: 225 | AF4: 316 | AG4: =AF4-AE4
A5: =A4 | B5: NIGHT | C5: =D4 | D5: 263 | E5: =D5-C5 | N5: =O4 | O5: 2712 | P5: =O5-N5 | R5: =R4 | S5: NIGHT | T5: =U4 | U5: 49 | V5: =U5-T5 | AE5: =AF4 | AF5: 429 | AG5: =AF5-AE5
A6: =A5+1 | B6: DAY | C6: =D5 | D6: 270 | E6: =D6-C6 | F6: 170 | G6: 267 | H6: =G6-G4 | I6: =F6/H6 | N6: =O5 | O6: 2798 | P6: =O6-N6 | R6: =R5+1 | S6: DAY | T6: =U5 | U6: 54 | V6: =U6-T6 | W6: 200 | X6: 50 | Y6: =X6-X4 | Z6: =W6/Y6 | AA6: 0.10416667 | AB6: 0.14583333 | AC6: =AB6-AA6 | AD6: Cooling | AE6: =AF5 | AF6: 511 | AG6: =AF6-AE6
A7: =A6 | B7: NIGHT | C7: =D6 | D7: 280 | E7: =D7-C7 | N7: =O6 | O7: 2862 | P7: =O7-N7 | R7: =R6 | S7: NIGHT | T7: =U6 | U7: 59 | V7: =U7-T7 | AE7: =AF6 | AF7: 580 | AG7: =AF7-AE7
A8: =A7+1 | B8: DAY | C8: =D7 | D8: 280 | E8: =D8-C8 | F8: 120 | G8: 280 | H8: =G8-G6 | I8: =F8/H8 | J8: 0.33333333 | K8: 0.83333333 | L8: =K8-J8 | M8: No Operator | N8: =O7 | O8: 2862 | P8: =O8-N8 | R8: =R7+1 | S8: DAY | T8: =U7 | U8: 69 | V8: =U8-T8 | W8: 140 | X8: 61 | Y8: =X8-X6 | Z8: =W8/Y8 | AE8: =AF7 | AF8: 704 | AG8: =AF8-AE8
A9: =A8 | B9: NIGHT | C9: =D8 | D9: 290 | E9: =D9-C9 | N9: =O8 | O9: 2985 | P9: =O9-N9 | R9: =R8 | S9: NIGHT | T9: =U8 | U9: 77 | V9: =U9-T9 | AE9: =AF8 | AF9: 825 | AG9: =AF9-AE9
A10: =A9+1 | B10: DAY | C10: =D9 | D10: 290 | E10: =D10-C10 | J10: 0.33333333 | K10: 0.83333333 | L10: =K10-J10 | M10: No Operator | N10: =O9 | O10: 2985 | P10: =O10-N10 | R10: =R9+1 | S10: DAY | T10: =U9 | U10: 87 | V10: =U10-T10 | W10: 280 | X10: 82 | Y10: =X10-X8 | Z10: =W10/Y10 | AE10: =AF9 | AF10: 936 | AG10: =AF10-AE10
A11: =A10 | B11: NIGHT | C11: =D10 | D11: 301 | E11: =D11-C11 | N11: =O10 | O11: 3090 | P11: =O11-N11 | R11: =R10 | S11: NIGHT | T11: =U10 | U11: 97 | V11: =U11-T11 | AE11: =AF10 | AF11: 1116 | AG11: =AF11-AE11
A12: =A11+1 | B12: DAY | C12: =D11 | D12: 310 | E12: =D12-C12 | F12: 90 | G12: 304 | H12: =G12-G8 | I12: =F12/H12 | N12: =O11 | O12: 3211 | P12: =O12-N12 | R12: =R11+1 | S12: DAY | T12: =U11 | U12: 105 | V12: =U12-T12 | W12: 200 | X12: 104 | Y12: =X12-X10 | Z12: =W12/Y12 | AE12: =AF11 | AF12: 1170 | AG12: =AF12-AE12
A13: =A12 | B13: NIGHT | C13: =D12 | D13: 310 | E13: =D13-C13 | J13: 0.33333333 | K13: 0.83333333 | L13: =K13-J13 | M13: No Operator | N13: =O12 | O13: 3211 | P13: =O13-N13 | R13: =R12 | S13: NIGHT | T13: =U12 | U13: 116 | V13: =U13-T13 | AE13: =AF12 | AF13: 1272 | AG13: =AF13-AE13
A14: =A13+1 | B14: DAY | C14: =D13 | D14: 320 | E14: =D14-C14 | F14: 180 | G14: 316 | H14: =G14-G12 | I14: =F14/H14 | N14: =O13 | O14: 3415 | P14: =O14-N14 | R14: =R13+1 | S14: DAY | T14: =U13 | U14: 123 | V14: =U14-T14 | AA14: 0.29166667 | AB14: 0.33333333 | AC14: 0.041666667 | AD14: Cooling | AE14: =AF13 | AF14: 1345 | AG14: =AF14-AE14
A15: =A14 | B15: NIGHT | C15: =D14 | D15: 320 | E15: =D15-C15 | J15: 0.33333333 | K15: 0.83333333 | L15: =K15-J15 | M15: No Operator | N15: =O14 | O15: 3415 | P15: =O15-N15 | R15: =R14 | S15: NIGHT | T15: =U14 | U15: 134 | V15: =U15-T15 | AE15: =AF14 | AF15: 1461 | AG15: =AF15-AE15
A16: =A15+1 | B16: DAY | C16: =D15 | D16: 329 | E16: =D16-C16 | F16: 130 | G16: 324 | H16: =G16-G14 | I16: =F16/H16 | N16: =O15 | O16: 3575 | P16: =O16-N16 | R16: =R15+1 | S16: DAY | T16: =U15 | U16: 139 | V16: =U16-T16 | W16: 200 | X16: 137 | Y16: =X16-X12 | Z16: =W16/Y16 | AA16: 0.29166667 | AB16: 0.33333333 | AC16: 0.041666667 | AD16: Cooling | AE16: =AF15 | AF16: 1510 | AG16: =AF16-AE16
A17: =A16 | B17: NIGHT | C17: =D16 | D17: 329 | E17: =D17-C17 | J17: 0.33333333 | K17: 0.83333333 | L17: =K17-J17 | M17: No Operator | N17: =O16 | O17: 3575 | P17: =O17-N17 | R17: =R16 | S17: NIGHT | T17: =U16 | U17: 150 | V17: =U17-T17 | AE17: =AF16 | AF17: 1595 | AG17: =AF17-AE17
A18: =A17+1 | B18: DAY | C18: =D17 | D18: 336 | E18: =D18-C18 | F18: 120 | G18: 334 | H18: =G18-G16 | I18: =F18/H18 | J18: 0.27083333 | K18: 0.33333333 | L18: =K18-J18 | M18: Cooling | N18: =O17 | O18: 3700 | P18: =O18-N18 | R18: =R17+1 | S18: DAY | T18: =U17 | U18: 160 | V18: =U18-T18 | W18: 130 | X18: 153 | Y18: =X18-X16 | Z18: =W18/Y18 | AE18: =AF17 | AF18: 1742 | AG18: =AF18-AE18
A19: =A18 | B19: NIGHT | C19: =D18 | D19: 336 | E19: =D19-C19 | J19: 0.33333333 | K19: 0.83333333 | L19: =K19-J19 | M19: No Operator | N19: =O18 | O19: 3700 | P19: =O19-N19 | R19: =R18 | S19: NIGHT | T19: =U18 | U19: 171 | V19: =U19-T19 | AE19: =AF18 | AF19: 1799 | AG19: =AF19-AE19
A20: =A19+1 | B20: DAY | C20: =D19 | D20: 341 | E20: =D20-C20 | F20: 71 | G20: 339 | H20: =G20-G18 | I20: =F20/H20 | J20: 0.29166667 | K20: 0.33333333 | L20: =K20-J20 | M20: Cooling | N20: =O19 | O20: 3758 | P20: =O20-N20 | R20: =R19+1 | S20: DAY | T20: =U19 | U20: 179 | V20: =U20-T20 | W20: 250 | X20: 175 | Y20: =X20-X18 | Z20: =W20/Y20 | AE20: =AF19 | AF20: 1907 | AG20: =AF20-AE20
A21: =A20 | B21: NIGHT | C21: =D20 | D21: 351 | E21: =D21-C21 | J21: 0.33333333 | K21: 0.83333333 | L21: =K21-J21 | M21: No Operator | N21: =O20 | O21: 3804 | P21: =O21-N21 | R21: =R20 | S21: NIGHT | T21: =U20 | U21: 189 | V21: =U21-T21 | AE21: =AF20 | AF21: 1961 | AG21: =AF21-AE21
A22: =A21+1 | B22: DAY | C22: =D21 | D22: 351 | E22: =D22-C22 | J22: 0.33333333 | K22: 0.83333333 | L22: =K22-J22 | M22: No Operator | N22: =O21 | O22: 3804 | P22: =O22-N22 | R22: =R21+1 | S22: DAY | T22: =U21 | U22: 200 | V22: =U22-T22 | W22: 140 | X22: 191 | Y22: =X22-X20 | Z22: =W22/Y22 | AE22: =AF21 | AF22: 2060 | AG22: =AF22-AE22
A23: =A22 | B23: NIGHT | C23: =D22 | D23: 361 | E23: =D23-C23 | N23: =O22 | O23: 3855 | P23: =O23-N23 | R23: =R22 | S23: NIGHT | T23: =U22 | U23: 211 | V23: =U23-T23 | AE23: =AF22 | AF23: 2128 | AG23: =AF23-AE23
A24: =A23+1 | B24: DAY | C24: =D23 | D24: 367 | E24: =D24-C24 | F24: 200 | G24: 361 | H24: =G24-G20 | I24: =F24/H24 | J24: 0.097222222 | K24: 0.21875 | L24: =K24-J24 | M24: Joystick communication error | N24: =O23 | O24: 3957 | P24: =O24-N24 | R24: =R23+1 | S24: DAY | T24: =U23 | U24: 219 | V24: =U24-T24 | W24: 220 | X24: 214 | Y24: =X24-X22 | Z24: =W24/Y24 | AE24: =AF23 | AF24: 2203 | AG24: =AF24-AE24
A25: =A24 | B25: NIGHT | C25: =D24 | D25: 367 | E25: =D25-C25 | J25: 0.33333333 | K25: 0.83333333 | L25: =K25-J25 | M25: No Operator | N25: =O24 | O25: 3957 | P25: =O25-N25 | R25: =R24 | S25: NIGHT | T25: =U24 | U25: 230 | V25: =U25-T25 | AE25: =AF24 | AF25: 2268 | AG25: =AF25-AE25
A26: =A25+1 | B26: DAY | C26: =D25 | D26: 377 | E26: =D26-C26 | F26: 91 | G26: 372 | H26: =G26-G24 | I26: =F26/H26 | N26: =O25 | O26: 4073 | P26: =O26-N26 | R26: =R25+1 | S26: DAY | T26: =U25 | U26: 241 | V26: =U26-T26 | W26: 250 | X26: 237 | Y26: =X26-X24 | Z26: =W26/Y26 | AE26: =AF25 | AF26: 2420 | AG26: =AF26-AE26
A27: =A26 | B27: NIGHT | C27: =D26 | D27: 377 | E27: =D27-C27 | J27: 0.33333333 | K27: 0.83333333 | L27: =K27-J27 | M27: No Operator | N27: =O26 | O27: 4073 | P27: =O27-N27 | R27: =R26 | S27: NIGHT | T27: =U26 | U27: 252 | V27: =U27-T27 | AE27: =AF26 | AF27: 2552 | AG27: =AF27-AE27
A28: =A27+1 | B28: DAY | C28: =D27 | D28: 383 | E28: =D28-C28 | F28: 80 | G28: 379 | H28: =G28-G26 | I28: =F28/H28 | J28: 0.52083333 | K28: 0.72222222 | L28: =K28-J28 | M28: A/C PROBLEM | N28: =O27 | O28: 4178 | P28: =O28-N28 | R28: =R27+1 | S28: DAY | T28: =U27 | U28: 263 | V28: =U28-T28 | W28: 240 | X28: 255 | Y28: =X28-X26 | Z28: =W28/Y28 | AE28: =AF27 | AF28: 2730 | AG28: =AF28-AE28
A29: =A28 | B29: NIGHT | C29: =D28 | D29: 383 | E29: =D29-C29 | J29: 0.33333333 | K29: 0.83333333 | L29: =K29-J29 | M29: No Operator | N29: =O28 | O29: 4178 | P29: =O29-N29 | R29: =R28 | S29: NIGHT | T29: =U28 | U29: 275 | V29: =U29-T29 | AE29: =AF28 | AF29: 2840 | AG29: =AF29-AE29
A30: =A29+1 | B30: DAY | C30: =D29 | D30: 392 | E30: =D30-C30 | N30: =O29 | O30: 4263 | P30: =O30-N30 | R30: =R29+1 | S30: DAY | T30: =U29 | U30: 281 | V30: =U30-T30 | W30: 200 | X30: 276 | Y30: =X30-X28 | Z30: =W30/Y30 | AE30: =AF29 | AF30: 2925 | AG30: =AF30-AE30
A31: =A30 | B31: NIGHT | C31: =D30 | D31: 400 | E31: =D31-C31 | N31: =O30 | O31: 4378 | P31: =O31-N31 | R31: =R30 | S31: NIGHT | T31: =U30 | U31: 291 | V31: =U31-T31 | AE31: =AF30 | AF31: 2979 | AG31: =AF31-AE31
A32: =A31+1 | B32: DAY | C32: =D31 | D32: 410 | E32: =D32-C32 | F32: 250 | G32: 402 | H32: =G32-G28 | I32: =F32/H32 | J32: 0.45833333 | K32: 0.54166667 | L32: =K32-J32 | M32: Maintnance | N32: =O31 | O32: 4472 | P32: =O32-N32 | R32: =R31+1 | S32: DAY | T32: =U31 | U32: 298 | V32: =U32-T32 | W32: 90 | X32: 292 | Y32: =X32-X30 | Z32: =W32/Y32 | AE32: =AF31 | AF32: 3061 | AG32: =AF32-AE32
A33: =A32 | B33: NIGHT | C33: =D32 | D33: 419 | E33: =D33-C33 | N33: =O32 | O33: 4520 | P33: =O33-N33 | R33: =R32 | S33: NIGHT | T33: =U32 | U33: 302 | V33: =U33-T33 | AE33: =AF32 | AF33: 3104 | AG33: =AF33-AE33
A34: =A33+1 | B34: DAY | C34: =D33 | D34: 429 | E34: =D34-C34 | F34: 210 | G34: 425 | H34: =G34-G32 | I34: =F34/H34 | N34: =O33 | O34: 4604 | P34: =O34-N34 | R34: =R33+1 | S34: DAY | T34: =U33 | U34: 310 | V34: =U34-T34 | W34: 230 | X34: 304 | Y34: =X34-X32 | Z34: =W34/Y34 | AE34: =AF33 | AF34: 3177 | AG34: =AF34-AE34
A35: =A34 | B35: NIGHT | C35: =D34 | D35: 437 | E35: =D35-C35 | N35: =O34 | O35: 4766 | P35: =O35-N35 | R35: =R34 | S35: NIGHT | T35: =U34 | U35: 321 | V35: =U35-T35 | AE35: =AF34 | AF35: 3289 | AG35: =AF35-AE35
A36: =A35+1 | B36: DAY | C36: =D35 | D36: 437 | E36: =D36-C36 | J36: 0.33333333 | K36: 0.83333333 | L36: =K36-J36 | M36: No Operator | N36: =O35 | O36: 4766 | P36: =O36-N36 | R36: =R35+1 | S36: DAY | T36: =U35 | U36: 329 | V36: =U36-T36 | W36: 190 | X36: 323 | Y36: =X36-X34 | Z36: =W36/Y36 | AE36: =AF35 | AF36: 3371 | AG36: =AF36-AE36
A37: =A36 | B37: NIGHT | C37: =D36 | D37: 437 | E37: =D37-C37 | J37: 0.33333333 | K37: 0.83333333 | L37: =K37-J37 | M37: No Operator | N37: =O36 | O37: 4766 | P37: =O37-N37 | R37: =R36 | S37: NIGHT | T37: =U36 | U37: 339 | V37: =U37-T37 | AE37: =AF36 | AF37: 3517 | AG37: =AF37-AE37
A38: =A37+1 | B38: DAY | C38: =D37 | D38: 446 | E38: =D38-C38 | F38: 190 | G38: 440 | H38: =G38-G34 | I38: =F38/H38 | N38: =O37 | O38: 4869 | P38: =O38-N38 | R38: =R37+1 | S38: DAY | T38: =U37 | U38: 347 | V38: =U38-T38 | W38: 290 | X38: 344 | Y38: =X38-X36 | Z38: =W38/Y38 | AE38: =AF37 | AF38: 3633 | AG38: =AF38-AE38
A39: =A38 | B39: NIGHT | C39: =D38 | D39: 456 | E39: =D39-C39 | N39: =O38 | O39: 4909 | P39: =O39-N39 | R39: =R38 | S39: NIGHT | T39: =U38 | U39: 355 | V39: =U39-T39 | AE39: =AF38 | AF39: 3681 | AG39: =AF39-AE39
A40: =A39+1 | B40: DAY | C40: =D39 | D40: 461 | E40: =D40-C40 | F40: 90 | G40: 456 | H40: =G40-G38 | I40: =F40/H40 | J40: 0.54166667 | K40: 0.83333333 | L40: =K40-J40 | M40: Break oil leakage | N40: =O39 | O40: 4925 | P40: =O40-N40 | R40: =R39+1 | S40: DAY | T40: =U39 | U40: 363 | V40: =U40-T40 | W40: 160 | X40: 356 | Y40: =X40-X38 | Z40: =W40/Y40 | AE40: =AF39 | AF40: 3764 | AG40: =AF40-AE40
...

Sheet June-26
A1: NEW MACHINE NO - XCMG-8 | J1: BREAKDOWN TIME/Cooling | R1: NEW MACHINE NO - SANY-9 | AA1: BREAKDOWN TIME/Cooling
A2: DATE | B2: SHIFT | C2: SHIFT START - HMR | D2: SHIFT END - HMR | E2: HOURS | F2: DIESEL | G2: HMR | H2: HOURS | I2: AVERAGE | J2: START TIME | K2: END TIME | L2: TOTAL HRS | M2: Remarks | N2: Container Start Count | O2: Container End Count | P2: Total | R2: DATE | S2: SHIFT | T2: SHIFT START - HMR | U2: SHIFT END - HMR | V2: HOURS | W2: DIESEL | X2: HMR | Y2: HOURS | Z2: AVERAGE | AA2: START TIME | AB2: END TIME | AC2: TOTAL HRS | AD2: Remarks | AE2: Container Start Count | AF2: Container End Count | AG2: Total
G3: 589 | X3: 539
A4: 46174 | B4: DAY | C4: 605 | D4: 616 | E4: =D4-C4 | F4: 180 | G4: 608 | H4: =G4-G3 | I4: =F4/H4 | J4: XCMG(RST-08) MOVE TO TALOJA FROM BMCT PORT 10-JUN-26 & THEN RST DEPLOYED IN KATTUPALLI 17-06-26. | N4: 6261 | O4: 6362 | P4: =O4-N4 | R4: 46174 | S4: DAY | T4: 551 | U4: 558 | V4: =U4-T4 | W4: 150 | X4: 552 | Y4: =X4-X3 | Z4: =W4/Y4 | AE4: 5436 | AF4: 5500 | AG4: =AF4-AE4
A5: =A4 | B5: NIGHT | C5: =D4 | D5: 624 | E5: =D5-C5 | N5: =O4 | O5: 6515 | P5: =O5-N5 | R5: =R4 | S5: NIGHT | T5: =U4 | U5: 567 | V5: =U5-T5 | AE5: =AF4 | AF5: 5592 | AG5: =AF5-AE5
A6: =A5+1 | B6: DAY | C6: =D5 | D6: 629 | E6: =D6-C6 | F6: 240 | G6: 627 | H6: =G6-G4 | I6: =F6/H6 | N6: =O5 | O6: 6527 | P6: =O6-N6 | R6: =R5+1 | S6: DAY | T6: =U5 | U6: 573 | V6: =U6-T6 | W6: 200 | X6: 570 | Y6: =X6-X4 | Z6: =W6/Y6 | AE6: =AF5 | AF6: 5622 | AG6: =AF6-AE6
A7: =A6 | B7: NIGHT | C7: =D6 | D7: 638 | E7: =D7-C7 | N7: =O6 | O7: 6576 | P7: =O7-N7 | R7: =R6 | S7: NIGHT | T7: =U6 | U7: 581 | V7: =U7-T7 | AE7: =AF6 | AF7: 5688 | AG7: =AF7-AE7
A8: =A7+1 | B8: DAY | C8: =D7 | D8: 645 | E8: =D8-C8 | F8: 110 | G8: 638 | H8: =G8-G6 | I8: =F8/H8 | N8: =O7 | O8: 6633 | P8: =O8-N8 | R8: =R7+1 | S8: DAY | T8: =U7 | U8: 592 | V8: =U8-T8 | W8: 190 | X8: 585 | Y8: =X8-X6 | Z8: =W8/Y8 | AE8: =AF7 | AF8: 5741 | AG8: =AF8-AE8
A9: =A8 | B9: NIGHT | C9: =D8 | D9: 652 | E9: =D9-C9 | N9: =O8 | O9: 6713 | P9: =O9-N9 | R9: =R8 | S9: NIGHT | T9: =U8 | U9: 600 | V9: =U9-T9 | AE9: =AF8 | AF9: 5853 | AG9: =AF9-AE9
A10: =A9+1 | B10: DAY | C10: =D9 | D10: 662 | E10: =D10-C10 | F10: 150 | G10: 656 | H10: =G10-G8 | I10: =F10/H10 | N10: =O9 | O10: 6933 | P10: =O10-N10 | R10: =R9+1 | S10: DAY | T10: =U9 | U10: 612 | V10: =U10-T10 | W10: 250 | X10: 605 | Y10: =X10-X8 | Z10: =W10/Y10 | AE10: =AF9 | AF10: 5996 | AG10: =AF10-AE10
A11: =A10 | B11: NIGHT | C11: =D10 | D11: 672 | E11: =D11-C11 | N11: =O10 | O11: 7071 | P11: =O11-N11 | R11: =R10 | S11: NIGHT | T11: =U10 | U11: 619 | V11: =U11-T11 | AE11: =AF10 | AF11: 6053 | AG11: =AF11-AE11
A12: =A11+1 | B12: DAY | C12: 10 | D12: 15 | E12: =D12-C12 | F12: 400 | G12: 12 | J12: NEW SANY (RST-08) MACHINE START ON 05-06-26 | N12: 24 | O12: 52 | P12: =O12-N12 | R12: =R11+1 | S12: DAY | T12: =U11 | U12: 630 | V12: =U12-T12 | W12: 200 | X12: 626 | Y12: =X12-X10 | Z12: =W12/Y12 | AE12: =AF11 | AF12: 6169 | AG12: =AF12-AE12
A13: =A12 | B13: NIGHT | C13: =D12 | D13: 24 | E13: =D13-C13 | N13: =O12 | O13: 153 | P13: =O13-N13 | R13: =R12 | S13: NIGHT | T13: =U12 | U13: 639 | V13: =U13-T13 | AE13: =AF12 | AF13: 6258 | AG13: =AF13-AE13
A14: =A13+1 | B14: DAY | C14: =D13 | D14: 34 | E14: =D14-C14 | F14: 220 | G14: 26 | H14: =G14-G12 | I14: =F14/H14 | N14: =O13 | O14: 271 | P14: =O14-N14 | R14: =R13+1 | S14: DAY | T14: =U13 | U14: 647 | V14: =U14-T14 | W14: 200 | X14: 641 | Y14: =X14-X12 | Z14: =W14/Y14 | AE14: =AF13 | AF14: 6345 | AG14: =AF14-AE14
A15: =A14 | B15: NIGHT | C15: =D14 | D15: 44 | E15: =D15-C15 | N15: =O14 | O15: 369 | P15: =O15-N15 | R15: =R14 | S15: NIGHT | T15: =U14 | U15: 654 | V15: =U15-T15 | AE15: =AF14 | AF15: 6423 | AG15: =AF15-AE15
A16: =A15+1 | B16: DAY | C16: =D15 | D16: 51 | E16: =D16-C16 | F16: 210 | G16: 47 | H16: =G16-G14 | I16: =F16/H16 | N16: =O15 | O16: 446 | P16: =O16-N16 | R16: =R15+1 | S16: DAY | T16: =U15 | U16: 662 | V16: =U16-T16 | W16: 190 | X16: 657 | Y16: =X16-X14 | Z16: =W16/Y16 | AE16: =AF15 | AF16: 6508 | AG16: =AF16-AE16
A17: =A16 | B17: NIGHT | C17: =D16 | D17: 62 | E17: =D17-C17 | N17: =O16 | O17: 535 | P17: =O17-N17 | R17: =R16 | S17: NIGHT | T17: =U16 | U17: 671 | V17: =U17-T17 | AE17: =AF16 | AF17: 6617 | AG17: =AF17-AE17
A18: =A17+1 | B18: DAY | C18: =D17 | D18: 71 | E18: =D18-C18 | F18: 180 | G18: 69 | H18: =G18-G16 | I18: =F18/H18 | N18: =O17 | O18: 636 | P18: =O18-N18 | R18: =R17+1 | S18: DAY | T18: =U17 | U18: 682 | V18: =U18-T18 | W18: 220 | X18: 677 | Y18: =X18-X16 | Z18: =W18/Y18 | AE18: =AF17 | AF18: 6788 | AG18: =AF18-AE18
A19: =A18 | B19: NIGHT | C19: =D18 | D19: 76 | E19: =D19-C19 | N19: =O18 | O19: 702 | P19: =O19-N19 | R19: =R18 | S19: NIGHT | T19: =U18 | U19: 688 | V19: =U19-T19 | AE19: =AF18 | AF19: 6860 | AG19: =AF19-AE19
A20: =A19+1 | B20: DAY | C20: =D19 | D20: 83 | E20: =D20-C20 | F20: 150 | G20: 76 | H20: =G20-G16 | I20: =F20/H20 | N20: =O19 | O20: 747 | P20: =O20-N20 | R20: =R19+1 | S20: DAY | T20: =U19 | U20: 698 | V20: =U20-T20 | W20: 190 | X20: 691 | Y20: =X20-X18 | Z20: =W20/Y20 | AE20: =AF19 | AF20: 6966 | AG20: =AF20-AE20
A21: =A20 | B21: NIGHT | C21: =D20 | D21: 89 | E21: =D21-C21 | N21: =O20 | O21: 787 | P21: =O21-N21 | R21: =R20 | S21: NIGHT | T21: =U20 | U21: 700 | V21: =U21-T21 | AE21: =AF20 | AF21: 6976 | AG21: =AF21-AE21
A22: =A21+1 | B22: DAY | C22: =D21 | D22: 98 | E22: =D22-C22 | F22: 160 | G22: 91 | H22: =G22-G20 | I22: =F22/H22 | N22: =O21 | O22: 862 | P22: =O22-N22 | R22: =R21+1 | S22: DAY | T22: =U21 | U22: 704 | V22: =U22-T22 | W22: 70 | X22: 700 | Y22: =X22-X20 | Z22: =W22/Y22 | AE22: =AF21 | AF22: 6997 | AG22: =AF22-AE22
A23: =A22 | B23: NIGHT | C23: =D22 | D23: 102 | E23: =D23-C23 | N23: =O22 | O23: 906 | P23: =O23-N23 | R23: =R22 | S23: NIGHT | T23: =U22 | U23: 713 | V23: =U23-T23 | AE23: =AF22 | AF23: 7090 | AG23: =AF23-AE23
A24: =A23+1 | B24: DAY | C24: =D23 | D24: 112 | E24: =D24-C24 | F24: 110 | G24: 108 | H24: =G24-G22 | I24: =F24/H24 | N24: =O23 | O24: 1009 | P24: =O24-N24 | R24: =R23+1 | S24: DAY | T24: =U23 | U24: 720 | V24: =U24-T24 | W24: 130 | X24: 716 | Y24: =X24-X22 | Z24: =W24/Y24 | AE24: =AF23 | AF24: 7123 | AG24: =AF24-AE24
A25: =A24 | B25: NIGHT | C25: =D24 | D25: 117 | E25: =D25-C25 | N25: =O24 | O25: 1058 | P25: =O25-N25 | R25: =R24 | S25: NIGHT | T25: =U24 | U25: 729 | V25: =U25-T25 | AE25: =AF24 | AF25: 7232 | AG25: =AF25-AE25
A26: =A25+1 | B26: DAY | C26: =D25 | D26: 128 | E26: =D26-C26 | F26: 190 | G26: 122 | H26: =G26-G24 | I26: =F26/H26 | N26: =O25 | O26: 1132 | P26: =O26-N26 | R26: =R25+1 | S26: DAY | T26: =U25 | U26: 739 | V26: =U26-T26 | W26: 170 | X26: 733 | Y26: =X26-X24 | Z26: =W26/Y26 | AE26: =AF25 | AF26: 7353 | AG26: =AF26-AE26
A27: =A26 | B27: NIGHT | C27: =D26 | D27: 135 | E27: =D27-C27 | N27: =O26 | O27: 1181 | P27: =O27-N27 | R27: =R26 | S27: NIGHT | T27: =U26 | U27: 749 | V27: =U27-T27 | AE27: =AF26 | AF27: 7465 | AG27: =AF27-AE27
A28: =A27+1 | B28: DAY | C28: =D27 | D28: 143 | E28: =D28-C28 | F28: 200 | G28: 138 | H28: =G28-G26 | I28: =F28/H28 | N28: =O27 | O28: 1329 | P28: =O28-N28 | R28: =R27+1 | S28: DAY | T28: =U27 | U28: 757 | V28: =U28-T28 | W28: 220 | X28: 751 | Y28: =X28-X26 | Z28: =W28/Y28 | AE28: =AF27 | AF28: 7578 | AG28: =AF28-AE28
A29: =A28 | B29: NIGHT | C29: =D28 | D29: 154 | E29: =D29-C29 | N29: =O28 | O29: 1431 | P29: =O29-N29 | R29: =R28 | S29: NIGHT | T29: =U28 | U29: 767 | V29: =U29-T29 | AE29: =AF28 | AF29: 7670 | AG29: =AF29-AE29
A30: =A29+1 | B30: DAY | C30: =D29 | D30: 162 | E30: =D30-C30 | F30: 200 | G30: 158 | H30: =G30-G28 | I30: =F30/H30 | N30: =O29 | O30: 1554 | P30: =O30-N30 | R30: =R29+1 | S30: DAY | T30: =U29 | U30: 776 | V30: =U30-T30 | W30: 220 | X30: 770 | Y30: =X30-X28 | Z30: =W30/Y30 | AE30: =AF29 | AF30: 7801 | AG30: =AF30-AE30
A31: =A30 | B31: NIGHT | C31: =D30 | D31: 171 | E31: =D31-C31 | N31: =O30 | O31: 1636 | P31: =O31-N31 | R31: =R30 | S31: NIGHT | T31: =U30 | U31: 782 | V31: =U31-T31 | AE31: =AF30 | AF31: 7874 | AG31: =AF31-AE31
A32: =A31+1 | B32: DAY | C32: =D31 | D32: 180 | E32: =D32-C32 | F32: 150 | G32: 176 | H32: =G32-G30 | I32: =F32/H32 | N32: =O31 | O32: 1770 | P32: =O32-N32 | R32: =R31+1 | S32: DAY | T32: =U31 | U32: 791 | V32: =U32-T32 | W32: 120 | X32: 787 | Y32: =X32-X30 | Z32: =W32/Y32 | AE32: =AF31 | AF32: 7994 | AG32: =AF32-AE32
A33: =A32 | B33: NIGHT | C33: =D32 | D33: 190 | E33: =D33-C33 | N33: =O32 | O33: 1890 | P33: =O33-N33 | R33: =R32 | S33: NIGHT | T33: =U32 | U33: 801 | V33: =U33-T33 | AE33: =AF32 | AF33: 8113 | AG33: =AF33-AE33
A34: =A33+1 | B34: DAY | C34: =D33 | D34: 200 | E34: =D34-C34 | F34: 210 | G34: 193 | H34: =G34-G32 | I34: =F34/H34 | N34: =O33 | O34: 1955 | P34: =O34-N34 | R34: =R33+1 | S34: DAY | T34: =U33 | U34: 808 | V34: =U34-T34 | W34: 260 | X34: 804 | Y34: =X34-X32 | Z34: =W34/Y34 | AE34: =AF33 | AF34: 8171 | AG34: =AF34-AE34
A35: =A34 | B35: NIGHT | C35: =D34 | D35: 205 | E35: =D35-C35 | N35: =O34 | O35: 2010 | P35: =O35-N35 | R35: =R34 | S35: NIGHT | T35: =U34 | U35: 818 | V35: =U35-T35 | AE35: =AF34 | AF35: 8243 | AG35: =AF35-AE35
A36: =A35+1 | B36: DAY | C36: =D35 | D36: 216 | E36: =D36-C36 | F36: 130 | G36: 207 | H36: =G36-G34 | I36: =F36/H36 | N36: =O35 | O36: 2092 | P36: =O36-N36 | R36: =R35+1 | S36: DAY | T36: =U35 | U36: 826 | V36: =U36-T36 | W36: 150 | X36: 820 | Y36: =X36-X34 | Z36: =W36/Y36 | AE36: =AF35 | AF36: 8318 | AG36: =AF36-AE36
A37: =A36 | B37: NIGHT | C37: =D36 | D37: 222 | E37: =D37-C37 | N37: =O36 | O37: 2159 | P37: =O37-N37 | R37: =R36 | S37: NIGHT | T37: =U36 | U37: 835 | V37: =U37-T37 | AE37: =AF36 | AF37: 8427 | AG37: =AF37-AE37
A38: =A37+1 | B38: DAY | C38: =D37 | D38: 229 | E38: =D38-C38 | F38: 200 | G38: 225 | H38: =G38-G36 | I38: =F38/H38 | N38: =O37 | O38: 2243 | P38: =O38-N38 | R38: =R37+1 | S38: DAY | T38: =U37 | U38: 845 | V38: =U38-T38 | W38: 200 | X38: 839 | Y38: =X38-X36 | Z38: =W38/Y38 | AE38: =AF37 | AF38: 8559 | AG38: =AF38-AE38
A39: =A38 | B39: NIGHT | C39: =D38 | D39: 236 | E39: =D39-C39 | N39: =O38 | O39: 2327 | P39: =O39-N39 | R39: =R38 | S39: NIGHT | T39: =U38 | U39: 852 | V39: =U39-T39 | AE39: =AF38 | AF39: 8609 | AG39: =AF39-AE39
A40: =A39+1 | B40: DAY | C40: =D39 | D40: 243 | E40: =D40-C40 | F40: 210 | G40: 239 | H40: =G40-G38 | I40: =F40/H40 | N40: =O39 | O40: 2423 | P40: =O40-N40 | R40: =R39+1 | S40: DAY | T40: =U39 | U40: 858 | V40: =U40-T40 | W40: 150 | X40: 854 | Y40: =X40-X38 | Z40: =W40/Y40 | AE40: =AF39 | AF40: 8667 | AG40: =AF40-AE40
...

Sheet JULY-26
A1: NEW MACHINE NO - SANY-8 | J1: BREAKDOWN TIME/Cooling | R1: NEW MACHINE NO - SANY-9 | AA1: BREAKDOWN TIME/Cooling
A2: DATE | B2: SHIFT | C2: SHIFT START - HMR | D2: SHIFT END - HMR | E2: HOURS | F2: DIESEL | G2: HMR | H2: HOURS | I2: AVERAGE | J2: START TIME | K2: END TIME | L2: TOTAL HRS | M2: Remarks | N2: Container Start Count | O2: Container End Count | P2: Total | R2: DATE | S2: SHIFT | T2: SHIFT START - HMR | U2: SHIFT END - HMR | V2: HOURS | W2: DIESEL | X2: HMR | Y2: HOURS | Z2: AVERAGE | AA2: START TIME | AB2: END TIME | AC2: TOTAL HRS | AD2: Remarks | AE2: Container Start Count | AF2: Container End Count | AG2: Total
G3: 410 | X3: 1048
A4: 46204 | B4: DAY | C4: 436 | D4: 444 | E4: =D4-C4 | F4: 220 | G4: 440 | H4: =G4-G3 | I4: =F4/H4 | N4: 4918 | O4: 5064 | P4: =O4-N4 | R4: 46204 | S4: DAY | T4: 1063 | U4: 1071 | V4: =U4-T4 | W4: 200 | X4: 1068 | Y4: =X4-X3 | Z4: =W4/Y4 | AE4: 11130 | AF4: 11216 | AG4: =AF4-AE4
A5: =A4 | B5: NIGHT | C5: =D4 | D5: 454 | E5: =D5-C5 | N5: =O4 | O5: 5166 | P5: =O5-N5 | R5: =R4 | S5: NIGHT | T5: =U4 | U5: 1078 | V5: =U5-T5 | AE5: =AF4 | AF5: 11313 | AG5: =AF5-AE5
A6: =A5+1 | B6: DAY | C6: =D5 | D6: 462 | E6: =D6-C6 | F6: 140 | G6: 456 | H6: =G6-G4 | I6: =F6/H6 | N6: =O5 | O6: 5343 | P6: =O6-N6 | R6: =R5+1 | S6: DAY | T6: =U5 | U6: 1087 | V6: =U6-T6 | W6: 160 | X6: 1080 | Y6: =X6-X4 | Z6: =W6/Y6 | AE6: =AF5 | AF6: 11465 | AG6: =AF6-AE6
A7: =A6 | B7: NIGHT | C7: =D6 | D7: 471 | E7: =D7-C7 | N7: =O6 | O7: 5550 | P7: =O7-N7 | R7: =R6 | S7: NIGHT | T7: =U6 | U7: 1098 | V7: =U7-T7 | AE7: =AF6 | AF7: 11613 | AG7: =AF7-AE7
A8: =A7+1 | B8: DAY | C8: =D7 | D8: 481 | E8: =D8-C8 | F8: 300 | G8: 474 | H8: =G8-G6 | I8: =F8/H8 | L8: 0.16666667 | M8: PM Service 04:00 hrs | N8: =O7 | O8: 5677 | P8: =O8-N8 | R8: =R7+1 | S8: DAY | T8: =U7 | U8: 1108 | V8: =U8-T8 | W8: 200 | X8: 1102 | Y8: =X8-X6 | Z8: =W8/Y8 | AE8: =AF7 | AF8: 11719 | AG8: =AF8-AE8
A9: =A8 | B9: NIGHT | C9: =D8 | D9: 489 | E9: =D9-C9 | N9: =O8 | O9: 5818 | P9: =O9-N9 | R9: =R8 | S9: NIGHT | T9: =U8 | U9: 1117 | V9: =U9-T9 | AE9: =AF8 | AF9: 11843 | AG9: =AF9-AE9
A10: =A9+1 | B10: DAY | C10: =D9 | D10: 499 | E10: =D10-C10 | F10: 200 | G10: 492 | H10: =G10-G8 | I10: =F10/H10 | N10: =O9 | O10: 5998 | P10: =O10-N10 | R10: =R9+1 | S10: DAY | T10: =U9 | U10: 1127 | V10: =U10-T10 | W10: 200 | X10: 1120 | Y10: =X10-X8 | Z10: =W10/Y10 | AE10: =AF9 | AF10: 11942 | AG10: =AF10-AE10
A11: =A10 | B11: NIGHT | C11: =D10 | D11: 507 | E11: =D11-C11 | N11: =O10 | O11: 6079 | P11: =O11-N11 | R11: =R10 | S11: NIGHT | T11: =U10 | U11: 1133 | V11: =U11-T11 | AE11: =AF10 | AF11: 12001 | AG11: =AF11-AE11
A12: =A11+1 | B12: DAY | C12: =D11 | D12: 516 | E12: =D12-C12 | F12: 170 | G12: 509 | H12: =G12-G10 | I12: =F12/H12 | N12: =O11 | O12: 6170 | P12: =O12-N12 | R12: =R11+1 | S12: DAY | T12: =U11 | U12: 1142 | V12: =U12-T12 | W12: 110 | X12: 1135 | Y12: =X12-X10 | Z12: =W12/Y12 | AE12: =AF11 | AF12: 12066 | AG12: =AF12-AE12
A13: =A12 | B13: NIGHT | C13: =D12 | D13: 519 | E13: =D13-C13 | N13: =O12 | O13: 6196 | P13: =O13-N13 | R13: =R12 | S13: NIGHT | T13: =U12 | U13: 1148 | V13: =U13-T13 | AE13: =AF12 | AF13: 12120 | AG13: =AF13-AE13
A14: =A13+1 | B14: DAY | C14: =D13 | D14: 522 | E14: =D14-C14 | N14: =O13 | O14: 6208 | P14: =O14-N14 | R14: =R13+1 | S14: DAY | T14: =U13 | U14: 1154 | V14: =U14-T14 | W14: 150 | X14: 1148 | Y14: =X14-X12 | Z14: =W14/Y14 | AE14: =AF13 | AF14: 12187 | AG14: =AF14-AE14
A15: =A14 | B15: NIGHT | C15: =D14 | D15: 528 | E15: =D15-C15 | N15: =O14 | O15: 6271 | P15: =O15-N15 | R15: =R14 | S15: NIGHT | T15: =U14 | U15: 1160 | V15: =U15-T15 | AE15: =AF14 | AF15: 12265 | AG15: =AF15-AE15
A16: =A15+1 | B16: DAY | C16: =D15 | D16: 538 | E16: =D16-C16 | F16: 250 | G16: 532 | H16: =G16-G12 | I16: =F16/H16 | N16: =O15 | O16: 6393 | P16: =O16-N16 | R16: =R15+1 | S16: DAY | T16: =U15 | U16: 1169 | V16: =U16-T16 | W16: 180 | X16: 1164 | Y16: =X16-X14 | Z16: =W16/Y16 | AE16: =AF15 | AF16: 12395 | AG16: =AF16-AE16
A17: =A16 | B17: NIGHT | C17: =D16 | D17: 541 | E17: =D17-C17 | N17: =O16 | O17: 6437 | P17: =O17-N17 | R17: =R16 | S17: NIGHT | T17: =U16 | U17: 1174 | V17: =U17-T17 | AE17: =AF16 | AF17: 12453 | AG17: =AF17-AE17
A18: =A17+1 | B18: DAY | C18: =D17 | D18: 550 | E18: =D18-C18 | F18: 110 | G18: 543 | H18: =G18-G16 | I18: =F18/H18 | N18: =O17 | O18: 6597 | P18: =O18-N18 | R18: =R17+1 | S18: DAY | T18: =U17 | U18: 1184 | V18: =U18-T18 | W18: 150 | X18: 1178 | Y18: =X18-X16 | Z18: =W18/Y18 | AE18: =AF17 | AF18: 12607 | AG18: =AF18-AE18
A19: =A18 | B19: NIGHT | C19: =D18 | D19: 557 | E19: =D19-C19 | N19: =O18 | O19: 6739 | P19: =O19-N19 | R19: =R18 | S19: NIGHT | T19: =U18 | U19: 1193 | V19: =U19-T19 | AE19: =AF18 | AF19: 12727 | AG19: =AF19-AE19
A20: =A19+1 | B20: DAY | C20: =D19 | D20: 564 | E20: =D20-C20 | F20: 290 | G20: 560 | H20: =G20-G18 | I20: =F20/H20 | N20: =O19 | O20: 6868 | P20: =O20-N20 | R20: =R19+1 | S20: DAY | T20: =U19 | U20: 1202 | V20: =U20-T20 | W20: 250 | X20: 1196 | Y20: =X20-X18 | Z20: =W20/Y20 | AE20: =AF19 | AF20: 12855 | AG20: =AF20-AE20
A21: =A20 | B21: NIGHT | C21: =D20 | D21: 570 | E21: =D21-C21 | N21: =O20 | O21: 6927 | P21: =O21-N21 | R21: =R20 | S21: NIGHT | T21: =U20 | U21: 1210 | V21: =U21-T21 | AE21: =AF20 | AF21: 12932 | AG21: =AF21-AE21
A22: =A21+1 | B22: DAY | C22: =D21 | D22: 580 | E22: =D22-C22 | F22: 100 | G22: 573 | H22: =G22-G20 | I22: =F22/H22 | N22: =O21 | O22: 7044 | P22: =O22-N22 | R22: =R21+1 | S22: DAY | T22: =U21 | U22: 1218 | V22: =U22-T22 | W22: 70 | X22: 1211 | Y22: =X22-X20 | Z22: =W22/Y22 | AE22: =AF21 | AF22: 13049 | AG22: =AF22-AE22
A23: =A22 | B23: NIGHT | C23: =D22 | D23: 586 | E23: =D23-C23 | N23: =O22 | O23: 7109 | P23: =O23-N23 | R23: =R22 | S23: NIGHT | T23: =U22 | U23: 1224 | V23: =U23-T23 | AE23: =AF22 | AF23: 13150 | AG23: =AF23-AE23
A24: =A23+1 | B24: DAY | C24: =D23 | D24: 596 | E24: =D24-C24 | F24: 230 | G24: 587 | H24: =G24-G22 | I24: =F24/H24 | N24: =O23 | O24: 7309 | P24: =O24-N24 | R24: =R23+1 | S24: DAY | T24: =U23 | U24: 1234 | V24: =U24-T24 | W24: 230 | X24: 1225 | Y24: =X24-X22 | Z24: =W24/Y24 | AE24: =AF23 | AF24: 13301 | AG24: =AF24-AE24
A25: =A24 | B25: NIGHT | C25: =D24 | D25: 603 | E25: =D25-C25 | N25: =O24 | O25: 7423 | P25: =O25-N25 | R25: =R24 | S25: NIGHT | T25: =U24 | U25: 1239 | V25: =U25-T25 | AE25: =AF24 | AF25: 13356 | AG25: =AF25-AE25
A26: =A25+1 | B26: DAY | C26: =D25 | D26: 613 | E26: =D26-C26 | F26: 180 | G26: 605 | H26: =G26-G24 | I26: =F26/H26 | N26: =O25 | O26: 7586 | P26: =O26-N26 | R26: =R25+1 | S26: DAY | T26: =U25 | U26: 1250 | V26: =U26-T26 | W26: 150 | X26: 1241 | Y26: =X26-X24 | Z26: =W26/Y26 | AE26: =AF25 | AF26: 13506 | AG26: =AF26-AE26
A27: =A26 | B27: NIGHT | C27: =D26 | D27: 622 | E27: =D27-C27 | N27: =O26 | O27: 7727 | P27: =O27-N27 | R27: =R26 | S27: NIGHT | T27: =U26 | U27: 1260 | V27: =U27-T27 | AE27: =AF26 | AF27: 13666 | AG27: =AF27-AE27
A28: =A27+1 | B28: DAY | C28: =D27 | D28: 628 | E28: =D28-C28 | F28: 330 | G28: 625 | H28: =G28-G26 | I28: =F28/H28 | N28: =O27 | O28: 7845 | P28: =O28-N28 | R28: =R27+1 | S28: DAY | T28: =U27 | U28: 1268 | V28: =U28-T28 | W28: 270 | X28: 1264 | Y28: =X28-X26 | Z28: =W28/Y28 | AE28: =AF27 | AF28: 13752 | AG28: =AF28-AE28
A29: =A28 | B29: NIGHT | C29: =D28 | D29: 637 | E29: =D29-C29 | N29: =O28 | O29: 7939 | P29: =O29-N29 | R29: =R28 | S29: NIGHT | T29: =U28 | U29: 1276 | V29: =U29-T29 | AE29: =AF28 | AF29: 13860 | AG29: =AF29-AE29
A30: =A29+1 | B30: DAY | C30: =D29 | D30: 646 | E30: =D30-C30 | F30: 220 | G30: 642 | H30: =G30-G28 | I30: =F30/H30 | N30: =O29 | O30: 8183 | P30: =O30-N30 | R30: =R29+1 | S30: DAY | T30: =U29 | U30: 1286 | V30: =U30-T30 | W30: 200 | X30: 1281 | Y30: =X30-X28 | Z30: =W30/Y30 | AE30: =AF29 | AF30: 14055 | AG30: =AF30-AE30
A31: =A30 | B31: NIGHT | C31: =D30 | D31: 654 | E31: =D31-C31 | N31: =O30 | O31: 8277 | P31: =O31-N31 | R31: =R30 | S31: NIGHT | T31: =U30 | U31: 1294 | V31: =U31-T31 | AE31: =AF30 | AF31: 14182 | AG31: =AF31-AE31
A32: =A31+1 | B32: DAY | C32: =D31 | D32: 662 | E32: =D32-C32 | F32: 160 | G32: 657 | H32: =G32-G30 | I32: =F32/H32 | N32: =O31 | O32: 8352 | P32: =O32-N32 | R32: =R31+1 | S32: DAY | T32: =U31 | U32: 1301 | V32: =U32-T32 | W32: 200 | X32: 1297 | Y32: =X32-X30 | Z32: =W32/Y32 | AE32: =AF31 | AF32: 14279 | AG32: =AF32-AE32
A33: =A32 | B33: NIGHT | C33: =D32 | D33: 671 | E33: =D33-C33 | N33: =O32 | O33: 8443 | P33: =O33-N33 | R33: =R32 | S33: NIGHT | T33: =U32 | U33: 1312 | V33: =U33-T33 | AE33: =AF32 | AF33: 14408 | AG33: =AF33-AE33
A34: =A33+1 | B34: DAY | C34: =D33 | D34: 679 | E34: =D34-C34 | F34: 200 | G34: 678 | H34: =G34-G32 | I34: =F34/H34 | N34: =O33 | O34: 8550 | P34: =O34-N34 | R34: =R33+1 | S34: DAY | T34: =U33 | U34: 1320 | V34: =U34-T34 | W34: 200 | X34: 1318 | Y34: =X34-X32 | Z34: =W34/Y34 | AE34: =AF33 | AF34: 14513 | AG34: =AF34-AE34
A35: =A34 | B35: NIGHT | C35: =D34 | D35: 686 | E35: =D35-C35 | N35: =O34 | O35: 8647 | P35: =O35-N35 | R35: =R34 | S35: NIGHT | T35: =U34 | U35: 1328 | V35: =U35-T35 | AE35: =AF34 | AF35: 14595 | AG35: =AF35-AE35
A36: =A35+1 | B36: DAY | C36: =D35 | D36: 695 | E36: =D36-C36 | F36: 190 | G36: 689 | H36: =G36-G34 | I36: =F36/H36 | N36: =O35 | O36: 8771 | P36: =O36-N36 | R36: =R35+1 | S36: DAY | T36: =U35 | U36: 1337 | V36: =U36-T36 | W36: 200 | X36: 1332 | Y36: =X36-X34 | Z36: =W36/Y36 | AE36: =AF35 | AF36: 14719 | AG36: =AF36-AE36
A37: =A36 | B37: NIGHT | C37: =D36 | D37: 704 | E37: =D37-C37 | N37: =O36 | O37: 8919 | P37: =O37-N37 | R37: =R36 | S37: NIGHT | T37: =U36 | U37: 1346 | V37: =U37-T37 | AE37: =AF36 | AF37: 14838 | AG37: =AF37-AE37
A38: =A37+1 | B38: DAY | C38: =D37 | D38: 714 | E38: =D38-C38 | F38: 200 | G38: 707 | H38: =G38-G36 | I38: =F38/H38 | N38: =O37 | O38: 9098 | P38: =O38-N38 | R38: =R37+1 | S38: DAY | T38: =U37 | U38: 1355 | V38: =U38-T38 | W38: 210 | X38: 1349 | Y38: =X38-X36 | Z38: =W38/Y38 | AE38: =AF37 | AF38: 14955 | AG38: =AF38-AE38
A39: =A38 | B39: NIGHT | C39: =D38 | D39: 721 | E39: =D39-C39 | N39: =O38 | O39: 9188 | P39: =O39-N39 | R39: =R38 | S39: NIGHT | T39: =U38 | U39: 1361 | V39: =U39-T39 | AE39: =AF38 | AF39: 15034 | AG39: =AF39-AE39
A40: =A39+1 | B40: DAY | C40: =D39 | D40: 729 | E40: =D40-C40 | F40: 168 | G40: 722 | H40: =G40-G38 | I40: =F40/H40 | N40: =O39 | O40: 9309 | P40: =O40-N40 | R40: =R39+1 | S40: DAY | T40: =U39 | U40: 1371 | V40: =U40-T40 | W40: 150 | X40: 1362 | Y40: =X40-X38 | Z40: =W40/Y40 | AE40: =AF39 | AF40: 15208 | AG40: =AF40-AE40
...

Sheet Aug-26
A1: NEW MACHINE NO - SANY-8 | J1: BREAKDOWN TIME/Cooling | R1: NEW MACHINE NO - SANY-9 | AA1: BREAKDOWN TIME/Cooling
A2: DATE | B2: SHIFT | C2: SHIFT START - HMR | D2: SHIFT END - HMR | E2: HOURS | F2: DIESEL | G2: HMR | H2: HOURS | I2: AVERAGE | J2: START TIME | K2: END TIME | L2: TOTAL HRS | M2: Remarks | N2: Container Start Count | O2: Container End Count | P2: Total | R2: DATE | S2: SHIFT | T2: SHIFT START - HMR | U2: SHIFT END - HMR | V2: HOURS | W2: DIESEL | X2: HMR | Y2: HOURS | Z2: AVERAGE | AA2: START TIME | AB2: END TIME | AC2: TOTAL HRS | AD2: Remarks | AE2: Container Start Count | AF2: Container End Count | AG2: Total
G3: 906 | X3: 1553
A4: 46235 | B4: DAY | C4: 922 | D4: 930 | E4: =D4-C4 | F4: 270 | G4: 927 | H4: =G4-G3 | I4: =F4/H4 | N4: 12086 | O4: 12246 | P4: =O4-N4 | R4: 46235 | S4: DAY | T4: 1565 | U4: 1574 | V4: =U4-T4 | W4: 200 | X4: 1570 | Y4: =X4-X3 | Z4: =W4/Y4 | AE4: 17917 | AF4: 18065 | AG4: =AF4-AE4
A5: =A4 | B5: NIGHT | C5: =D4 | D5: 941 | E5: =D5-C5 | N5: =O4 | O5: 12376 | P5: =O5-N5 | R5: =R4 | S5: NIGHT | T5: =U4 | U5: 1584 | V5: =U5-T5 | AE5: =AF4 | AF5: 18208 | AG5: =AF5-AE5
A6: =A5+1 | B6: DAY | C6: =D5 | D6: 950 | E6: =D6-C6 | F6: 240 | G6: 946 | H6: =G6-G4 | I6: =F6/H6 | N6: =O5 | O6: 12504 | P6: =O6-N6 | R6: =R5+1 | S6: DAY | T6: =U5 | U6: 1594 | V6: =U6-T6 | W6: 230 | X6: 1588 | Y6: =X6-X4 | Z6: =W6/Y6 | AE6: =AF5 | AF6: 18374 | AG6: =AF6-AE6
A7: =A6 | B7: NIGHT | C7: =D6 | D7: 960 | E7: =D7-C7 | N7: =O6 | O7: 12652 | P7: =O7-N7 | R7: =R6 | S7: NIGHT | T7: =U6 | U7: 1602 | V7: =U7-T7 | AE7: =AF6 | AF7: 18508 | AG7: =AF7-AE7
A8: =A7+1 | B8: DAY | C8: =D7 | D8: 970 | E8: =D8-C8 | F8: 230 | G8: 963 | H8: =G8-G6 | I8: =F8/H8 | N8: =O7 | O8: 12822 | P8: =O8-N8 | R8: =R7+1 | S8: DAY | T8: =U7 | U8: 1613 | V8: =U8-T8 | W8: 250 | X8: 1606 | Y8: =X8-X6 | Z8: =W8/Y8 | AE8: =AF7 | AF8: 18745 | AG8: =AF8-AE8
A9: =A8 | B9: NIGHT | C9: =D8 | D9: 978 | E9: =D9-C9 | N9: =O8 | O9: 12903 | P9: =O9-N9 | R9: =R8 | S9: NIGHT | T9: =U8 | U9: 1621 | V9: =U9-T9 | AE9: =AF8 | AF9: 18844 | AG9: =AF9-AE9
A10: =A9+1 | B10: DAY | C10: =D9 | D10: 987 | E10: =D10-C10 | F10: 230 | G10: 981 | H10: =G10-G8 | I10: =F10/H10 | N10: =O9 | O10: 13029 | P10: =O10-N10 | R10: =R9+1 | S10: DAY | T10: =U9 | U10: 1630 | V10: =U10-T10 | W10: 250 | X10: 1623 | Y10: =X10-X8 | Z10: =W10/Y10 | AE10: =AF9 | AF10: 19010 | AG10: =AF10-AE10
A11: =A10 | B11: NIGHT | C11: =D10 | D11: 997 | E11: =D11-C11 | N11: =O10 | O11: 13125 | P11: =O11-N11 | R11: =R10 | S11: NIGHT | T11: =U10 | U11: 1637 | V11: =U11-T11 | AE11: =AF10 | AF11: 19102 | AG11: =AF11-AE11
A12: =A11+1 | B12: DAY | C12: =D11 | D12: 1006 | E12: =D12-C12 | F12: 270 | G12: 1000 | H12: =G12-G10 | I12: =F12/H12 | N12: =O11 | O12: 13276 | P12: =O12-N12 | R12: =R11+1 | S12: DAY | T12: =U11 | U12: 1646 | V12: =U12-T12 | W12: 250 | X12: 1640 | Y12: =X12-X10 | Z12: =W12/Y12 | AE12: =AF11 | AF12: 19231 | AG12: =AF12-AE12
A13: =A12 | B13: NIGHT | C13: =D12 | D13: 1011 | E13: =D13-C13 | N13: =O12 | O13: 13335 | P13: =O13-N13 | R13: =R12 | S13: NIGHT | T13: =U12 | U13: 1654 | V13: =U13-T13 | AE13: =AF12 | AF13: 19338 | AG13: =AF13-AE13
A14: =A13+1 | B14: DAY | C14: =D13 | D14: 1020 | E14: =D14-C14 | F14: 150 | G14: 1014 | H14: =G14-G12 | I14: =F14/H14 | N14: =O13 | O14: 13493 | P14: =O14-N14 | R14: =R13+1 | S14: DAY | T14: =U13 | U14: 1661 | V14: =U14-T14 | W14: 200 | X14: 1657 | Y14: =X14-X12 | Z14: =W14/Y14 | AE14: =AF13 | AF14: 19437 | AG14: =AF14-AE14
A15: =A14 | B15: NIGHT | C15: =D14 | D15: 1027 | E15: =D15-C15 | N15: =O14 | O15: 13602 | P15: =O15-N15 | R15: =R14 | S15: NIGHT | T15: =U14 | U15: 1671 | V15: =U15-T15 | AE15: =AF14 | AF15: 19567 | AG15: =AF15-AE15
A16: =A15+1 | B16: DAY | C16: =D15 | D16: 1037 | E16: =D16-C16 | F16: 250 | G16: 1031 | H16: =G16-G14 | I16: =F16/H16 | N16: =O15 | O16: 13723 | P16: =O16-N16 | R16: =R15+1 | S16: DAY | T16: =U15 | U16: 1676 | V16: =U16-T16 | W16: 200 | X16: 1673 | Y16: =X16-X14 | Z16: =W16/Y16 | AE16: =AF15 | AF16: 19625 | AG16: =AF16-AE16
A17: =A16 | B17: NIGHT | C17: =D16 | D17: 1044 | E17: =D17-C17 | N17: =O16 | O17: 13815 | P17: =O17-N17 | R17: =R16 | S17: NIGHT | T17: =U16 | U17: 1684 | V17: =U17-T17 | AE17: =AF16 | AF17: 19707 | AG17: =AF17-AE17
A18: =A17+1 | B18: DAY | C18: =D17 | D18: 1055 | E18: =D18-C18 | F18: 230 | G18: 1048 | H18: =G18-G16 | I18: =F18/H18 | N18: =O17 | O18: 13940 | P18: =O18-N18 | R18: =R17+1 | S18: DAY | T18: =U17 | U18: 1695 | V18: =U18-T18 | W18: 170 | X18: 1687 | Y18: =X18-X16 | Z18: =W18/Y18 | AE18: =AF17 | AF18: 19880 | AG18: =AF18-AE18
A19: =A18 | B19: NIGHT | C19: =D18 | D19: 1061 | E19: =D19-C19 | N19: =O18 | O19: 14042 | P19: =O19-N19 | R19: =R18 | S19: NIGHT | T19: =U18 | U19: 1703 | V19: =U19-T19 | AE19: =AF18 | AF19: 19976 | AG19: =AF19-AE19
A20: =A19+1 | B20: DAY | C20: =D19 | D20: 1072 | E20: =D20-C20 | F20: 200 | G20: 1064 | H20: =G20-G18 | I20: =F20/H20 | N20: =O19 | O20: 14184 | P20: =O20-N20 | R20: =R19+1 | S20: DAY | T20: =U19 | U20: 1714 | V20: =U20-T20 | W20: 230 | X20: 1706 | Y20: =X20-X18 | Z20: =W20/Y20 | AE20: =AF19 | AF20: 20146 | AG20: =AF20-AE20
A21: =A20 | B21: NIGHT | C21: =D20 | D21: 1082 | E21: =D21-C21 | N21: =O20 | O21: 14336 | P21: =O21-N21 | R21: =R20 | S21: NIGHT | T21: =U20 | U21: 1725 | V21: =U21-T21 | AE21: =AF20 | AF21: 20331 | AG21: =AF21-AE21
A22: =A21+1 | B22: DAY | C22: =D21 | D22: 1092 | E22: =D22-C22 | F22: 340 | G22: 1087 | H22: =G22-G20 | I22: =F22/H22 | N22: =O21 | O22: 14493 | P22: =O22-N22 | R22: =R21+1 | S22: DAY | T22: =U21 | U22: 1736 | V22: =U22-T22 | W22: 350 | X22: 1731 | Y22: =X22-X20 | Z22: =W22/Y22 | AE22: =AF21 | AF22: 20573 | AG22: =AF22-AE22
A23: =A22 | B23: NIGHT | C23: =D22 | D23: 1100 | E23: =D23-C23 | N23: =O22 | O23: 14616 | P23: =O23-N23 | R23: =R22 | S23: NIGHT | T23: =U22 | U23: 1746 | V23: =U23-T23 | AE23: =AF22 | AF23: 20754 | AG23: =AF23-AE23
A24: =A23+1 | B24: DAY | C24: =D23 | D24: 1108 | E24: =D24-C24 | F24: 240 | G24: 1104 | H24: =G24-G22 | I24: =F24/H24 | N24: =O23 | O24: 14770 | P24: =O24-N24 | R24: =R23+1 | S24: DAY | T24: =U23 | U24: 1755 | V24: =U24-T24 | W24: 260 | X24: 1752 | Y24: =X24-X22 | Z24: =W24/Y24 | AE24: =AF23 | AF24: 20877 | AG24: =AF24-AE24
A25: =A24 | B25: NIGHT | C25: =D24 | D25: 1116 | E25: =D25-C25 | N25: =O24 | O25: 14867 | P25: =O25-N25 | R25: =R24 | S25: NIGHT | T25: =U24 | U25: 1762 | V25: =U25-T25 | AE25: =AF24 | AF25: 20947 | AG25: =AF25-AE25
A26: =A25+1 | B26: DAY | C26: =D25 | D26: 1121 | E26: =D26-C26 | F26: 180 | G26: 1118 | H26: =G26-G24 | I26: =F26/H26 | N26: =O25 | O26: 14963 | P26: =O26-N26 | R26: =R25+1 | S26: DAY | T26: =U25 | U26: 1769 | V26: =U26-T26 | W26: 150 | X26: 1764 | Y26: =X26-X24 | Z26: =W26/Y26 | AE26: =AF25 | AF26: 21030 | AG26: =AF26-AE26
A27: =A26 | B27: NIGHT | C27: =D26 | D27: 1130 | E27: =D27-C27 | N27: =O26 | O27: 15002 | P27: =O27-N27 | R27: =R26 | S27: NIGHT | T27: =U26 | U27: 1776 | V27: =U27-T27 | AE27: =AF26 | AF27: 21093 | AG27: =AF27-AE27
A28: =A27+1 | B28: DAY | C28: =D27 | D28: 1139 | E28: =D28-C28 | F28: 150 | G28: 1132 | H28: =G28-G26 | I28: =F28/H28 | N28: =O27 | O28: 15199 | P28: =O28-N28 | R28: =R27+1 | S28: DAY | T28: =U27 | U28: 1786 | V28: =U28-T28 | W28: 160 | X28: 1779 | Y28: =X28-X26 | Z28: =W28/Y28 | AE28: =AF27 | AF28: 21289 | AG28: =AF28-AE28
A29: =A28 | B29: NIGHT | C29: =D28 | D29: 1148 | E29: =D29-C29 | N29: =O28 | O29: 15302 | P29: =O29-N29 | R29: =R28 | S29: NIGHT | T29: =U28 | U29: 1794 | V29: =U29-T29 | AE29: =AF28 | AF29: 21364 | AG29: =AF29-AE29
A30: =A29+1 | B30: DAY | C30: =D29 | D30: 1156 | E30: =D30-C30 | F30: 250 | G30: 1157 | H30: =G30-G28 | I30: =F30/H30 | N30: =O29 | O30: 15426 | P30: =O30-N30 | R30: =R29+1 | S30: DAY | T30: =U29 | U30: 1804 | V30: =U30-T30 | W30: 250 | X30: 1798 | Y30: =X30-X28 | Z30: =W30/Y30 | AE30: =AF29 | AF30: 21521 | AG30: =AF30-AE30
A31: =A30 | B31: NIGHT | C31: =D30 | D31: 1167 | E31: =D31-C31 | N31: =O30 | O31: 15537 | P31: =O31-N31 | R31: =R30 | S31: NIGHT | T31: =U30 | U31: 1814 | V31: =U31-T31 | AE31: =AF30 | AF31: 21687 | AG31: =AF31-AE31
A32: =A31+1 | B32: DAY | C32: =D31 | D32: 1177 | E32: =D32-C32 | F32: 230 | G32: 1171 | H32: =G32-G30 | I32: =F32/H32 | N32: =O31 | O32: 15699 | P32: =O32-N32 | R32: =R31+1 | S32: DAY | T32: =U31 | U32: 1823 | V32: =U32-T32 | W32: 260 | X32: 1818 | Y32: =X32-X30 | Z32: =W32/Y32 | AE32: =AF31 | AF32: 21824 | AG32: =AF32-AE32
A33: =A32 | B33: NIGHT | C33: =D32 | D33: 1184 | E33: =D33-C33 | N33: =O32 | O33: 15767 | P33: =O33-N33 | R33: =R32 | S33: NIGHT | T33: =U32 | U33: 1828 | V33: =U33-T33 | AE33: =AF32 | AF33: 21888 | AG33: =AF33-AE33
A34: =A33+1 | B34: DAY | C34: =D33 | D34: 1194 | E34: =D34-C34 | F34: 150 | G34: 1187 | H34: =G34-G32 | I34: =F34/H34 | N34: =O33 | O34: 15903 | P34: =O34-N34 | R34: =R33+1 | S34: DAY | T34: =U33 | U34: 1837 | V34: =U34-T34 | W34: 110 | X34: 1831 | Y34: =X34-X32 | Z34: =W34/Y34 | AE34: =AF33 | AF34: 22035 | AG34: =AF34-AE34
A35: =A34 | B35: NIGHT | C35: =D34 | D35: 1203 | E35: =D35-C35 | N35: =O34 | O35: 16038 | P35: =O35-N35 | R35: =R34 | S35: NIGHT | T35: =U34 | U35: 1847 | V35: =U35-T35 | AE35: =AF34 | AF35: 22153 | AG35: =AF35-AE35
A36: =A35+1 | B36: DAY | C36: =D35 | D36: 1213 | E36: =D36-C36 | F36: 320 | G36: 1209 | H36: =G36-G34 | I36: =F36/H36 | N36: =O35 | O36: 16217 | P36: =O36-N36 | R36: =R35+1 | S36: DAY | T36: =U35 | U36: 1857 | V36: =U36-T36 | W36: 340 | X36: 1853 | Y36: =X36-X34 | Z36: =W36/Y36 | AE36: =AF35 | AF36: 22354 | AG36: =AF36-AE36
A37: =A36 | B37: NIGHT | C37: =D36 | D37: 1223 | E37: =D37-C37 | N37: =O36 | O37: 16367 | P37: =O37-N37 | R37: =R36 | S37: NIGHT | T37: =U36 | U37: 1869 | V37: =U37-T37 | AE37: =AF36 | AF37: 22562 | AG37: =AF37-AE37
A38: =A37+1 | B38: DAY | C38: =D37 | D38: 1231 | E38: =D38-C38 | F38: 240 | N38: =O37 | O38: 16481 | P38: =O38-N38 | R38: =R37+1 | S38: DAY | T38: =U37 | U38: 1879 | V38: =U38-T38 | W38: 270 | X38: 1873 | Y38: =X38-X36 | Z38: =W38/Y38 | AE38: =AF37 | AF38: 22720 | AG38: =AF38-AE38
A39: =A38 | B39: NIGHT | C39: =D38 | D39: 1239 | E39: =D39-C39 | N39: =O38 | O39: 16576 | P39: =O39-N39 | R39: =R38 | S39: NIGHT | T39: =U38 | U39: 1887 | V39: =U39-T39 | AE39: =AF38 | AF39: 22874 | AG39: =AF39-AE39
A40: =A39+1 | B40: DAY | C40: =D39 | D40: 1250 | E40: =D40-C40 | F40: 300 | G40: 1241 | H40: =G40-G36 | I40: =F40/H40 | N40: =O39 | O40: 16726 | P40: =O40-N40 | R40: =R39+1 | S40: DAY | T40: =U39 | U40: 1898 | V40: =U40-T40 | W40: 240 | X40: 1893 | Y40: =X40-X38 | Z40: =W40/Y40 | AE40: =AF39 | AF40: 23053 | AG40: =AF40-AE40
...

Sheet Sep-26
A1: NEW MACHINE NO - SANY-8 | J1: BREAKDOWN TIME/Cooling | R1: NEW MACHINE NO - SANY-9 | AA1: BREAKDOWN TIME/Cooling
A2: Date | B2: Shift | C2: Starting HMR | D2: Closing HMR | E2: HOURS | F2: Diesel Issued (Ltr) | G2: HMR at Diesel Fill | H2: HOURS | I2: Avg. Diesel Consumption (Ltr/Hr) | J2: Shift Start Time | K2: Shift End Time | L2: TOTAL HRS | M2: Remarks | N2: Container Start Count | O2: Container End Count | P2: Total | Q2: Remark | R2: Date | S2: Shift | T2: Starting HMR | U2: Closing HMR | V2: HOURS | W2: Diesel Issued (Ltr) | X2: HMR at Diesel Fill | Y2: HOURS | Z2: Avg. Diesel Consumption (Ltr/Hr) | AA2: Shift Start Time | AB2: Shift End Time | AC2: TOTAL HRS | AD2: Remarks | AE2: Container Start Count | AF2: Container End Count | AG2: Total | AH2: Remark
G3: 1456 | X3: 2121
A4: 46266 | B4: DAY | C4: ='Aug-26'!D65 | D4: 1481 | E4: =IF(OR(C4="",D4=""),0,D4-C4) | F4: 240 | G4: 1476 | H4: =IF(OR(G3="",G4=""),"",G4-G3) | I4: =IFERROR(F4/H4,0) | N4: 19882 | O4: 20010 | P4: =IF(OR(N4="",O4=""),0,O4-N4) | Q4: NAZEER | R4: 46266 | S4: DAY | T4: 2137 | U4: 2147 | V4: =IF(OR(T4="",U4=""),0,U4-T4) | W4: 250 | X4: 2143 | Y4: =IF(OR(X3="",X4=""),"",X4-X3) | Z4: =IFERROR(W4/Y4,0) | AE4: 26442 | AF4: 26601 | AG4: =IF(OR(AE4="",AF4=""),0,AF4-AE4) | AH4: AMAN
